Workbook

Sheet Top 50 Shows & Movies
F1: WK-28, 2026 ( 11 Jul 2026 - 17 Jul 2026 )
A7: Week | B7: MARKET | C7: Platform | D7: Content format | E7: PAID/FREE | F7: Content Type | G7: Shows/Live Content | H7: Language | I7: Genre | J7: Release Date | K7: Rank | L7: Reach | M7: Total Time Spent (In Mins) Mn
A8: WK-28,2026 | B8: ALL INDIA | C8: JioHotstar | D8: Live Event | E8: PAID | F8: Sports | G8: England vs India ODI Series 2026 | H8: Bengali,Bhojpuri,English,Haryanvi,Hindi,Kannada,Tamil,Telugu | I8: Sport | J8: 46217 | K8: 1 | L8: 92.983875 | M8: 10187.41
A9: WK-28,2026 | B9: ALL INDIA | C9: Zee5 | D9: Live Event | E9: PAID | F9: Sports | G9: FIFA World Cup 2026 | H9: Bengali,English,Hindi,Malayalam | I9: Sport | J9: 46185 | K9: =K8+1 -> 2 | L9: 54.261232 | M9: 816.84195
A10: WK-28,2026 | B10: ALL INDIA | C10: Amazon Mx Player | D10: AVOD Originals Shows | E10: FREE | F10: Shows | G10: Raktanchal Season 3 | H10: Hindi,Tamil,Telugu | I10: Action,Crime,Drama | J10: 46219 | K10: =K9+1 -> 3 | L10: 31.519333 | M10: 4174.1199
A11: WK-28,2026 | B11: ALL INDIA | C11: Netflix | D11: Svod Originals Shows | E11: PAID | F11: Shows | G11: Lock Upp | H11: Hindi | I11: Reality Tv | J11: 46200 | K11: =K10+1 -> 4 | L11: 24.197959 | M11: 4106.8413
A12: WK-28,2026 | B12: ALL INDIA | C12: Netflix | D12: SVOD Originals Movies | E12: PAID | F12: Movies | G12: Ikka | H12: English,Hindi,Tamil,Telugu | I12: Crime,Drama,Thriller | J12: 46213 | K12: =K11+1 -> 5 | L12: 22.341902 | M12: 1074.2816
A13: WK-28,2026 | B13: ALL INDIA | C13: JioHotstar | D13: Svod Originals Shows | E13: PAID | F13: Shows | G13: Pritam And Pedro | H13: Bengali,Bhojpuri,Haryanvi,Hindi,Kannada,Marathi,Tamil,Telugu | I13: Crime,Drama,Thriller | J13: 46206 | K13: =K12+1 -> 6 | L13: 21.809854 | M13: 1101.1545
A14: WK-28,2026 | B14: ALL INDIA | C14: Amazon Prime Video | D14: Svod Originals Shows | E14: PAID | F14: Shows | G14: Alliance | H14: Hindi | I14: Reality Tv | J14: 46199 | K14: =K13+1 -> 7 | L14: 21.303523 | M14: 1716.4378
A15: WK-28,2026 | B15: ALL INDIA | C15: JioHotstar | D15: Theatrical Movies | E15: PAID | F15: Movies | G15: Chand Mera Dil | H15: Hindi | I15: Drama,Romance | J15: 46220 | K15: =K14+1 -> 8 | L15: 20.892084 | M15: 311.47395
A16: WK-28,2026 | B16: ALL INDIA | C16: Netflix | D16: Svod Originals Shows | E16: PAID | F16: Shows | G16: India’s Got Latent Season 2 | H16: Hindi | I16: Comedy | J16: 46193 | K16: =K15+1 -> 9 | L16: 20.585342 | M16: 1041.7468
A17: WK-28,2026 | B17: ALL INDIA | C17: Amazon Prime Video | D17: Theatrical Movies | E17: PAID | F17: Movies | G17: Ek Din | H17: Hindi,Tamil,Telugu | I17: Drama,Romance | J17: 46220 | K17: =K16+1 -> 10 | L17: 19.822692 | M17: 655.39331
A18: WK-28,2026 | B18: ALL INDIA | C18: Netflix | D18: SVOD Originals Shows | E18: PAID | F18: Shows | G18: The Apartment Job | H18: English,Hindi | I18: Crime,Drama,Thriller | J18: 46214 | K18: =K17+1 -> 11 | L18: 19.571276 | M18: 613
A19: WK-28,2026 | B19: ALL INDIA | C19: JioHotstar | D19: Svod Originals Shows | E19: PAID | F19: Shows | G19: House of the Dragon Season 3 | H19: English,Hindi,Tamil,Telugu | I19: Action,Adventure,Drama | J19: 46195 | K19: =K18+1 -> 12 | L19: 19.419063 | M19: 1189.4553
A20: WK-28,2026 | B20: ALL INDIA | C20: JioHotstar | D20: Theatrical Movies | E20: PAID | F20: Movies | G20: Wuthering Heights | H20: English,Hindi | I20: Drama,Romance | J20: 46216 | K20: =K19+1 -> 13 | L20: 18.791233 | M20: 209.57395
... A57: WK-28,2026 | B57: ALL INDIA | C57: Netflix | D57: SVOD Originals Shows | E57: PAID | F57: Shows | G57: Young Sheldon Season 6 | H57: English | I57: Comedy | J57: 46218 | K57: =K56+1 -> 50 | L57: 12.07726 | M57: 650
C60: Gender
A61: PLATFORM | B61: Total Reach | C61: Male | D61: Female
A62: Netflix | B62: 483.47874 | C62: =VLOOKUP(A:A,'Updated SES'!B:J,8,0) -> 0.49 | D62: =VLOOKUP(A:A,'Updated SES'!B:J,9,0) -> 0.51
A63: JioHotstar | B63: 345.93343 | C63: =VLOOKUP(A:A,'Updated SES'!B:J,8,0) -> 0.625 | D63: =VLOOKUP(A:A,'Updated SES'!B:J,9,0) -> 0.375
A64: Amazon Prime Video | B64: 282.34023 | C64: =VLOOKUP(A:A,'Updated SES'!B:J,8,0) -> 0.52 | D64: =VLOOKUP(A:A,'Updated SES'!B:J,9,0) -> 0.48
A65: Zee5 | B65: 97.136739 | C65: =VLOOKUP(A:A,'Updated SES'!B:J,8,0) -> 0.65 | D65: =VLOOKUP(A:A,'Updated SES'!B:J,9,0) -> 0.35
A66: Amazon Mx Player | B66: 62.244994 | C66: =VLOOKUP(A:A,'Updated SES'!B:J,8,0) -> 0.8 | D66: =VLOOKUP(A:A,'Updated SES'!B:J,9,0) -> 0.2

Sheet Compile data Working
G1: WK-28, 2026 ( 11 Jul 2026 - 17 Jul 2026 )
M3: Genre Weightage%
A4: Week | B4: MARKET | C4: Platform | D4: Live Event | E4: PAID/FREE | F4: Show Type | G4: Shows/Live Content | H4: Language | I4: Release Date | J4: Ranking | K4: Genre | L4: Total Viewers In Mn | M4: Male | N4: Female | O4: Language Weightage % | P4: Ranking Penetration | Q4: Reach | R4: Content format % | S4: Final Reach | T4: WK-28 Reach
A5: Cott Data Servey | B5: ALL INDIA | C5: JioHotstar | D5: Live Event | E5: PAID | F5: Sports | G5: England vs India ODI Series 2026 | H5: Bengali,Bhojpuri,English,Haryanvi,Hindi,Kannada,Tamil,Telugu | I5: 46217 | K5: Sport | L5: =VLOOKUP($C5&$E5,'Updated SES'!A:N,14,0) -> 127.11702 | M5: =VLOOKUP($K5,'Genre Penetration'!A:B,2,0)*VLOOKUP($C5&$E5,'Updated SES'!A:I,9,0) -> 0.5025 | N5: =VLOOKUP(K:K,'Genre Penetration'!A:C,3,0)*VLOOKUP($C5&$E5,'Updated SES'!A:J,10,0) -> 0.0825 | O5: =VLOOKUP($B5,'Language Penetration'!$B$1:$BL$14,MATCH('Compile data Working'!$H5,'Language Penetration'!$B$1:$BL$1,0),0) -> 0.19285714 | P5: =IF(ISBLANK(J5),RANDBETWEEN(1,2)&"%",IF(J5=1,RANDBETWEEN(35,40)&"%",IF(J5=2,RANDBETWEEN(30,35)&"%",IF(J5=3,RANDBETWEEN(25,30)&"%",IF(J5=4,RANDBETWEEN(20,25)&"%",IF(J5=5,RANDBETWEEN(15,20)&"%",IF(J5=6,RANDBETWEEN(10,15)&"%",IF(J5=7,RANDBETWEEN(8,10)&"%",IF(J5=8,RANDBETWEEN(6,8)&"%",IF(J5=9,RANDBETWEEN(4,6)&"%",IF(J5=10,RANDBETWEEN(2,4)&"%",""))))))))))) -> 2% | Q5: =IFERROR(L5*(M5+N5)*O5*P5,RANDBETWEEN(1,2)%*L5*(M5+N5)*O5) -> 0.28683048 | R5: =VLOOKUP(D:D,ranking!W:X,2,0) -> 0.1 | S5: =R5*Q5 -> 0.028683048 | T5: 92.983875
A6: Cott Data Servey | B6: ALL INDIA | C6: Zee5 | D6: Live Event | E6: PAID | F6: Sports | G6: FIFA World Cup 2026 | H6: Bengali,English,Hindi,Malayalam | I6: 46185 | K6: Sport | L6: =VLOOKUP($C6&$E6,'Updated SES'!A:N,14,0) -> 60.152 | M6: =VLOOKUP($K6,'Genre Penetration'!A:B,2,0)*VLOOKUP($C6&$E6,'Updated SES'!A:I,9,0) -> 0.4875 | N6: =VLOOKUP(K:K,'Genre Penetration'!A:C,3,0)*VLOOKUP($C6&$E6,'Updated SES'!A:J,10,0) -> 0.0875 | O6: =VLOOKUP($B6,'Language Penetration'!$B$1:$BL$14,MATCH('Compile data Working'!$H132,'Language Penetration'!$B$1:$BL$1,0),0) -> 0.12 | P6: =IF(ISBLANK(J6),RANDBETWEEN(1,2)&"%",IF(J6=1,RANDBETWEEN(35,40)&"%",IF(J6=2,RANDBETWEEN(30,35)&"%",IF(J6=3,RANDBETWEEN(25,30)&"%",IF(J6=4,RANDBETWEEN(20,25)&"%",IF(J6=5,RANDBETWEEN(15,20)&"%",IF(J6=6,RANDBETWEEN(10,15)&"%",IF(J6=7,RANDBETWEEN(8,10)&"%",IF(J6=8,RANDBETWEEN(6,8)&"%",IF(J6=9,RANDBETWEEN(4,6)&"%",IF(J6=10,RANDBETWEEN(2,4)&"%",""))))))))))) -> 2% | Q6: =IFERROR(L6*(M6+N6)*O6*P6,RANDBETWEEN(1,2)%*L6*(M6+N6)*O6) -> 0.08300976 | R6: =VLOOKUP(D:D,ranking!W:X,2,0) -> 0.1 | S6: =R6*Q6 -> 0.008300976 | T6: 54.261232
A7: WK-28'2026 | B7: ALL INDIA | C7: Amazon Mx Player | D7: AVOD Originals Shows | E7: FREE | F7: Shows | G7: Raktanchal Season 3 | H7: Hindi,Tamil,Telugu | I7: 46219 | K7: Action,Crime,Drama | L7: =VLOOKUP($C7&$E7,'Updated SES'!A:N,14,0) -> 78.93987 | M7: =VLOOKUP($K7,'Genre Penetration'!A:B,2,0)*VLOOKUP($C7&$E7,'Updated SES'!A:I,9,0) -> 0.488 | N7: =VLOOKUP(K:K,'Genre Penetration'!A:C,3,0)*VLOOKUP($C7&$E7,'Updated SES'!A:J,10,0) -> 0.078 | O7: =VLOOKUP($B7,'Language Penetration'!$B$1:$BL$14,MATCH('Compile data Working'!$H38,'Language Penetration'!$B$1:$BL$1,0),0) -> 0.2625 | P7: =IF(ISBLANK(J7),RANDBETWEEN(1,2)&"%",IF(J7=1,RANDBETWEEN(35,40)&"%",IF(J7=2,RANDBETWEEN(30,35)&"%",IF(J7=3,RANDBETWEEN(25,30)&"%",IF(J7=4,RANDBETWEEN(20,25)&"%",IF(J7=5,RANDBETWEEN(15,20)&"%",IF(J7=6,RANDBETWEEN(10,15)&"%",IF(J7=7,RANDBETWEEN(8,10)&"%",IF(J7=8,RANDBETWEEN(6,8)&"%",IF(J7=9,RANDBETWEEN(4,6)&"%",IF(J7=10,RANDBETWEEN(2,4)&"%",""))))))))))) -> 2% | Q7: =IFERROR(L7*(M7+N7)*O7*P7,RANDBETWEEN(1,2)%*L7*(M7+N7)*O7) -> 0.23456982 | R7: =VLOOKUP(D:D,ranking!W:X,2,0) -> 0.6 | S7: =R7*Q7 -> 0.14074189 | T7: 31.519333
A8: Trending Top 10 | B8: ALL INDIA | C8: Netflix | D8: Svod Originals Shows | E8: PAID | F8: Shows | G8: Lock Upp | H8: Hindi | I8: 46200 | J8: 2 | K8: Reality Tv | L8: =VLOOKUP($C8&$E8,'Updated SES'!A:N,14,0) -> 55.4592 | M8: =VLOOKUP($K8,'Genre Penetration'!A:B,2,0)*VLOOKUP($C8&$E8,'Updated SES'!A:I,9,0) -> 0.196 | N8: =VLOOKUP(K:K,'Genre Penetration'!A:C,3,0)*VLOOKUP($C8&$E8,'Updated SES'!A:J,10,0) -> 0.306 | O8: =VLOOKUP($B8,'Language Penetration'!$B$1:$BL$14,MATCH('Compile data Working'!$H98,'Language Penetration'!$B$1:$BL$1,0),0) -> 0.204 | P8: =IF(ISBLANK(J8),RANDBETWEEN(1,2)&"%",IF(J8=1,RANDBETWEEN(35,40)&"%",IF(J8=2,RANDBETWEEN(30,35)&"%",IF(J8=3,RANDBETWEEN(25,30)&"%",IF(J8=4,RANDBETWEEN(20,25)&"%",IF(J8=5,RANDBETWEEN(15,20)&"%",IF(J8=6,RANDBETWEEN(10,15)&"%",IF(J8=7,RANDBETWEEN(8,10)&"%",IF(J8=8,RANDBETWEEN(6,8)&"%",IF(J8=9,RANDBETWEEN(4,6)&"%",IF(J8=10,RANDBETWEEN(2,4)&"%",""))))))))))) -> 31% | Q8: =IFERROR(L8*(M8+N8)*O8*P8,RANDBETWEEN(1,2)%*L8*(M8+N8)*O8) -> 1.7606344 | R8: =VLOOKUP(D:D,ranking!W:X,2,0) -> 0.6 | S8: =R8*Q8 -> 1.0563806 | T8: 24.197959
A9: Trending Top 10 | B9: ALL INDIA | C9: Netflix | D9: SVOD Originals Movies | E9: PAID | F9: Movies | G9: Ikka | H9: English,Hindi,Tamil,Telugu | I9: 46213 | J9: 1 | K9: Crime,Drama,Thriller | L9: =VLOOKUP($C9&$E9,'Updated SES'!A:N,14,0) -> 55.4592 | M9: =VLOOKUP($K9,'Genre Penetration'!A:B,2,0)*VLOOKUP($C9&$E9,'Updated SES'!A:I,9,0) -> 0.3528 | N9: =VLOOKUP(K:K,'Genre Penetration'!A:C,3,0)*VLOOKUP($C9&$E9,'Updated SES'!A:J,10,0) -> 0.1428 | O9: =VLOOKUP($B9,'Language Penetration'!$B$1:$BL$14,MATCH('Compile data Working'!$H90,'Language Penetration'!$B$1:$BL$1,0),0) -> 0.204 | P9: =IF(ISBLANK(J9),RANDBETWEEN(1,2)&"%",IF(J9=1,RANDBETWEEN(35,40)&"%",IF(J9=2,RANDBETWEEN(30,35)&"%",IF(J9=3,RANDBETWEEN(25,30)&"%",IF(J9=4,RANDBETWEEN(20,25)&"%",IF(J9=5,RANDBETWEEN(15,20)&"%",IF(J9=6,RANDBETWEEN(10,15)&"%",IF(J9=7,RANDBETWEEN(8,10)&"%",IF(J9=8,RANDBETWEEN(6,8)&"%",IF(J9=9,RANDBETWEEN(4,6)&"%",IF(J9=10,RANDBETWEEN(2,4)&"%",""))))))))))) -> 35% | Q9: =IFERROR(L9*(M9+N9)*O9*P9,RANDBETWEEN(1,2)%*L9*(M9+N9)*O9) -> 1.9624704 | R9: =VLOOKUP(D:D,ranking!W:X,2,0) -> 0.8 | S9: =R9*Q9 -> 1.5699763 | T9: 22.341902
A10: Trending Top 10 | B10: ALL INDIA | C10: JioHotstar | D10: Svod Originals Shows | E10: PAID | F10: Shows | G10: Pritam And Pedro | H10: Bengali,Bhojpuri,Haryanvi,Hindi,Kannada,Marathi,Tamil,Telugu | I10: 46206 | J10: 4 | K10: Crime,Drama,Thriller | L10: =VLOOKUP($C10&$E10,'Updated SES'!A:N,14,0) -> 127.11702 | M10: =VLOOKUP($K10,'Genre Penetration'!A:B,2,0)*VLOOKUP($C10&$E10,'Updated SES'!A:I,9,0) -> 0.4824 | N10: =VLOOKUP(K:K,'Genre Penetration'!A:C,3,0)*VLOOKUP($C10&$E10,'Updated SES'!A:J,10,0) -> 0.0924 | O10: =VLOOKUP($B10,'Language Penetration'!$B$1:$BL$14,MATCH('Compile data Working'!$H86,'Language Penetration'!$B$1:$BL$1,0),0) -> 0.1 | P10: =IF(ISBLANK(J10),RANDBETWEEN(1,2)&"%",IF(J10=1,RANDBETWEEN(35,40)&"%",IF(J10=2,RANDBETWEEN(30,35)&"%",IF(J10=3,RANDBETWEEN(25,30)&"%",IF(J10=4,RANDBETWEEN(20,25)&"%",IF(J10=5,RANDBETWEEN(15,20)&"%",IF(J10=6,RANDBETWEEN(10,15)&"%",IF(J10=7,RANDBETWEEN(8,10)&"%",IF(J10=8,RANDBETWEEN(6,8)&"%",IF(J10=9,RANDBETWEEN(4,6)&"%",IF(J10=10,RANDBETWEEN(2,4)&"%",""))))))))))) -> 23% | Q10: =IFERROR(L10*(M10+N10)*O10*P10,RANDBETWEEN(1,2)%*L10*(M10+N10)*O10) -> 1.6805379 | R10: =VLOOKUP(D:D,ranking!W:X,2,0) -> 0.6 | S10: =R10*Q10 -> 1.0083227 | T10: 21.809854
A11: Trending Top 10 | B11: ALL INDIA | C11: Amazon Prime Video | D11: Svod Originals Shows | E11: PAID | F11: Shows | G11: Alliance | H11: Hindi | I11: 46199 | J11: 1 | K11: Reality Tv | L11: =VLOOKUP($C11&$E11,'Updated SES'!A:N,14,0) -> 36.49824 | M11: =VLOOKUP($K11,'Genre Penetration'!A:B,2,0)*VLOOKUP($C11&$E11,'Updated SES'!A:I,9,0) -> 0.208 | N11: =VLOOKUP(K:K,'Genre Penetration'!A:C,3,0)*VLOOKUP($C11&$E11,'Updated SES'!A:J,10,0) -> 0.288 | O11: =VLOOKUP($B11,'Language Penetration'!$B$1:$BL$14,MATCH('Compile data Working'!$H76,'Language Penetration'!$B$1:$BL$1,0),0) -> 0.6 | P11: =IF(ISBLANK(J11),RANDBETWEEN(1,2)&"%",IF(J11=1,RANDBETWEEN(35,40)&"%",IF(J11=2,RANDBETWEEN(30,35)&"%",IF(J11=3,RANDBETWEEN(25,30)&"%",IF(J11=4,RANDBETWEEN(20,25)&"%",IF(J11=5,RANDBETWEEN(15,20)&"%",IF(J11=6,RANDBETWEEN(10,15)&"%",IF(J11=7,RANDBETWEEN(8,10)&"%",IF(J11=8,RANDBETWEEN(6,8)&"%",IF(J11=9,RANDBETWEEN(4,6)&"%",IF(J11=10,RANDBETWEEN(2,4)&"%",""))))))))))) -> 35% | Q11: =IFERROR(L11*(M11+N11)*O11*P11,RANDBETWEEN(1,2)%*L11*(M11+N11)*O11) -> 3.8016567 | R11: =VLOOKUP(D:D,ranking!W:X,2,0) -> 0.6 | S11: =R11*Q11 -> 2.280994 | T11: 21.303523
A12: WK-28'2026 | B12: ALL INDIA | C12: JioHotstar | D12: Theatrical Movies | E12: PAID | F12: Movies | G12: Chand Mera Dil | H12: Hindi | I12: 46220 | K12: Drama,Romance | L12: =VLOOKUP($C12&$E12,'Updated SES'!A:N,14,0) -> 127.11702 | M12: =VLOOKUP($K12,'Genre Penetration'!A:B,2,0)*VLOOKUP($C12&$E12,'Updated SES'!A:I,9,0) -> 0.268 | N12: =VLOOKUP(K:K,'Genre Penetration'!A:C,3,0)*VLOOKUP($C12&$E12,'Updated SES'!A:J,10,0) -> 0.198 | O12: =VLOOKUP($B12,'Language Penetration'!$B$1:$BL$14,MATCH('Compile data Working'!$H45,'Language Penetration'!$B$1:$BL$1,0),0) -> 0.4 | P12: =IF(ISBLANK(J12),RANDBETWEEN(1,2)&"%",IF(J12=1,RANDBETWEEN(35,40)&"%",IF(J12=2,RANDBETWEEN(30,35)&"%",IF(J12=3,RANDBETWEEN(25,30)&"%",IF(J12=4,RANDBETWEEN(20,25)&"%",IF(J12=5,RANDBETWEEN(15,20)&"%",IF(J12=6,RANDBETWEEN(10,15)&"%",IF(J12=7,RANDBETWEEN(8,10)&"%",IF(J12=8,RANDBETWEEN(6,8)&"%",IF(J12=9,RANDBETWEEN(4,6)&"%",IF(J12=10,RANDBETWEEN(2,4)&"%",""))))))))))) -> 1% | Q12: =IFERROR(L12*(M12+N12)*O12*P12,RANDBETWEEN(1,2)%*L12*(M12+N12)*O12) -> 0.23694613 | R12: =VLOOKUP(D:D,ranking!W:X,2,0) -> 0.7 | S12: =R12*Q12 -> 0.16586229 | T12: 20.892084
A13: Trending Top 10 | B13: ALL INDIA | C13: Netflix | D13: Svod Originals Shows | E13: PAID | F13: Shows | G13: India’s Got Latent Season 2 | H13: Hindi | I13: 46193 | J13: 1 | K13: Comedy | L13: =VLOOKUP($C13&$E13,'Updated SES'!A:N,14,0) -> 55.4592 | M13: =VLOOKUP($K13,'Genre Penetration'!A:B,2,0)*VLOOKUP($C13&$E13,'Updated SES'!A:I,9,0) -> 0.2205 | N13: =VLOOKUP(K:K,'Genre Penetration'!A:C,3,0)*VLOOKUP($C13&$E13,'Updated SES'!A:J,10,0) -> 0.2805 | O13: =VLOOKUP($B13,'Language Penetration'!$B$1:$BL$14,MATCH('Compile data Working'!$H97,'Language Penetration'!$B$1:$BL$1,0),0) -> 0.12 | P13: =IF(ISBLANK(J13),RANDBETWEEN(1,2)&"%",IF(J13=1,RANDBETWEEN(35,40)&"%",IF(J13=2,RANDBETWEEN(30,35)&"%",IF(J13=3,RANDBETWEEN(25,30)&"%",IF(J13=4,RANDBETWEEN(20,25)&"%",IF(J13=5,RANDBETWEEN(15,20)&"%",IF(J13=6,RANDBETWEEN(10,15)&"%",IF(J13=7,RANDBETWEEN(8,10)&"%",IF(J13=8,RANDBETWEEN(6,8)&"%",IF(J13=9,RANDBETWEEN(4,6)&"%",IF(J13=10,RANDBETWEEN(2,4)&"%",""))))))))))) -> 36% | Q13: =IFERROR(L13*(M13+N13)*O13*P13,RANDBETWEEN(1,2)%*L13*(M13+N13)*O13) -> 1.2003146 | R13: =VLOOKUP(D:D,ranking!W:X,2,0) -> 0.6 | S13: =R13*Q13 -> 0.72018873 | T13: 20.585342
A14: WK-28'2026 | B14: ALL INDIA | C14: Amazon Prime Video | D14: Theatrical Movies | E14: PAID | F14: Movies | G14: Ek Din | H14: Hindi,Tamil,Telugu | I14: 46220 | K14: Drama,Romance | L14: =VLOOKUP($C14&$E14,'Updated SES'!A:N,14,0) -> 36.49824 | M14: =VLOOKUP($K14,'Genre Penetration'!A:B,2,0)*VLOOKUP($C14&$E14,'Updated SES'!A:I,9,0) -> 0.208 | N14: =VLOOKUP(K:K,'Genre Penetration'!A:C,3,0)*VLOOKUP($C14&$E14,'Updated SES'!A:J,10,0) -> 0.288 | O14: =VLOOKUP($B14,'Language Penetration'!$B$1:$BL$14,MATCH('Compile data Working'!$H49,'Language Penetration'!$B$1:$BL$1,0),0) -> 0.2 | P14: =IF(ISBLANK(J14),RANDBETWEEN(1,2)&"%",IF(J14=1,RANDBETWEEN(35,40)&"%",IF(J14=2,RANDBETWEEN(30,35)&"%",IF(J14=3,RANDBETWEEN(25,30)&"%",IF(J14=4,RANDBETWEEN(20,25)&"%",IF(J14=5,RANDBETWEEN(15,20)&"%",IF(J14=6,RANDBETWEEN(10,15)&"%",IF(J14=7,RANDBETWEEN(8,10)&"%",IF(J14=8,RANDBETWEEN(6,8)&"%",IF(J14=9,RANDBETWEEN(4,6)&"%",IF(J14=10,RANDBETWEEN(2,4)&"%",""))))))))))) -> 1% | Q14: =IFERROR(L14*(M14+N14)*O14*P14,RANDBETWEEN(1,2)%*L14*(M14+N14)*O14) -> 0.036206254 | R14: =VLOOKUP(D:D,ranking!W:X,2,0) -> 0.7 | S14: =R14*Q14 -> 0.025344378 | T14: 19.822692
A15: WK-28'2026 | B15: ALL INDIA | C15: Netflix | D15: SVOD Originals Shows | E15: PAID | F15: Shows | G15: The Apartment Job | H15: English,Hindi | I15: 46214 | K15: Crime,Drama,Thriller | L15: =VLOOKUP($C15&$E15,'Updated SES'!A:N,14,0) -> 55.4592 | M15: =VLOOKUP($K15,'Genre Penetration'!A:B,2,0)*VLOOKUP($C15&$E15,'Updated SES'!A:I,9,0) -> 0.3528 | N15: =VLOOKUP(K:K,'Genre Penetration'!A:C,3,0)*VLOOKUP($C15&$E15,'Updated SES'!A:J,10,0) -> 0.1428 | O15: =VLOOKUP($B15,'Language Penetration'!$B$1:$BL$14,MATCH('Compile data Working'!$H9,'Language Penetration'!$B$1:$BL$1,0),0) -> 0.2625 | P15: =IF(ISBLANK(J15),RANDBETWEEN(1,2)&"%",IF(J15=1,RANDBETWEEN(35,40)&"%",IF(J15=2,RANDBETWEEN(30,35)&"%",IF(J15=3,RANDBETWEEN(25,30)&"%",IF(J15=4,RANDBETWEEN(20,25)&"%",IF(J15=5,RANDBETWEEN(15,20)&"%",IF(J15=6,RANDBETWEEN(10,15)&"%",IF(J15=7,RANDBETWEEN(8,10)&"%",IF(J15=8,RANDBETWEEN(6,8)&"%",IF(J15=9,RANDBETWEEN(4,6)&"%",IF(J15=10,RANDBETWEEN(2,4)&"%",""))))))))))) -> 1% | Q15: =IFERROR(L15*(M15+N15)*O15*P15,RANDBETWEEN(1,2)%*L15*(M15+N15)*O15) -> 0.072149646 | R15: =VLOOKUP(D:D,ranking!W:X,2,0) -> 0.6 | S15: =R15*Q15 -> 0.043289788 | T15: 19.571276
A16: Trending Top 10 | B16: ALL INDIA | C16: JioHotstar | D16: Svod Originals Shows | E16: PAID | F16: Shows | G16: House of the Dragon Season 3 | H16: English,Hindi,Tamil,Telugu | I16: 46195 | J16: 5 | K16: Action,Adventure,Drama | L16: =VLOOKUP($C16&$E16,'Updated SES'!A:N,14,0) -> 127.11702 | M16: =VLOOKUP($K16,'Genre Penetration'!A:B,2,0)*VLOOKUP($C16&$E16,'Updated SES'!A:I,9,0) -> 0.3886 | N16: =VLOOKUP(K:K,'Genre Penetration'!A:C,3,0)*VLOOKUP($C16&$E16,'Updated SES'!A:J,10,0) -> 0.1386 | O16: =VLOOKUP($B16,'Language Penetration'!$B$1:$BL$14,MATCH('Compile data Working'!$H87,'Language Penetration'!$B$1:$BL$1,0),0) -> 0.6 | P16: =IF(ISBLANK(J16),RANDBETWEEN(1,2)&"%",IF(J16=1,RANDBETWEEN(35,40)&"%",IF(J16=2,RANDBETWEEN(30,35)&"%",IF(J16=3,RANDBETWEEN(25,30)&"%",IF(J16=4,RANDBETWEEN(20,25)&"%",IF(J16=5,RANDBETWEEN(15,20)&"%",IF(J16=6,RANDBETWEEN(10,15)&"%",IF(J16=7,RANDBETWEEN(8,10)&"%",IF(J16=8,RANDBETWEEN(6,8)&"%",IF(J16=9,RANDBETWEEN(4,6)&"%",IF(J16=10,RANDBETWEEN(2,4)&"%",""))))))))))) -> 16% | Q16: =IFERROR(L16*(M16+N16)*O16*P16,RANDBETWEEN(1,2)%*L16*(M16+N16)*O16) -> 6.4335449 | R16: =VLOOKUP(D:D,ranking!W:X,2,0) -> 0.6 | S16: =R16*Q16 -> 3.860127 | T16: 19.419063
A17: WK-28'2026 | B17: ALL INDIA | C17: JioHotstar | D17: Theatrical Movies | E17: PAID | F17: Movies | G17: Wuthering Heights | H17: English,Hindi | I17: 46216 | K17: Drama,Romance | L17: =VLOOKUP($C17&$E17,'Updated SES'!A:N,14,0) -> 127.11702 | M17: =VLOOKUP($K17,'Genre Penetration'!A:B,2,0)*VLOOKUP($C17&$E17,'Updated SES'!A:I,9,0) -> 0.268 | N17: =VLOOKUP(K:K,'Genre Penetration'!A:C,3,0)*VLOOKUP($C17&$E17,'Updated SES'!A:J,10,0) -> 0.198 | O17: =VLOOKUP($B17,'Language Penetration'!$B$1:$BL$14,MATCH('Compile data Working'!$H17,'Language Penetration'!$B$1:$BL$1,0),0) -> 0.4 | P17: =IF(ISBLANK(J17),RANDBETWEEN(1,2)&"%",IF(J17=1,RANDBETWEEN(35,40)&"%",IF(J17=2,RANDBETWEEN(30,35)&"%",IF(J17=3,RANDBETWEEN(25,30)&"%",IF(J17=4,RANDBETWEEN(20,25)&"%",IF(J17=5,RANDBETWEEN(15,20)&"%",IF(J17=6,RANDBETWEEN(10,15)&"%",IF(J17=7,RANDBETWEEN(8,10)&"%",IF(J17=8,RANDBETWEEN(6,8)&"%",IF(J17=9,RANDBETWEEN(4,6)&"%",IF(J17=10,RANDBETWEEN(2,4)&"%",""))))))))))) -> 2% | Q17: =IFERROR(L17*(M17+N17)*O17*P17,RANDBETWEEN(1,2)%*L17*(M17+N17)*O17) -> 0.47389225 | R17: =VLOOKUP(D:D,ranking!W:X,2,0) -> 0.7 | S17: =R17*Q17 -> 0.33172458 | T17: 18.791233
A18: Trending Top 10 | B18: ALL INDIA | C18: Netflix | D18: Theatrical Movies | E18: PAID | F18: Movies | G18: Pati Patni Aur Woh Do | H18: Hindi | I18: 46213 | J18: 2 | K18: Comedy,Drama,Romance | L18: =VLOOKUP($C18&$E18,'Updated SES'!A:N,14,0) -> 55.4592 | M18: =VLOOKUP($K18,'Genre Penetration'!A:B,2,0)*VLOOKUP($C18&$E18,'Updated SES'!A:I,9,0) -> 0.1813 | N18: =VLOOKUP(K:K,'Genre Penetration'!A:C,3,0)*VLOOKUP($C18&$E18,'Updated SES'!A:J,10,0) -> 0.3213 | O18: =VLOOKUP($B18,'Language Penetration'!$B$1:$BL$14,MATCH('Compile data Working'!$H91,'Language Penetration'!$B$1:$BL$1,0),0) -> 0.6 | P18: =IF(ISBLANK(J18),RANDBETWEEN(1,2)&"%",IF(J18=1,RANDBETWEEN(35,40)&"%",IF(J18=2,RANDBETWEEN(30,35)&"%",IF(J18=3,RANDBETWEEN(25,30)&"%",IF(J18=4,RANDBETWEEN(20,25)&"%",IF(J18=5,RANDBETWEEN(15,20)&"%",IF(J18=6,RANDBETWEEN(10,15)&"%",IF(J18=7,RANDBETWEEN(8,10)&"%",IF(J18=8,RANDBETWEEN(6,8)&"%",IF(J18=9,RANDBETWEEN(4,6)&"%",IF(J18=10,RANDBETWEEN(2,4)&"%",""))))))))))) -> 30% | Q18: =IFERROR(L18*(M18+N18)*O18*P18,RANDBETWEEN(1,2)%*L18*(M18+N18)*O18) -> 5.0172829 | R18: =VLOOKUP(D:D,ranking!W:X,2,0) -> 0.7 | S18: =R18*Q18 -> 3.512098 | T18: 18.315602
A19: WK-28'2026 | B19: ALL INDIA | C19: Amazon Prime Video | D19: Theatrical Movies | E19: PAID | F19: Movies | G19: Passenger | H19: English,Hindi | I19: 46216 | K19: Horror,Thriller | L19: =VLOOKUP($C19&$E19,'Updated SES'!A:N,14,0) -> 36.49824 | M19: =VLOOKUP($K19,'Genre Penetration'!A:B,2,0)*VLOOKUP($C19&$E19,'Updated SES'!A:I,9,0) -> 0.364 | N19: =VLOOKUP(K:K,'Genre Penetration'!A:C,3,0)*VLOOKUP($C19&$E19,'Updated SES'!A:J,10,0) -> 0.144 | O19: =VLOOKUP($B19,'Language Penetration'!$B$1:$BL$14,MATCH('Compile data Working'!$H14,'Language Penetration'!$B$1:$BL$1,0),0) -> 0.28333333 | P19: =IF(ISBLANK(J19),RANDBETWEEN(1,2)&"%",IF(J19=1,RANDBETWEEN(35,40)&"%",IF(J19=2,RANDBETWEEN(30,35)&"%",IF(J19=3,RANDBETWEEN(25,30)&"%",IF(J19=4,RANDBETWEEN(20,25)&"%",IF(J19=5,RANDBETWEEN(15,20)&"%",IF(J19=6,RANDBETWEEN(10,15)&"%",IF(J19=7,RANDBETWEEN(8,10)&"%",IF(J19=8,RANDBETWEEN(6,8)&"%",IF(J19=9,RANDBETWEEN(4,6)&"%",IF(J19=10,RANDBETWEEN(2,4)&"%",""))))))))))) -> 1% | Q19: =IFERROR(L19*(M19+N19)*O19*P19,RANDBETWEEN(1,2)%*L19*(M19+N19)*O19) -> 0.052533133 | R19: =VLOOKUP(D:D,ranking!W:X,2,0) -> 0.7 | S19: =R19*Q19 -> 0.036773193 | T19: 18.170801
A20: Trending Top 10 | B20: ALL INDIA | C20: Amazon Prime Video | D20: Svod Originals Shows | E20: PAID | F20: Shows | G20: Gram Chikitsalay S2 | H20: Hindi | I20: 46196 | J20: 3 | K20: Comedy,Drama | L20: =VLOOKUP($C20&$E20,'Updated SES'!A:N,14,0) -> 36.49824 | M20: =VLOOKUP($K20,'Genre Penetration'!A:B,2,0)*VLOOKUP($C20&$E20,'Updated SES'!A:I,9,0) -> 0.2444 | N20: =VLOOKUP(K:K,'Genre Penetration'!A:C,3,0)*VLOOKUP($C20&$E20,'Updated SES'!A:J,10,0) -> 0.2544 | O20: =VLOOKUP($B20,'Language Penetration'!$B$1:$BL$14,MATCH('Compile data Working'!$H77,'Language Penetration'!$B$1:$BL$1,0),0) -> 0.2 | P20: =IF(ISBLANK(J20),RANDBETWEEN(1,2)&"%",IF(J20=1,RANDBETWEEN(35,40)&"%",IF(J20=2,RANDBETWEEN(30,35)&"%",IF(J20=3,RANDBETWEEN(25,30)&"%",IF(J20=4,RANDBETWEEN(20,25)&"%",IF(J20=5,RANDBETWEEN(15,20)&"%",IF(J20=6,RANDBETWEEN(10,15)&"%",IF(J20=7,RANDBETWEEN(8,10)&"%",IF(J20=8,RANDBETWEEN(6,8)&"%",IF(J20=9,RANDBETWEEN(4,6)&"%",IF(J20=10,RANDBETWEEN(2,4)&"%",""))))))))))) -> 29% | Q20: =IFERROR(L20*(M20+N20)*O20*P20,RANDBETWEEN(1,2)%*L20*(M20+N20)*O20) -> 1.0559087 | R20: =VLOOKUP(D:D,ranking!W:X,2,0) -> 0.6 | S20: =R20*Q20 -> 0.63354521 | T20: 17.147691
A21: Trending Top 10 | B21: ALL INDIA | C21: Amazon Prime Video | D21: Svod Originals Shows | E21: PAID | F21: Shows | G21: Isakapatnam | H21: Hindi,Kannada,Malayalam,Tamil,Telugu | I21: 46205 | J21: 7 | K21: Action,Crime,Drama | L21: =VLOOKUP($C21&$E21,'Updated SES'!A:N,14,0) -> 36.49824 | M21: =VLOOKUP($K21,'Genre Penetration'!A:B,2,0)*VLOOKUP($C21&$E21,'Updated SES'!A:I,9,0) -> 0.3172 | N21: =VLOOKUP(K:K,'Genre Penetration'!A:C,3,0)*VLOOKUP($C21&$E21,'Updated SES'!A:J,10,0) -> 0.1872 | O21: =VLOOKUP($B21,'Language Penetration'!$B$1:$BL$14,MATCH('Compile data Working'!$H81,'Language Penetration'!$B$1:$BL$1,0),0) -> 0.2625 | P21: =IF(ISBLANK(J21),RANDBETWEEN(1,2)&"%",IF(J21=1,RANDBETWEEN(35,40)&"%",IF(J21=2,RANDBETWEEN(30,35)&"%",IF(J21=3,RANDBETWEEN(25,30)&"%",IF(J21=4,RANDBETWEEN(20,25)&"%",IF(J21=5,RANDBETWEEN(15,20)&"%",IF(J21=6,RANDBETWEEN(10,15)&"%",IF(J21=7,RANDBETWEEN(8,10)&"%",IF(J21=8,RANDBETWEEN(6,8)&"%",IF(J21=9,RANDBETWEEN(4,6)&"%",IF(J21=10,RANDBETWEEN(2,4)&"%",""))))))))))) -> 8% | Q21: =IFERROR(L21*(M21+N21)*O21*P21,RANDBETWEEN(1,2)%*L21*(M21+N21)*O21) -> 0.38660396 | R21: =VLOOKUP(D:D,ranking!W:X,2,0) -> 0.6 | S21: =R21*Q21 -> 0.23196237 | T21: 16.765524
A22: Trending Top 10 | B22: ALL INDIA | C22: JioHotstar | D22: Svod Originals Shows | E22: PAID | F22: Shows | G22: Thukra Ke Mera Pyaar Season 2 | H22: Bengali,Bhojpuri,Hindi,Kannada,Malayalam,Marathi,Tamil,Telugu | I22: 46192 | J22: 1 | K22: Romance | L22: =VLOOKUP($C22&$E22,'Updated SES'!A:N,14,0) -> 127.11702 | M22: =VLOOKUP($K22,'Genre Penetration'!A:B,2,0)*VLOOKUP($C22&$E22,'Updated SES'!A:I,9,0) -> 0.3015 | N22: =VLOOKUP(K:K,'Genre Penetration'!A:C,3,0)*VLOOKUP($C22&$E22,'Updated SES'!A:J,10,0) -> 0.1815 | O22: =VLOOKUP($B22,'Language Penetration'!$B$1:$BL$14,MATCH('Compile data Working'!$H84,'Language Penetration'!$B$1:$BL$1,0),0) -> 0.6 | P22: =IF(ISBLANK(J22),RANDBETWEEN(1,2)&"%",IF(J22=1,RANDBETWEEN(35,40)&"%",IF(J22=2,RANDBETWEEN(30,35)&"%",IF(J22=3,RANDBETWEEN(25,30)&"%",IF(J22=4,RANDBETWEEN(20,25)&"%",IF(J22=5,RANDBETWEEN(15,20)&"%",IF(J22=6,RANDBETWEEN(10,15)&"%",IF(J22=7,RANDBETWEEN(8,10)&"%",IF(J22=8,RANDBETWEEN(6,8)&"%",IF(J22=9,RANDBETWEEN(4,6)&"%",IF(J22=10,RANDBETWEEN(2,4)&"%",""))))))))))) -> 39% | Q22: =IFERROR(L22*(M22+N22)*O22*P22,RANDBETWEEN(1,2)%*L22*(M22+N22)*O22) -> 14.36702 | R22: =VLOOKUP(D:D,ranking!W:X,2,0) -> 0.6 | S22: =R22*Q22 -> 8.6202119 | T22: 16.744785
A23: Trending Top 10 | B23: ALL INDIA | C23: JioHotstar | D23: Tv Catch-Up | E23: PAID | F23: Tv catchup | G23: Laughter Chefs S3 | H23: Hindi | I23: 45983 | J23: 2 | K23: Comedy,Reality-Tv | L23: =VLOOKUP($C23&$E23,'Updated SES'!A:N,14,0) -> 127.11702 | M23: =VLOOKUP($K23,'Genre Penetration'!A:B,2,0)*VLOOKUP($C23&$E23,'Updated SES'!A:I,9,0) -> 0.335 | N23: =VLOOKUP(K:K,'Genre Penetration'!A:C,3,0)*VLOOKUP($C23&$E23,'Updated SES'!A:J,10,0) -> 0.165 | O23: =VLOOKUP($B23,'Language Penetration'!$B$1:$BL$14,MATCH('Compile data Working'!$H85,'Language Penetration'!$B$1:$BL$1,0),0) -> 0.204 | P23: =IF(ISBLANK(J23),RANDBETWEEN(1,2)&"%",IF(J23=1,RANDBETWEEN(35,40)&"%",IF(J23=2,RANDBETWEEN(30,35)&"%",IF(J23=3,RANDBETWEEN(25,30)&"%",IF(J23=4,RANDBETWEEN(20,25)&"%",IF(J23=5,RANDBETWEEN(15,20)&"%",IF(J23=6,RANDBETWEEN(10,15)&"%",IF(J23=7,RANDBETWEEN(8,10)&"%",IF(J23=8,RANDBETWEEN(6,8)&"%",IF(J23=9,RANDBETWEEN(4,6)&"%",IF(J23=10,RANDBETWEEN(2,4)&"%",""))))))))))) -> 34% | Q23: =IFERROR(L23*(M23+N23)*O23*P23,RANDBETWEEN(1,2)%*L23*(M23+N23)*O23) -> 4.4084183 | R23: =VLOOKUP(D:D,ranking!W:X,2,0) -> 0.3 | S23: =R23*Q23 -> 1.3225255 | T23: 16.629948
A24: WK-28'2026 | B24: ALL INDIA | C24: JioHotstar | D24: SVOD Originals Shows | E24: PAID | F24: Shows | G24: Second Love | H24: Hindi,Kannada,Malayalam,Tamil,Telugu | I24: 46216 | K24: Reality Tv | L24: =VLOOKUP($C24&$E24,'Updated SES'!A:N,14,0) -> 127.11702 | M24: =VLOOKUP($K24,'Genre Penetration'!A:B,2,0)*VLOOKUP($C24&$E24,'Updated SES'!A:I,9,0) -> 0.268 | N24: =VLOOKUP(K:K,'Genre Penetration'!A:C,3,0)*VLOOKUP($C24&$E24,'Updated SES'!A:J,10,0) -> 0.198 | O24: =VLOOKUP($B24,'Language Penetration'!$B$1:$BL$14,MATCH('Compile data Working'!$H16,'Language Penetration'!$B$1:$BL$1,0),0) -> 0.2625 | P24: =IF(ISBLANK(J24),RANDBETWEEN(1,2)&"%",IF(J24=1,RANDBETWEEN(35,40)&"%",IF(J24=2,RANDBETWEEN(30,35)&"%",IF(J24=3,RANDBETWEEN(25,30)&"%",IF(J24=4,RANDBETWEEN(20,25)&"%",IF(J24=5,RANDBETWEEN(15,20)&"%",IF(J24=6,RANDBETWEEN(10,15)&"%",IF(J24=7,RANDBETWEEN(8,10)&"%",IF(J24=8,RANDBETWEEN(6,8)&"%",IF(J24=9,RANDBETWEEN(4,6)&"%",IF(J24=10,RANDBETWEEN(2,4)&"%",""))))))))))) -> 1% | Q24: =IFERROR(L24*(M24+N24)*O24*P24,RANDBETWEEN(1,2)%*L24*(M24+N24)*O24) -> 0.15549589 | R24: =VLOOKUP(D:D,ranking!W:X,2,0) -> 0.6 | S24: =R24*Q24 -> 0.093297537 | T24: 16.419063
A25: Trending Top 10 | B25: ALL INDIA | C25: Netflix | D25: Theatrical Movies | E25: PAID | F25: Movies | G25: Peddi | H25: Kannada,Malayalam,Tamil,Telugu | I25: 46212 | J25: 4 | K25: Action,Drama | L25: =VLOOKUP($C25&$E25,'Updated SES'!A:N,14,0) -> 55.4592 | M25: =VLOOKUP($K25,'Genre Penetration'!A:B,2,0)*VLOOKUP($C25&$E25,'Updated SES'!A:I,9,0) -> 0.2597 | N25: =VLOOKUP(K:K,'Genre Penetration'!A:C,3,0)*VLOOKUP($C25&$E25,'Updated SES'!A:J,10,0) -> 0.2397 | O25: =VLOOKUP($B25,'Language Penetration'!$B$1:$BL$14,MATCH('Compile data Working'!$H92,'Language Penetration'!$B$1:$BL$1,0),0) -> 0.27166667 | P25: =IF(ISBLANK(J25),RANDBETWEEN(1,2)&"%",IF(J25=1,RANDBETWEEN(35,40)&"%",IF(J25=2,RANDBETWEEN(30,35)&"%",IF(J25=3,RANDBETWEEN(25,30)&"%",IF(J25=4,RANDBETWEEN(20,25)&"%",IF(J25=5,RANDBETWEEN(15,20)&"%",IF(J25=6,RANDBETWEEN(10,15)&"%",IF(J25=7,RANDBETWEEN(8,10)&"%",IF(J25=8,RANDBETWEEN(6,8)&"%",IF(J25=9,RANDBETWEEN(4,6)&"%",IF(J25=10,RANDBETWEEN(2,4)&"%",""))))))))))) -> 23% | Q25: =IFERROR(L25*(M25+N25)*O25*P25,RANDBETWEEN(1,2)%*L25*(M25+N25)*O25) -> 1.7305587 | R25: =VLOOKUP(D:D,ranking!W:X,2,0) -> 0.7 | S25: =R25*Q25 -> 1.2113911 | T25: 16.289302
A26: Trending Top 10 | B26: ALL INDIA | C26: Netflix | D26: Theatrical Movies | E26: PAID | F26: Movies | G26: Blast | H26: Hindi,Kannada,Malayalam,Tamil,Telugu | I26: 46198 | J26: 6 | K26: Action,Drama | L26: =VLOOKUP($C26&$E26,'Updated SES'!A:N,14,0) -> 55.4592 | M26: =VLOOKUP($K26,'Genre Penetration'!A:B,2,0)*VLOOKUP($C26&$E26,'Updated SES'!A:I,9,0) -> 0.2597 | N26: =VLOOKUP(K:K,'Genre Penetration'!A:C,3,0)*VLOOKUP($C26&$E26,'Updated SES'!A:J,10,0) -> 0.2397 | O26: =VLOOKUP($B26,'Language Penetration'!$B$1:$BL$14,MATCH('Compile data Working'!$H94,'Language Penetration'!$B$1:$BL$1,0),0) -> 0.6 | P26: =IF(ISBLANK(J26),RANDBETWEEN(1,2)&"%",IF(J26=1,RANDBETWEEN(35,40)&"%",IF(J26=2,RANDBETWEEN(30,35)&"%",IF(J26=3,RANDBETWEEN(25,30)&"%",IF(J26=4,RANDBETWEEN(20,25)&"%",IF(J26=5,RANDBETWEEN(15,20)&"%",IF(J26=6,RANDBETWEEN(10,15)&"%",IF(J26=7,RANDBETWEEN(8,10)&"%",IF(J26=8,RANDBETWEEN(6,8)&"%",IF(J26=9,RANDBETWEEN(4,6)&"%",IF(J26=10,RANDBETWEEN(2,4)&"%",""))))))))))) -> 10% | Q26: =IFERROR(L26*(M26+N26)*O26*P26,RANDBETWEEN(1,2)%*L26*(M26+N26)*O26) -> 1.6617795 | R26: =VLOOKUP(D:D,ranking!W:X,2,0) -> 0.7 | S26: =R26*Q26 -> 1.1632456 | T26: 16.178457
A27: WK-28'2026 | B27: ALL INDIA | C27: Amazon Prime Video | D27: SVOD Originals Shows | E27: PAID | F27: Shows | G27: Ride or Die | H27: English,Hindi,Kannada,Malayalam,Tamil,Telugu | I27: 46218 | K27: Action,Adventure,Drama | L27: =VLOOKUP($C27&$E27,'Updated SES'!A:N,14,0) -> 36.49824 | M27: =VLOOKUP($K27,'Genre Penetration'!A:B,2,0)*VLOOKUP($C27&$E27,'Updated SES'!A:I,9,0) -> 0.3016 | N27: =VLOOKUP(K:K,'Genre Penetration'!A:C,3,0)*VLOOKUP($C27&$E27,'Updated SES'!A:J,10,0) -> 0.2016 | O27: =VLOOKUP($B27,'Language Penetration'!$B$1:$BL$14,MATCH('Compile data Working'!$H25,'Language Penetration'!$B$1:$BL$1,0),0) -> 0.105 | P27: =IF(ISBLANK(J27),RANDBETWEEN(1,2)&"%",IF(J27=1,RANDBETWEEN(35,40)&"%",IF(J27=2,RANDBETWEEN(30,35)&"%",IF(J27=3,RANDBETWEEN(25,30)&"%",IF(J27=4,RANDBETWEEN(20,25)&"%",IF(J27=5,RANDBETWEEN(15,20)&"%",IF(J27=6,RANDBETWEEN(10,15)&"%",IF(J27=7,RANDBETWEEN(8,10)&"%",IF(J27=8,RANDBETWEEN(6,8)&"%",IF(J27=9,RANDBETWEEN(4,6)&"%",IF(J27=10,RANDBETWEEN(2,4)&"%",""))))))))))) -> 1% | Q27: =IFERROR(L27*(M27+N27)*O27*P27,RANDBETWEEN(1,2)%*L27*(M27+N27)*O27) -> 0.01928421 | R27: =VLOOKUP(D:D,ranking!W:X,2,0) -> 0.6 | S27: =R27*Q27 -> 0.011570526 | T27: 16.041073
A28: WK-28'2026 | B28: ALL INDIA | C28: Netflix | D28: Theatrical Movies | E28: PAID | F28: Movies | G28: Desire | H28: English,Hindi | I28: 46220 | K28: Drama,Thriller | L28: =VLOOKUP($C28&$E28,'Updated SES'!A:N,14,0) -> 55.4592 | M28: =VLOOKUP($K28,'Genre Penetration'!A:B,2,0)*VLOOKUP($C28&$E28,'Updated SES'!A:I,9,0) -> 0.2695 | N28: =VLOOKUP(K:K,'Genre Penetration'!A:C,3,0)*VLOOKUP($C28&$E28,'Updated SES'!A:J,10,0) -> 0.2295 | O28: =VLOOKUP($B28,'Language Penetration'!$B$1:$BL$14,MATCH('Compile data Working'!$H48,'Language Penetration'!$B$1:$BL$1,0),0) -> 0.2625 | P28: =IF(ISBLANK(J28),RANDBETWEEN(1,2)&"%",IF(J28=1,RANDBETWEEN(35,40)&"%",IF(J28=2,RANDBETWEEN(30,35)&"%",IF(J28=3,RANDBETWEEN(25,30)&"%",IF(J28=4,RANDBETWEEN(20,25)&"%",IF(J28=5,RANDBETWEEN(15,20)&"%",IF(J28=6,RANDBETWEEN(10,15)&"%",IF(J28=7,RANDBETWEEN(8,10)&"%",IF(J28=8,RANDBETWEEN(6,8)&"%",IF(J28=9,RANDBETWEEN(4,6)&"%",IF(J28=10,RANDBETWEEN(2,4)&"%",""))))))))))) -> 1% | Q28: =IFERROR(L28*(M28+N28)*O28*P28,RANDBETWEEN(1,2)%*L28*(M28+N28)*O28) -> 0.07264462 | R28: =VLOOKUP(D:D,ranking!W:X,2,0) -> 0.7 | S28: =R28*Q28 -> 0.050851234 | T28: 15.872473
A29: Trending Top 10 | B29: ALL INDIA | C29: JioHotstar | D29: Theatrical Movies | E29: PAID | F29: Movies | G29: Dhurandhar: The Revenge | H29: Hindi,Kannada,Malayalam,Tamil,Telugu | I29: 46177 | J29: 7 | K29: Action,Crime,Thriller | L29: =VLOOKUP($C29&$E29,'Updated SES'!A:N,14,0) -> 127.11702 | M29: =VLOOKUP($K29,'Genre Penetration'!A:B,2,0)*VLOOKUP($C29&$E29,'Updated SES'!A:I,9,0) -> 0.4824 | N29: =VLOOKUP(K:K,'Genre Penetration'!A:C,3,0)*VLOOKUP($C29&$E29,'Updated SES'!A:J,10,0) -> 0.0924 | O29: =VLOOKUP($B29,'Language Penetration'!$B$1:$BL$14,MATCH('Compile data Working'!$H89,'Language Penetration'!$B$1:$BL$1,0),0) -> 0.6 | P29: =IF(ISBLANK(J29),RANDBETWEEN(1,2)&"%",IF(J29=1,RANDBETWEEN(35,40)&"%",IF(J29=2,RANDBETWEEN(30,35)&"%",IF(J29=3,RANDBETWEEN(25,30)&"%",IF(J29=4,RANDBETWEEN(20,25)&"%",IF(J29=5,RANDBETWEEN(15,20)&"%",IF(J29=6,RANDBETWEEN(10,15)&"%",IF(J29=7,RANDBETWEEN(8,10)&"%",IF(J29=8,RANDBETWEEN(6,8)&"%",IF(J29=9,RANDBETWEEN(4,6)&"%",IF(J29=10,RANDBETWEEN(2,4)&"%",""))))))))))) -> 9% | Q29: =IFERROR(L29*(M29+N29)*O29*P29,RANDBETWEEN(1,2)%*L29*(M29+N29)*O29) -> 3.9456106 | R29: =VLOOKUP(D:D,ranking!W:X,2,0) -> 0.7 | S29: =R29*Q29 -> 2.7619274 | T29: 15.596927
A30: Trending Top 10 | B30: ALL INDIA | C30: Netflix | D30: Theatrical Movies | E30: PAID | F30: Movies | G30: Daadi Ki Shaadi | H30: Hindi | I30: 46206 | J30: 5 | K30: Comedy,Drama,Romance | L30: =VLOOKUP($C30&$E30,'Updated SES'!A:N,14,0) -> 55.4592 | M30: =VLOOKUP($K30,'Genre Penetration'!A:B,2,0)*VLOOKUP($C30&$E30,'Updated SES'!A:I,9,0) -> 0.1813 | N30: =VLOOKUP(K:K,'Genre Penetration'!A:C,3,0)*VLOOKUP($C30&$E30,'Updated SES'!A:J,10,0) -> 0.3213 | O30: =VLOOKUP($B30,'Language Penetration'!$B$1:$BL$14,MATCH('Compile data Working'!$H93,'Language Penetration'!$B$1:$BL$1,0),0) -> 0.20333333 | P30: =IF(ISBLANK(J30),RANDBETWEEN(1,2)&"%",IF(J30=1,RANDBETWEEN(35,40)&"%",IF(J30=2,RANDBETWEEN(30,35)&"%",IF(J30=3,RANDBETWEEN(25,30)&"%",IF(J30=4,RANDBETWEEN(20,25)&"%",IF(J30=5,RANDBETWEEN(15,20)&"%",IF(J30=6,RANDBETWEEN(10,15)&"%",IF(J30=7,RANDBETWEEN(8,10)&"%",IF(J30=8,RANDBETWEEN(6,8)&"%",IF(J30=9,RANDBETWEEN(4,6)&"%",IF(J30=10,RANDBETWEEN(2,4)&"%",""))))))))))) -> 20% | Q30: =IFERROR(L30*(M30+N30)*O30*P30,RANDBETWEEN(1,2)%*L30*(M30+N30)*O30) -> 1.1335343 | R30: =VLOOKUP(D:D,ranking!W:X,2,0) -> 0.7 | S30: =R30*Q30 -> 0.793474 | T30: 15.397473
A31: WK-28'2026 | B31: ALL INDIA | C31: Netflix | D31: SVOD Originals Shows | E31: PAID | F31: Shows | G31: Quarterback Season 3 | H31: English,Hindi | I31: 46217 | K31: Documentary | L31: =VLOOKUP($C31&$E31,'Updated SES'!A:N,14,0) -> 55.4592 | M31: =VLOOKUP($K31,'Genre Penetration'!A:B,2,0)*VLOOKUP($C31&$E31,'Updated SES'!A:I,9,0) -> 0.2205 | N31: =VLOOKUP(K:K,'Genre Penetration'!A:C,3,0)*VLOOKUP($C31&$E31,'Updated SES'!A:J,10,0) -> 0.2805 | O31: =VLOOKUP($B31,'Language Penetration'!$B$1:$BL$14,MATCH('Compile data Working'!$H20,'Language Penetration'!$B$1:$BL$1,0),0) -> 0.6 | P31: =IF(ISBLANK(J31),RANDBETWEEN(1,2)&"%",IF(J31=1,RANDBETWEEN(35,40)&"%",IF(J31=2,RANDBETWEEN(30,35)&"%",IF(J31=3,RANDBETWEEN(25,30)&"%",IF(J31=4,RANDBETWEEN(20,25)&"%",IF(J31=5,RANDBETWEEN(15,20)&"%",IF(J31=6,RANDBETWEEN(10,15)&"%",IF(J31=7,RANDBETWEEN(8,10)&"%",IF(J31=8,RANDBETWEEN(6,8)&"%",IF(J31=9,RANDBETWEEN(4,6)&"%",IF(J31=10,RANDBETWEEN(2,4)&"%",""))))))))))) -> 1% | Q31: =IFERROR(L31*(M31+N31)*O31*P31,RANDBETWEEN(1,2)%*L31*(M31+N31)*O31) -> 0.16671036 | R31: =VLOOKUP(D:D,ranking!W:X,2,0) -> 0.6 | S31: =R31*Q31 -> 0.10002621 | T31: 15.279654
A32: WK-28'2026 | B32: ALL INDIA | C32: Netflix | D32: SVOD Originals Shows | E32: PAID | F32: Shows | G32: The East Palace | H32: English,Hindi,Tamil,Telugu | I32: 46220 | K32: Action,Fantasy | L32: =VLOOKUP($C32&$E32,'Updated SES'!A:N,14,0) -> 55.4592 | M32: =VLOOKUP($K32,'Genre Penetration'!A:B,2,0)*VLOOKUP($C32&$E32,'Updated SES'!A:I,9,0) -> 0.2891 | N32: =VLOOKUP(K:K,'Genre Penetration'!A:C,3,0)*VLOOKUP($C32&$E32,'Updated SES'!A:J,10,0) -> 0.2091 | O32: =VLOOKUP($B32,'Language Penetration'!$B$1:$BL$14,MATCH('Compile data Working'!$H66,'Language Penetration'!$B$1:$BL$1,0),0) -> 0.2 | P32: =IF(ISBLANK(J32),RANDBETWEEN(1,2)&"%",IF(J32=1,RANDBETWEEN(35,40)&"%",IF(J32=2,RANDBETWEEN(30,35)&"%",IF(J32=3,RANDBETWEEN(25,30)&"%",IF(J32=4,RANDBETWEEN(20,25)&"%",IF(J32=5,RANDBETWEEN(15,20)&"%",IF(J32=6,RANDBETWEEN(10,15)&"%",IF(J32=7,RANDBETWEEN(8,10)&"%",IF(J32=8,RANDBETWEEN(6,8)&"%",IF(J32=9,RANDBETWEEN(4,6)&"%",IF(J32=10,RANDBETWEEN(2,4)&"%",""))))))))))) -> 2% | Q32: =IFERROR(L32*(M32+N32)*O32*P32,RANDBETWEEN(1,2)%*L32*(M32+N32)*O32) -> 0.11051909 | R32: =VLOOKUP(D:D,ranking!W:X,2,0) -> 0.6 | S32: =R32*Q32 -> 0.066311456 | T32: 15.211755
A33: Trending Top 10 | B33: ALL INDIA | C33: Amazon Prime Video | D33: Svod Originals Shows | E33: PAID | F33: Shows | G33: Raakh | H33: Hindi,Tamil,Telugu | I33: 46185 | J33: 4 | K33: Crime,Drama,Thriller | L33: =VLOOKUP($C33&$E33,'Updated SES'!A:N,14,0) -> 36.49824 | M33: =VLOOKUP($K33,'Genre Penetration'!A:B,2,0)*VLOOKUP($C33&$E33,'Updated SES'!A:I,9,0) -> 0.3744 | N33: =VLOOKUP(K:K,'Genre Penetration'!A:C,3,0)*VLOOKUP($C33&$E33,'Updated SES'!A:J,10,0) -> 0.1344 | O33: =VLOOKUP($B33,'Language Penetration'!$B$1:$BL$14,MATCH('Compile data Working'!$H78,'Language Penetration'!$B$1:$BL$1,0),0) -> 0.1 | P33: =IF(ISBLANK(J33),RANDBETWEEN(1,2)&"%",IF(J33=1,RANDBETWEEN(35,40)&"%",IF(J33=2,RANDBETWEEN(30,35)&"%",IF(J33=3,RANDBETWEEN(25,30)&"%",IF(J33=4,RANDBETWEEN(20,25)&"%",IF(J33=5,RANDBETWEEN(15,20)&"%",IF(J33=6,RANDBETWEEN(10,15)&"%",IF(J33=7,RANDBETWEEN(8,10)&"%",IF(J33=8,RANDBETWEEN(6,8)&"%",IF(J33=9,RANDBETWEEN(4,6)&"%",IF(J33=10,RANDBETWEEN(2,4)&"%",""))))))))))) -> 22% | Q33: =IFERROR(L33*(M33+N33)*O33*P33,RANDBETWEEN(1,2)%*L33*(M33+N33)*O33) -> 0.4085467 | R33: =VLOOKUP(D:D,ranking!W:X,2,0) -> 0.6 | S33: =R33*Q33 -> 0.24512802 | T33: 15.170755
A34: WK-28'2026 | B34: ALL INDIA | C34: Netflix | D34: SVOD Originals Shows | E34: PAID | F34: Shows | G34: The Map of Longing | H34: English,Hindi,Telugu | I34: 46220 | K34: Drama,Romance | L34: =VLOOKUP($C34&$E34,'Updated SES'!A:N,14,0) -> 55.4592 | M34: =VLOOKUP($K34,'Genre Penetration'!A:B,2,0)*VLOOKUP($C34&$E34,'Updated SES'!A:I,9,0) -> 0.196 | N34: =VLOOKUP(K:K,'Genre Penetration'!A:C,3,0)*VLOOKUP($C34&$E34,'Updated SES'!A:J,10,0) -> 0.306 | O34: =VLOOKUP($B34,'Language Penetration'!$B$1:$BL$14,MATCH('Compile data Working'!$H61,'Language Penetration'!$B$1:$BL$1,0),0) -> 0.2 | P34: =IF(ISBLANK(J34),RANDBETWEEN(1,2)&"%",IF(J34=1,RANDBETWEEN(35,40)&"%",IF(J34=2,RANDBETWEEN(30,35)&"%",IF(J34=3,RANDBETWEEN(25,30)&"%",IF(J34=4,RANDBETWEEN(20,25)&"%",IF(J34=5,RANDBETWEEN(15,20)&"%",IF(J34=6,RANDBETWEEN(10,15)&"%",IF(J34=7,RANDBETWEEN(8,10)&"%",IF(J34=8,RANDBETWEEN(6,8)&"%",IF(J34=9,RANDBETWEEN(4,6)&"%",IF(J34=10,RANDBETWEEN(2,4)&"%",""))))))))))) -> 2% | Q34: =IFERROR(L34*(M34+N34)*O34*P34,RANDBETWEEN(1,2)%*L34*(M34+N34)*O34) -> 0.11136207 | R34: =VLOOKUP(D:D,ranking!W:X,2,0) -> 0.6 | S34: =R34*Q34 -> 0.066817244 | T34: 14.920133
A35: WK-28'2026 | B35: ALL INDIA | C35: Netflix | D35: SVOD Originals Shows | E35: PAID | F35: Shows | G35: Unexplainable | H35: English | I35: 46219 | K35: Drama | L35: =VLOOKUP($C35&$E35,'Updated SES'!A:N,14,0) -> 55.4592 | M35: =VLOOKUP($K35,'Genre Penetration'!A:B,2,0)*VLOOKUP($C35&$E35,'Updated SES'!A:I,9,0) -> 0.245 | N35: =VLOOKUP(K:K,'Genre Penetration'!A:C,3,0)*VLOOKUP($C35&$E35,'Updated SES'!A:J,10,0) -> 0.255 | O35: =VLOOKUP($B35,'Language Penetration'!$B$1:$BL$14,MATCH('Compile data Working'!$H42,'Language Penetration'!$B$1:$BL$1,0),0) -> 0.204 | P35: =IF(ISBLANK(J35),RANDBETWEEN(1,2)&"%",IF(J35=1,RANDBETWEEN(35,40)&"%",IF(J35=2,RANDBETWEEN(30,35)&"%",IF(J35=3,RANDBETWEEN(25,30)&"%",IF(J35=4,RANDBETWEEN(20,25)&"%",IF(J35=5,RANDBETWEEN(15,20)&"%",IF(J35=6,RANDBETWEEN(10,15)&"%",IF(J35=7,RANDBETWEEN(8,10)&"%",IF(J35=8,RANDBETWEEN(6,8)&"%",IF(J35=9,RANDBETWEEN(4,6)&"%",IF(J35=10,RANDBETWEEN(2,4)&"%",""))))))))))) -> 2% | Q35: =IFERROR(L35*(M35+N35)*O35*P35,RANDBETWEEN(1,2)%*L35*(M35+N35)*O35) -> 0.11313677 | R35: =VLOOKUP(D:D,ranking!W:X,2,0) -> 0.6 | S35: =R35*Q35 -> 0.067882061 | T35: 14.740372
A36: WK-28'2026 | B36: ALL INDIA | C36: Netflix | D36: SVOD Originals Shows | E36: PAID | F36: Shows | G36: The Ultimatum: Marry or Move On Season 4 | H36: English,Hindi | I36: 46218 | K36: Reality Tv | L36: =VLOOKUP($C36&$E36,'Updated SES'!A:N,14,0) -> 55.4592 | M36: =VLOOKUP($K36,'Genre Penetration'!A:B,2,0)*VLOOKUP($C36&$E36,'Updated SES'!A:I,9,0) -> 0.196 | N36: =VLOOKUP(K:K,'Genre Penetration'!A:C,3,0)*VLOOKUP($C36&$E36,'Updated SES'!A:J,10,0) -> 0.306 | O36: =VLOOKUP($B36,'Language Penetration'!$B$1:$BL$14,MATCH('Compile data Working'!$H29,'Language Penetration'!$B$1:$BL$1,0),0) -> 0.204 | P36: =IF(ISBLANK(J36),RANDBETWEEN(1,2)&"%",IF(J36=1,RANDBETWEEN(35,40)&"%",IF(J36=2,RANDBETWEEN(30,35)&"%",IF(J36=3,RANDBETWEEN(25,30)&"%",IF(J36=4,RANDBETWEEN(20,25)&"%",IF(J36=5,RANDBETWEEN(15,20)&"%",IF(J36=6,RANDBETWEEN(10,15)&"%",IF(J36=7,RANDBETWEEN(8,10)&"%",IF(J36=8,RANDBETWEEN(6,8)&"%",IF(J36=9,RANDBETWEEN(4,6)&"%",IF(J36=10,RANDBETWEEN(2,4)&"%",""))))))))))) -> 1% | Q36: =IFERROR(L36*(M36+N36)*O36*P36,RANDBETWEEN(1,2)%*L36*(M36+N36)*O36) -> 0.056794658 | R36: =VLOOKUP(D:D,ranking!W:X,2,0) -> 0.6 | S36: =R36*Q36 -> 0.034076795 | T36: 14.476063
A37: WK-28'2026 | B37: ALL INDIA | C37: Netflix | D37: SVOD Originals Shows | E37: PAID | F37: Shows | G37: The Hawk | H37: English,Hindi,Tamil,Telugu | I37: 46219 | K37: Comedy | L37: =VLOOKUP($C37&$E37,'Updated SES'!A:N,14,0) -> 55.4592 | M37: =VLOOKUP($K37,'Genre Penetration'!A:B,2,0)*VLOOKUP($C37&$E37,'Updated SES'!A:I,9,0) -> 0.2205 | N37: =VLOOKUP(K:K,'Genre Penetration'!A:C,3,0)*VLOOKUP($C37&$E37,'Updated SES'!A:J,10,0) -> 0.2805 | O37: =VLOOKUP($B37,'Language Penetration'!$B$1:$BL$14,MATCH('Compile data Working'!$H41,'Language Penetration'!$B$1:$BL$1,0),0) -> 0.20333333 | P37: =IF(ISBLANK(J37),RANDBETWEEN(1,2)&"%",IF(J37=1,RANDBETWEEN(35,40)&"%",IF(J37=2,RANDBETWEEN(30,35)&"%",IF(J37=3,RANDBETWEEN(25,30)&"%",IF(J37=4,RANDBETWEEN(20,25)&"%",IF(J37=5,RANDBETWEEN(15,20)&"%",IF(J37=6,RANDBETWEEN(10,15)&"%",IF(J37=7,RANDBETWEEN(8,10)&"%",IF(J37=8,RANDBETWEEN(6,8)&"%",IF(J37=9,RANDBETWEEN(4,6)&"%",IF(J37=10,RANDBETWEEN(2,4)&"%",""))))))))))) -> 2% | Q37: =IFERROR(L37*(M37+N37)*O37*P37,RANDBETWEEN(1,2)%*L37*(M37+N37)*O37) -> 0.11299257 | R37: =VLOOKUP(D:D,ranking!W:X,2,0) -> 0.6 | S37: =R37*Q37 -> 0.067795544 | T37: 14.135585
A38: WK-28'2026 | B38: ALL INDIA | C38: Netflix | D38: SVOD Originals Shows | E38: PAID | F38: Shows | G38: Stranger Things: VHS Special Edition | H38: English,Hindi,Tamil,Telugu | I38: 46218 | K38: Drama | L38: =VLOOKUP($C38&$E38,'Updated SES'!A:N,14,0) -> 55.4592 | M38: =VLOOKUP($K38,'Genre Penetration'!A:B,2,0)*VLOOKUP($C38&$E38,'Updated SES'!A:I,9,0) -> 0.245 | N38: =VLOOKUP(K:K,'Genre Penetration'!A:C,3,0)*VLOOKUP($C38&$E38,'Updated SES'!A:J,10,0) -> 0.255 | O38: =VLOOKUP($B38,'Language Penetration'!$B$1:$BL$14,MATCH('Compile data Working'!$H27,'Language Penetration'!$B$1:$BL$1,0),0) -> 0.20333333 | P38: =IF(ISBLANK(J38),RANDBETWEEN(1,2)&"%",IF(J38=1,RANDBETWEEN(35,40)&"%",IF(J38=2,RANDBETWEEN(30,35)&"%",IF(J38=3,RANDBETWEEN(25,30)&"%",IF(J38=4,RANDBETWEEN(20,25)&"%",IF(J38=5,RANDBETWEEN(15,20)&"%",IF(J38=6,RANDBETWEEN(10,15)&"%",IF(J38=7,RANDBETWEEN(8,10)&"%",IF(J38=8,RANDBETWEEN(6,8)&"%",IF(J38=9,RANDBETWEEN(4,6)&"%",IF(J38=10,RANDBETWEEN(2,4)&"%",""))))))))))) -> 2% | Q38: =IFERROR(L38*(M38+N38)*O38*P38,RANDBETWEEN(1,2)%*L38*(M38+N38)*O38) -> 0.11276704 | R38: =VLOOKUP(D:D,ranking!W:X,2,0) -> 0.6 | S38: =R38*Q38 -> 0.067660224 | T38: 13.77367
A39: WK-28'2026 | B39: ALL INDIA | C39: JioHotstar | D39: SVOD Originals Shows | E39: PAID | F39: Shows | G39: Spidey and His Amazing Friends Season 5 | H39: English | I39: 46218 | K39: Adventure,Animation,Comedy | L39: =VLOOKUP($C39&$E39,'Updated SES'!A:N,14,0) -> 127.11702 | M39: =VLOOKUP($K39,'Genre Penetration'!A:B,2,0)*VLOOKUP($C39&$E39,'Updated SES'!A:I,9,0) -> 0.335 | N39: =VLOOKUP(K:K,'Genre Penetration'!A:C,3,0)*VLOOKUP($C39&$E39,'Updated SES'!A:J,10,0) -> 0.165 | O39: =VLOOKUP($B39,'Language Penetration'!$B$1:$BL$14,MATCH('Compile data Working'!$H26,'Language Penetration'!$B$1:$BL$1,0),0) -> 0.204 | P39: =IF(ISBLANK(J39),RANDBETWEEN(1,2)&"%",IF(J39=1,RANDBETWEEN(35,40)&"%",IF(J39=2,RANDBETWEEN(30,35)&"%",IF(J39=3,RANDBETWEEN(25,30)&"%",IF(J39=4,RANDBETWEEN(20,25)&"%",IF(J39=5,RANDBETWEEN(15,20)&"%",IF(J39=6,RANDBETWEEN(10,15)&"%",IF(J39=7,RANDBETWEEN(8,10)&"%",IF(J39=8,RANDBETWEEN(6,8)&"%",IF(J39=9,RANDBETWEEN(4,6)&"%",IF(J39=10,RANDBETWEEN(2,4)&"%",""))))))))))) -> 1% | Q39: =IFERROR(L39*(M39+N39)*O39*P39,RANDBETWEEN(1,2)%*L39*(M39+N39)*O39) -> 0.12965936 | R39: =VLOOKUP(D:D,ranking!W:X,2,0) -> 0.6 | S39: =R39*Q39 -> 0.077795616 | T39: 13.682553
A40: WK-28'2026 | B40: ALL INDIA | C40: Netflix | D40: Theatrical Movies | E40: PAID | F40: Movies | G40: Sniper: No Nation | H40: English,Hindi | I40: 46219 | K40: Action | L40: =VLOOKUP($C40&$E40,'Updated SES'!A:N,14,0) -> 55.4592 | M40: =VLOOKUP($K40,'Genre Penetration'!A:B,2,0)*VLOOKUP($C40&$E40,'Updated SES'!A:I,9,0) -> 0.343 | N40: =VLOOKUP(K:K,'Genre Penetration'!A:C,3,0)*VLOOKUP($C40&$E40,'Updated SES'!A:J,10,0) -> 0.153 | O40: =VLOOKUP($B40,'Language Penetration'!$B$1:$BL$14,MATCH('Compile data Working'!$H145,'Language Penetration'!$B$1:$BL$1,0),0) -> 0.1 | P40: =IF(ISBLANK(J40),RANDBETWEEN(1,2)&"%",IF(J40=1,RANDBETWEEN(35,40)&"%",IF(J40=2,RANDBETWEEN(30,35)&"%",IF(J40=3,RANDBETWEEN(25,30)&"%",IF(J40=4,RANDBETWEEN(20,25)&"%",IF(J40=5,RANDBETWEEN(15,20)&"%",IF(J40=6,RANDBETWEEN(10,15)&"%",IF(J40=7,RANDBETWEEN(8,10)&"%",IF(J40=8,RANDBETWEEN(6,8)&"%",IF(J40=9,RANDBETWEEN(4,6)&"%",IF(J40=10,RANDBETWEEN(2,4)&"%",""))))))))))) -> 2% | Q40: =IFERROR(L40*(M40+N40)*O40*P40,RANDBETWEEN(1,2)%*L40*(M40+N40)*O40) -> 0.055015526 | R40: =VLOOKUP(D:D,ranking!W:X,2,0) -> 0.7 | S40: =R40*Q40 -> 0.038510868 | T40: 13.631233
A41: Trending Top 10 | B41: ALL INDIA | C41: Amazon Prime Video | D41: Theatrical Movies | E41: RENT | F41: Movies | G41: Project Hail Mary | H41: English,Hindi,Kannada,Malayalam,Tamil,Telugu | I41: 46206 | J41: 5 | K41: Adventure,Sci-Fi | L41: =VLOOKUP($C41&$E41,'Updated SES'!A:N,14,0) -> 4.689 | M41: =VLOOKUP($K41,'Genre Penetration'!A:B,2,0)*VLOOKUP($C41&$E41,'Updated SES'!A:I,9,0) -> 0.408 | N41: =VLOOKUP(K:K,'Genre Penetration'!A:C,3,0)*VLOOKUP($C41&$E41,'Updated SES'!A:J,10,0) -> 0.128 | O41: =VLOOKUP($B41,'Language Penetration'!$B$1:$BL$14,MATCH('Compile data Working'!$H79,'Language Penetration'!$B$1:$BL$1,0),0) -> 0.6 | P41: =IF(ISBLANK(J41),RANDBETWEEN(1,2)&"%",IF(J41=1,RANDBETWEEN(35,40)&"%",IF(J41=2,RANDBETWEEN(30,35)&"%",IF(J41=3,RANDBETWEEN(25,30)&"%",IF(J41=4,RANDBETWEEN(20,25)&"%",IF(J41=5,RANDBETWEEN(15,20)&"%",IF(J41=6,RANDBETWEEN(10,15)&"%",IF(J41=7,RANDBETWEEN(8,10)&"%",IF(J41=8,RANDBETWEEN(6,8)&"%",IF(J41=9,RANDBETWEEN(4,6)&"%",IF(J41=10,RANDBETWEEN(2,4)&"%",""))))))))))) -> 18% | Q41: =IFERROR(L41*(M41+N41)*O41*P41,RANDBETWEEN(1,2)%*L41*(M41+N41)*O41) -> 0.27143683 | R41: =VLOOKUP(D:D,ranking!W:X,2,0) -> 0.7 | S41: =R41*Q41 -> 0.19000578 | T41: 13.624902
...

Sheet ranking
A1: =B1&D1 -> OTT PLATFORMTop 10 | B1: OTT PLATFORM | C1: Content format | D1: Top 10 | E1: PAID/FREE | F1: Show/Movies | G1: Genre | H1: Language | I1: Average of Rank | J1: Round | L1: Rank | M1: Watching Percentage | O1: Rank | P1: Watching Percentage | S1: Rank | T1: Watching Percentage | AB1: 1) Original Shows - 80%
A2: =B2&D2 -> Adda TimesAbhishapto | B2: Adda Times | C2: Svod Originals Shows | D2: Abhishapto | E2: PAID | F2: Show | G2: Drama | H2: Bengali | I2: 9 | J2: 9 | L2: 7 | M2: 40-35% | O2: 7 | P2: 40-35% | S2: 1 | T2: 0.9 | W2: Content format | X2: Watching % | AB2: 2) Original Movies - 100%
A3: =B3&D3 -> Adda TimesBasanta Ese Geche | B3: Adda Times | C3: Svod Originals Shows | D3: Basanta Ese Geche | E3: PAID | F3: Show | G3: Drama | H3: Bengali | I3: 2 | J3: 2 | L3: 6 | M3: 35-30% | O3: 6 | P3: 35-30% | S3: 2 | T3: 0.85 | W3: Avod Originals Movies | X3: 0.8 | AB3: 3) Theatrical releases - 75% (conditions pl discuss)
A4: =B4&D4 -> Adda TimesCabaret | B4: Adda Times | C4: Svod Originals Shows | D4: Cabaret | E4: PAID | F4: Show | G4: Drama | H4: Bengali | I4: 4 | J4: 4 | L4: 5 | M4: 30-25% | O4: 5 | P4: 30-25% | S4: 3 | T4: 0.8 | W4: Avod Originals Shows | X4: 0.6 | AB4: 4) Catch up TV Shows - 30% (For bigg boss its also live and have highlights so higher)
A5: =B5&D5 -> Adda TimesGhoshbabur-retirement-plan | B5: Adda Times | C5: Svod Originals Shows | D5: Ghoshbabur-retirement-plan | E5: PAID | F5: Show | G5: Drama | H5: Bengali | I5: 7 | J5: 7 | L5: 4 | M5: 25-20% | O5: 4 | P5: 25-20% | S5: 4 | T5: 0.7 | W5: Live Event | X5: 0.1 | AB5: 5) Live sports - depending upon sports 100% for Cricket, Kabbadi 40%, rest sport 10-15%
A6: =B6&D6 -> Adda TimesKothamrita | B6: Adda Times | C6: Svod Originals Shows | D6: Kothamrita | E6: PAID | F6: Show | G6: Drama,Family | H6: Bengali | I6: 10 | J6: 10 | L6: 3 | M6: 20-15% | O6: 3 | P6: 20-15% | S6: 5 | T6: 0.65 | W6: Svod Originals Movies | X6: 0.8 | AB6: 4) Highlights - 10% of Live sports
A7: =B7&D7 -> Adda TimesNandini | B7: Adda Times | C7: Svod Originals Shows | D7: Nandini | E7: PAID | F7: Show | G7: Drama | H7: Bengali | I7: 8 | J7: 8 | L7: 2 | M7: 15-10% | O7: 2 | P7: 15-10% | S7: 6 | T7: 0.6 | W7: Svod Originals Shows | X7: 0.6
A8: =B8&D8 -> Adda TimesPetni | B8: Adda Times | C8: Svod Originals Shows | D8: Petni | E8: PAID | F8: Show | G8: Drama | H8: Bengali | I8: 5 | J8: 5 | L8: 1 | M8: 10-8% | O8: 1 | P8: 10-8% | S8: 7 | T8: 0.55 | W8: Theatrical releases | X8: 0.7
A9: =B9&D9 -> Adda TimesPreme Pora Baron | B9: Adda Times | C9: Svod Originals Shows | D9: Preme Pora Baron | E9: PAID | F9: Show | G9: Drama | H9: Bengali | I9: 3 | J9: 3 | L9: 8 | M9: 8-6% | S9: 8 | T9: 0.5 | W9: Tv Catch-Up | X9: 0.3
A10: =B10&D10 -> Adda TimesSIN - Whispers Of Guilt | B10: Adda Times | C10: Svod Originals Shows | D10: SIN - Whispers Of Guilt | E10: PAID | F10: Show | G10: Comedy | H10: Bengali | I10: 6 | J10: 6 | L10: 9 | M10: 6-4% | S10: 9 | T10: 0.45 | W10: Theatrical Movies | X10: 0.7
A11: =B11&D11 -> Adda TimesThe First Rain | B11: Adda Times | C11: Svod Originals Shows | D11: The First Rain | E11: PAID | F11: Show | G11: Drama,Romance | H11: Bengali | I11: 1 | J11: 1 | L11: 10 | M11: 4-2% | S11: 10 | T11: 0.4
A12: =B12&D12 -> Aha Video11th Hour | B12: Aha Video | C12: Svod Originals Shows | D12: 11th Hour | E12: PAID | F12: Show | G12: Drama,Thriller | H12: Telugu | I12: 8 | J12: 8 | S12: 11 | T12: =T11*90% -> 0.36
A13: =B13&D13 -> Aha VideoAkash Vaani | B13: Aha Video | C13: Svod Originals Shows | D13: Akash Vaani | E13: PAID | F13: Show | G13: Comedy,Romane | H13: Tamil,Telugu | I13: 5 | J13: 5 | S13: 12 | T13: =T12*90% -> 0.324
A14: =B14&D14 -> Aha VideoAmmuchi 2 | B14: Aha Video | C14: Svod Originals Shows | D14: Ammuchi 2 | E14: PAID | F14: Show | G14: Comedy | H14: Tamil | I14: 6 | J14: 6 | S14: 13 | T14: =T13*90% -> 0.2916
A15: =B15&D15 -> Aha VideoAnya's Tutorial | B15: Aha Video | C15: Svod Originals Shows | D15: Anya's Tutorial | E15: PAID | F15: Show | G15: Drama | H15: Tamil | I15: 10 | J15: 10 | S15: 14 | T15: =T14*90% -> 0.26244
A16: =B16&D16 -> Aha VideoEmoji | B16: Aha Video | C16: Svod Originals Shows | D16: Emoji | E16: PAID | F16: Show | G16: Romance | H16: Tamil | I16: 3 | J16: 3 | S16: 15 | T16: =T15*90% -> 0.236196
A17: =B17&D17 -> Aha VideoEP7 Youtubers | B17: Aha Video | C17: Svod Originals Shows | D17: EP7 Youtubers | E17: PAID | F17: Show | G17: Game Show | H17: Telugu | I17: 4 | J17: 4 | S17: 16 | T17: =T16*90% -> 0.2125764
A18: =B18&D18 -> Aha VideoIrai | B18: Aha Video | C18: Svod Originals Shows | D18: Irai | E18: PAID | F18: Show | G18: Action,Crime,Drama | H18: Tamil | I18: 2 | J18: 2 | S18: 17 | T18: =T17*90% -> 0.19131876
A19: =B19&D19 -> Aha VideoKuthukku Pathu | B19: Aha Video | C19: Svod Originals Shows | D19: Kuthukku Pathu | E19: PAID | F19: Show | G19: Comedy | H19: Tamil | I19: 7 | J19: 7 | S19: 18 | T19: =T18*90% -> 0.17218688
A20: =B20&D20 -> Aha VideoMad Company | B20: Aha Video | C20: Svod Originals Shows | D20: Mad Company | E20: PAID | F20: Show | G20: Comedy,Drama | H20: Tamil | I20: 9 | J20: 9 | S20: 19 | T20: =T19*90% -> 0.1549682
A21: =B21&D21 -> Aha VideoPettaikaali | B21: Aha Video | C21: Svod Originals Shows | D21: Pettaikaali | E21: PAID | F21: Show | G21: Action | H21: Tamil | I21: 1 | J21: 1 | S21: 20 | T21: =T20*90% -> 0.13947138
A22: =B22&D22 -> Aha VideoAyngaran | B22: Aha Video | C22: Theatrical releases | D22: Ayngaran | E22: PAID | F22: Movie | G22: Action,Drama | H22: Tamil | I22: 4 | J22: 4 | S22: 21 | T22: =T21*90% -> 0.12552424
A23: =B23&D23 -> Aha VideoDiary | B23: Aha Video | C23: Theatrical releases | D23: Diary | E23: PAID | F23: Movie | G23: Horror,Thriller | H23: Tamil | I23: 3 | J23: 3 | S23: 22 | T23: =T22*90% -> 0.11297181
... A92: =B92&D92 -> Apple TvBefore | B92: Apple Tv | C92: Svod Originals Shows | D92: Before | E92: PAID | F92: Show | G92: Drama,Thriller | H92: English | I92: 9 | J92: 9 | S92: 100 | T92: =T91*90% -> 7.865082e-05
A93: =B93&D93 -> Apple TvDisclaimer | B93: Apple Tv | C93: Svod Originals Shows | D93: Disclaimer | E93: PAID | F93: Show | G93: Drama,Mystery,Thriller | H93: English | I93: 5 | J93: 5
A94: =B94&D94 -> Apple TvPresumed Innocent | B94: Apple Tv | C94: Svod Originals Shows | D94: Presumed Innocent | E94: PAID | F94: Show | G94: Crime,Drama,Mystery | H94: English | I94: 7 | J94: 7
A95: =B95&D95 -> Apple TvSee | B95: Apple Tv | C95: Svod Originals Shows | D95: See | E95: PAID | F95: Show | G95: Action,Drama,Sci-Fi | H95: English | I95: 8 | J95: 8
A96: =B96&D96 -> Apple TvSeverance | B96: Apple Tv | C96: Svod Originals Shows | D96: Severance | E96: PAID | F96: Show | G96: Drama,Mystery,Thriller | H96: English | I96: 10 | J96: 10
A97: =B97&D97 -> Apple TvShrinking | B97: Apple Tv | C97: Svod Originals Shows | D97: Shrinking | E97: PAID | F97: Show | G97: Comedy,Drama | H97: English | I97: 3 | J97: 3
A98: =B98&D98 -> Apple TvSilo | B98: Apple Tv | C98: Svod Originals Shows | D98: Silo | E98: PAID | F98: Show | G98: Drama,Mystery,Sci-Fi | H98: English | I98: 1 | J98: 1
A99: =B99&D99 -> Apple TvSlow Horses | B99: Apple Tv | C99: Svod Originals Shows | D99: Slow Horses | E99: PAID | F99: Show | G99: Drama,Thriller | H99: English | I99: 6 | J99: 6
A100: =B100&D100 -> Apple TvTed Lasso | B100: Apple Tv | C100: Svod Originals Shows | D100: Ted Lasso | E100: PAID | F100: Show | G100: Comedy,Drama,Sport | H100: English | I100: 4 | J100: 4
A101: =B101&D101 -> Apple TvKillers of the Flower Moon | B101: Apple Tv | C101: Theatrical releases | D101: Killers of the Flower Moon | E101: PAID | F101: Movie | G101: Crime,Drama,Mystery | H101: English | I101: 8 | J101: 8
A102: =B102&D102 -> Apple TvLuck | B102: Apple Tv | C102: Theatrical releases | D102: Luck | E102: PAID | F102: Movie | G102: Animation,Adventure,Comedy | H102: English | I102: 4 | J102: 4
A103: =B103&D103 -> Apple TvWolfs | B103: Apple Tv | C103: Theatrical releases | D103: Wolfs | E103: PAID | F103: Movie | G103: Crime,Thriller | H103: English | I103: 1 | J103: 1
A104: =B104&D104 -> Chaupal TvJatt & Jullit 3 | B104: Chaupal Tv | C104: Svod Originals Movies | D104: Jatt & Jullit 3 | E104: PAID | F104: Movie | G104: Comedy,Romance | H104: Punjabi | I104: 3 | J104: 3
... A393: =B393&D393 -> Zee5Yek Number | B393: Zee5 | C393: Svod Originals Movies | D393: Yek Number | E393: PAID | F393: Movie | G393: Drama | H393: Marathi | I393: 4.6666667 | J393: 5
A394: =B394&D394 -> Zee52012 | B394: Zee5 | C394: Theatrical releases | D394: 2012 | E394: RENT | F394: Movie | G394: Action,Sci-Fi | H394: Hindi,English,Tamil, | I394: 9 | J394: 9
A395: =B395&D395 -> Zee5Bhaiyya Ji | B395: Zee5 | C395: Theatrical releases | D395: Bhaiyya Ji | E395: PAID | F395: Movie | G395: Action,Drama | H395: Hindi | I395: 7.3333333 | J395: 7
A396: =B396&D396 -> Zee5Fifty Shades Freed | B396: Zee5 | C396: Theatrical releases | D396: Fifty Shades Freed | E396: RENT | F396: Movie | G396: Romance,Drama,Thriller | H396: Hindi,English | I396: 6 | J396: 6
...

Sheet Updated SES
A2: OTT PlatformsTYPE | B2: OTT Platforms | C2: Language | D2: Region | E2: TYPE | F2: Show Type | G2: Top 10 | H2: Actual Subscribers | I2: Male % | J2: Female % | K2: CTV | L2: Mobile | M2: CTV+Mobile | N2: Total Viewers | V2: Category | W2: 2-24 | X2: 25-34 | Y2: 35-44 | Z2: 45+
A3: =B3&E3 -> Adda TimesPAID | B3: Adda Times | C3: Bengali | D3: West Bengali | E3: PAID | F3: SVOD | G3: NA | H3: 1.6 | I3: 0.8 | J3: 0.2 | K3: 0.13 | L3: 0.87 | M3: 0.06 | N3: =H3*K3*3+H3*L3*1.1-H3*M3*3 -> 1.8672 | O3: =VLOOKUP(B:B,'[1]Revenue share'!$C$6:$J$16,8,0) -> #N/A | V3: ALL INDIA | W3: 0.3 | X3: 0.33 | Y3: 0.2 | Z3: 0.17
A4: =B4&E4 -> Aha VideoPAID | B4: Aha Video | C4: Telugu & Tamil | D4: Andhra Pradesh,Telangana,Tamilnadu | E4: PAID | F4: SVOD | G4: Yes | H4: 9.23 | I4: 0.76 | J4: 0.24 | K4: 0.22 | L4: 0.78 | M4: 0.05 | N4: =H4*K4*3+H4*L4*1.1-H4*M4*3 -> 12.62664 | O4: =VLOOKUP(B:B,'[1]Revenue share'!$C$6:$J$16,8,0) -> #N/A
A5: =B5&E5 -> Aha VideoFREE | B5: Aha Video | C5: Telugu & Tamil | D5: Andhra Pradesh,Telangana,Tamilnadu | E5: FREE | F5: AVOD | G5: Yes | H5: 3.75 | I5: 0.76 | J5: 0.24 | K5: 0.22 | L5: 0.78 | M5: 0.05 | N5: =H5*K5*3+H5*L5*1.1-H5*M5*3 -> 5.13 | O5: =VLOOKUP(B:B,'[1]Revenue share'!$C$6:$J$16,8,0) -> #N/A
A6: =B6&E6 -> AlttPAID | B6: Altt | C6: Hindi | D6: All India | E6: PAID | F6: SVOD | G6: Yes | H6: 12.16 | I6: 0.65 | J6: 0.35 | K6: 0.26 | L6: 0.74 | M6: 0.07 | N6: =H6*K6*3+H6*L6*1.1-H6*M6*3 -> 16.82944 | O6: =VLOOKUP(B:B,'[1]Revenue share'!$C$6:$J$16,8,0) -> #N/A
A7: =B7&E7 -> Amazon Prime VideoPAID | B7: Amazon Prime Video | C7: Hindi,English,Tamil,Telugu,Malayalam,Kannada,Bengali | D7: All India | E7: PAID | F7: SVOD | G7: Yes | H7: 22.08 | I7: 0.52 | J7: 0.48 | K7: 0.37 | L7: 0.63 | M7: 0.05 | N7: =H7*K7*3+H7*L7*1.1-H7*M7*3 -> 36.49824 | O7: =VLOOKUP(B:B,'[1]Revenue share'!$C$6:$J$16,8,0) -> 78
A8: =B8&E8 -> Amazon Prime VideoFREE | B8: Amazon Prime Video | C8: Hindi,English,Tamil,Telugu,Malayalam,Kannada,Bengali | D8: All India | E8: FREE | F8: SVOD | G8: Yes | H8: 5.09 | I8: 0.52 | J8: 0.48 | K8: 0.37 | L8: 0.63 | M8: 0.05 | N8: =H8*K8*3+H8*L8*1.1-H8*M8*3 -> 8.41377 | O8: =VLOOKUP(B:B,'[1]Revenue share'!$C$6:$J$16,8,0) -> 78 | T8: Demographic Profile | U8: Jio Hotstar | V8: Amazon Prime Video | W8: Netflix | X8: Amazon MX Player | Y8: Zee5 | Z8: Sony Liv | AA8: Alt Balaji | AB8: Sun NXT | AC8: Hoichoi | AD8: Aha Video | AE8: Stage | AF8: Other OTT (Non Regional) | AG8: Other OTT (Regional) | AK8: Location | AL8: Jio Hotstar | AM8: Amazon Prime Video | AN8: Netflix | AO8: Amazon MX Player | AP8: Zee5 | AQ8: Sony Liv | AR8: Alt Balaji | AS8: Sun NXT | AT8: Hoichoi | AU8: Aha Video | AV8: Stage | AW8: Other OTT (Non Regional) | AX8: Other OTT (Regional)
