Workbook

Sheet Top 50 Shows & Movies
F1: WK-22, 2026 ( 01 Jun 2026 - 07 Jun 2026 )
A6: Week | B6: MARKET | C6: Platform | D6: Content format | E6: PAID/FREE | F6: Content Type | G6: Shows/Live Content | H6: Language | I6: Genre | J6: Release Date | K6: Rank | L6: Reach
A7: WK-22,2026 | B7: ALL INDIA | C7: Jio Hotstar | D7: Live Event | E7: PAID | F7: Sports | G7: Indian Premier League 2026 | H7: Hindi | I7: Sports | J7: 46109 | K7: 1 | L7: 156.53995
A8: WK-22,2026 | B8: ALL INDIA | C8: Jio Hotstar | D8: Theatrical releases | E8: PAID | F8: Movies | G8: Dhurandhar: The Revenge | H8: Hindi,Tamil,Telugu,Malayalam,Kannada | I8: Action,Crime,Thriller | J8: 46177 | K8: 2 | L8: 71.667874
A9: WK-22,2026 | B9: ALL INDIA | C9: Amazon Mx Player | D9: AVOD Originals Shows | E9: FREE | F9: Shows | G9: Made in India – A Titan Story | H9: Hindi | I9: Drama | J9: 46176 | K9: 3 | L9: 16.322048
A10: WK-22,2026 | B10: ALL INDIA | C10: Netflix | D10: SVOD Originals Movies | E10: PAID | F10: Movies | G10: Maa Behen | H10: Hindi,English,Tamil,Telugu | I10: Comedy,Crime,Drama | J10: 46177 | K10: 4 | L10: 14.589113
A11: WK-22,2026 | B11: ALL INDIA | C11: Amazon Prime Video | D11: Svod Originals Shows | E11: PAID | F11: Shows | G11: From S4 | H11: English,Hindi | I11: Drama,Horrror | J11: 46131 | K11: 5 | L11: 12.476475
A12: WK-22,2026 | B12: ALL INDIA | C12: Netflix | D12: Svod Originals Shows | E12: PAID | F12: Shows | G12: Berlin and the Lady with an Ermine | H12: Hindi,English,Tamil,Telugu | I12: Crime,Drama,Thriller | J12: 46157 | K12: 6 | L12: 10.281037
A13: WK-22,2026 | B13: ALL INDIA | C13: Sony Liv | D13: Svod Originals Shows | E13: PAID | F13: Shows | G13: Gullak Season 5 | H13: Hindi | I13: Comedy,Drama | J13: 46178 | K13: 7 | L13: 10.206505
A14: WK-22,2026 | B14: ALL INDIA | C14: Amazon Prime Video | D14: Svod Originals Shows | E14: PAID | F14: Shows | G14: Off Campus | H14: English,Hindi,Kannada,Malayalam,Tamil,Telugu | I14: Drama,Romance | J14: 46155 | K14: 8 | L14: 9.8921343
A15: WK-22,2026 | B15: ALL INDIA | C15: Amazon Mx Player | D15: AVOD Originals Shows | E15: FREE | F15: Shows | G15: Vimal Khanna | H15: Hindi | I15: Crime,Thriller | J15: 46157 | K15: 9 | L15: 9.1091012
A16: WK-22,2026 | B16: ALL INDIA | C16: Netflix | D16: Theatrical releases | E16: PAID | F16: Movies | G16: Kara | H16: Hindi,Tamil,Telugu,Malayalam,Kannada | I16: Action,Crime,Thriller | J16: 46170 | K16: 10 | L16: 9.0712981
A17: WK-22,2026 | B17: ALL INDIA | C17: Amazon Prime Video | D17: Svod Originals Shows | E17: PAID | F17: Shows | G17: Spider-Noir | H17: English,Hindi,Kannada,Malayalam,Tamil,Telugu | I17: Action,Adevnture,Drama | J17: 46169 | K17: 11 | L17: 8.2396161
A18: WK-22,2026 | B18: ALL INDIA | C18: Netflix | D18: Svod Originals Shows | E18: PAID | F18: Shows | G18: Night Shift for Cuties | H18: English | I18: Comedy,Drama | J18: 46177 | K18: 12 | L18: 8.0166772
... A56: WK-22,2026 | B56: ALL INDIA | C56: Netflix | D56: Svod Originals Shows | E56: PAID | F56: Shows | G56: Milky?Subway: The Galactic Limited Express – the Movie | H56: Hindi,English | I56: Animation | J56: 46174 | K56: 50 | L56: 4.5352331
C60: Gender
A61: PLATFORM | B61: Total Reach | C61: Male | D61: Female
A62: Jio Hotstar | B62: 399.48213 | C62: =VLOOKUP(A:A,'Updated SES'!B:J,8,0) -> 0.625 | D62: =VLOOKUP(A:A,'Updated SES'!B:J,9,0) -> 0.375
A63: Netflix | B63: 208.40434 | C63: =VLOOKUP(A:A,'Updated SES'!B:J,8,0) -> 0.49 | D63: =VLOOKUP(A:A,'Updated SES'!B:J,9,0) -> 0.51
A64: Amazon Prime Video | B64: 145.10851 | C64: =VLOOKUP(A:A,'Updated SES'!B:J,8,0) -> 0.52 | D64: =VLOOKUP(A:A,'Updated SES'!B:J,9,0) -> 0.48
A65: Zee5 | B65: 55.160877 | C65: =VLOOKUP(A:A,'Updated SES'!B:J,8,0) -> 0.65 | D65: =VLOOKUP(A:A,'Updated SES'!B:J,9,0) -> 0.35
A66: Amazon Mx Player | B66: 52.794339 | C66: =VLOOKUP(A:A,'Updated SES'!B:J,8,0) -> 0.8 | D66: =VLOOKUP(A:A,'Updated SES'!B:J,9,0) -> 0.2

Sheet Compile data Working
G1: WK-22, 2026 ( 01 Jun 2026 - 07 Jun 2026 )
M3: Genre Weightage%
A4: Week | B4: MARKET | C4: Platform | D4: Live Event | E4: PAID/FREE | F4: Show Type | G4: Shows/Live Content | H4: Language | I4: Release Date | J4: Ranking | K4: Genre | L4: Total Viewers In Mn | M4: Male | N4: Female | O4: Language Weightage % | P4: Ranking Penetration | Q4: Reach | R4: Content format % | S4: Final Reach | T4: WK-22 Reach
A5: Cott Data Servey | B5: ALL INDIA | C5: Jio Hotstar | D5: Live Event | E5: PAID | F5: Sports | G5: Indian Premier League 2026 | H5: Hindi | I5: 46109 | K5: Sports | L5: =VLOOKUP($C5&$E5,'Updated SES'!A:N,14,0) -> 127.11702 | M5: =VLOOKUP($K5,'Genre Penetration'!A:B,2,0)*VLOOKUP($C5&$E5,'Updated SES'!A:I,9,0) -> 0.5025 | N5: =VLOOKUP(K:K,'Genre Penetration'!A:C,3,0)*VLOOKUP($C5&$E5,'Updated SES'!A:J,10,0) -> 0.0825 | O5: =VLOOKUP($B5,'Language Penetration'!$B$1:$BE$14,MATCH('Compile data Working'!$H211,'Language Penetration'!$B$1:$BE$1,0),0) -> 0.6 | P5: =IF(ISBLANK(J5),RANDBETWEEN(1,2)&"%",IF(J5=1,RANDBETWEEN(35,40)&"%",IF(J5=2,RANDBETWEEN(30,35)&"%",IF(J5=3,RANDBETWEEN(25,30)&"%",IF(J5=4,RANDBETWEEN(20,25)&"%",IF(J5=5,RANDBETWEEN(15,20)&"%",IF(J5=6,RANDBETWEEN(10,15)&"%",IF(J5=7,RANDBETWEEN(8,10)&"%",IF(J5=8,RANDBETWEEN(6,8)&"%",IF(J5=9,RANDBETWEEN(4,6)&"%",IF(J5=10,RANDBETWEEN(2,4)&"%",""))))))))))) -> 2% | Q5: =IFERROR(L5*(M5+N5)*O5*P5,RANDBETWEEN(1,2)%*L5*(M5+N5)*O5) -> 0.89236148 | R5: =VLOOKUP(D:D,ranking!W:X,2,0) -> 0.1 | S5: =R5*Q5 -> 0.089236148 | T5: 156.53995
A6: WK-22'2026 | B6: ALL INDIA | C6: Jio Hotstar | D6: Theatrical releases | E6: PAID | F6: Movies | G6: Dhurandhar: The Revenge | H6: Hindi,Tamil,Telugu,Malayalam,Kannada | I6: 46177 | J6: 1 | K6: Action,Crime,Thriller | L6: =VLOOKUP($C6&$E6,'Updated SES'!A:N,14,0) -> 127.11702 | M6: =VLOOKUP($K6,'Genre Penetration'!A:B,2,0)*VLOOKUP($C6&$E6,'Updated SES'!A:I,9,0) -> 0.4824 | N6: =VLOOKUP(K:K,'Genre Penetration'!A:C,3,0)*VLOOKUP($C6&$E6,'Updated SES'!A:J,10,0) -> 0.0924 | O6: =VLOOKUP($B6,'Language Penetration'!$B$1:$BE$14,MATCH('Compile data Working'!#REF!,'Language Penetration'!$B$1:$BE$1,0),0) -> #REF! | P6: =IF(ISBLANK(J6),RANDBETWEEN(1,2)&"%",IF(J6=1,RANDBETWEEN(35,40)&"%",IF(J6=2,RANDBETWEEN(30,35)&"%",IF(J6=3,RANDBETWEEN(25,30)&"%",IF(J6=4,RANDBETWEEN(20,25)&"%",IF(J6=5,RANDBETWEEN(15,20)&"%",IF(J6=6,RANDBETWEEN(10,15)&"%",IF(J6=7,RANDBETWEEN(8,10)&"%",IF(J6=8,RANDBETWEEN(6,8)&"%",IF(J6=9,RANDBETWEEN(4,6)&"%",IF(J6=10,RANDBETWEEN(2,4)&"%",""))))))))))) -> 38% | Q6: =IFERROR(L6*(M6+N6)*O6*P6,RANDBETWEEN(1,2)%*L6*(M6+N6)*O6) -> #REF! | R6: =VLOOKUP(D:D,ranking!W:X,2,0) -> 0.7 | S6: =R6*Q6 -> #REF! | T6: 71.667874
A7: WK-22'2026 | B7: ALL INDIA | C7: Amazon Mx Player | D7: AVOD Originals Shows | E7: FREE | F7: Shows | G7: Made in India – A Titan Story | H7: Hindi | I7: 46176 | J7: 1 | K7: Drama | L7: =VLOOKUP($C7&$E7,'Updated SES'!A:N,14,0) -> 78.93987 | M7: =VLOOKUP($K7,'Genre Penetration'!A:B,2,0)*VLOOKUP($C7&$E7,'Updated SES'!A:I,9,0) -> 0.4 | N7: =VLOOKUP(K:K,'Genre Penetration'!A:C,3,0)*VLOOKUP($C7&$E7,'Updated SES'!A:J,10,0) -> 0.1 | O7: =VLOOKUP($B7,'Language Penetration'!$B$1:$BE$14,MATCH('Compile data Working'!#REF!,'Language Penetration'!$B$1:$BE$1,0),0) -> #REF! | P7: =IF(ISBLANK(J7),RANDBETWEEN(1,2)&"%",IF(J7=1,RANDBETWEEN(35,40)&"%",IF(J7=2,RANDBETWEEN(30,35)&"%",IF(J7=3,RANDBETWEEN(25,30)&"%",IF(J7=4,RANDBETWEEN(20,25)&"%",IF(J7=5,RANDBETWEEN(15,20)&"%",IF(J7=6,RANDBETWEEN(10,15)&"%",IF(J7=7,RANDBETWEEN(8,10)&"%",IF(J7=8,RANDBETWEEN(6,8)&"%",IF(J7=9,RANDBETWEEN(4,6)&"%",IF(J7=10,RANDBETWEEN(2,4)&"%",""))))))))))) -> 40% | Q7: =IFERROR(L7*(M7+N7)*O7*P7,RANDBETWEEN(1,2)%*L7*(M7+N7)*O7) -> #REF! | R7: =VLOOKUP(D:D,ranking!W:X,2,0) -> 0.6 | S7: =R7*Q7 -> #REF! | T7: 16.322048
A8: WK-22'2026 | B8: ALL INDIA | C8: Netflix | D8: SVOD Originals Movies | E8: PAID | F8: Movies | G8: Maa Behen | H8: Hindi,English,Tamil,Telugu | I8: 46177 | J8: 1 | K8: Comedy,Crime,Drama | L8: =VLOOKUP($C8&$E8,'Updated SES'!A:N,14,0) -> 55.4592 | M8: =VLOOKUP($K8,'Genre Penetration'!A:B,2,0)*VLOOKUP($C8&$E8,'Updated SES'!A:I,9,0) -> 0.2744 | N8: =VLOOKUP(K:K,'Genre Penetration'!A:C,3,0)*VLOOKUP($C8&$E8,'Updated SES'!A:J,10,0) -> 0.2244 | O8: =VLOOKUP($B8,'Language Penetration'!$B$1:$BE$14,MATCH('Compile data Working'!$H234,'Language Penetration'!$B$1:$BE$1,0),0) -> 0.07 | P8: =IF(ISBLANK(J8),RANDBETWEEN(1,2)&"%",IF(J8=1,RANDBETWEEN(35,40)&"%",IF(J8=2,RANDBETWEEN(30,35)&"%",IF(J8=3,RANDBETWEEN(25,30)&"%",IF(J8=4,RANDBETWEEN(20,25)&"%",IF(J8=5,RANDBETWEEN(15,20)&"%",IF(J8=6,RANDBETWEEN(10,15)&"%",IF(J8=7,RANDBETWEEN(8,10)&"%",IF(J8=8,RANDBETWEEN(6,8)&"%",IF(J8=9,RANDBETWEEN(4,6)&"%",IF(J8=10,RANDBETWEEN(2,4)&"%",""))))))))))) -> 37% | Q8: =IFERROR(L8*(M8+N8)*O8*P8,RANDBETWEEN(1,2)%*L8*(M8+N8)*O8) -> 0.71647297 | R8: =VLOOKUP(D:D,ranking!W:X,2,0) -> 0.8 | S8: =R8*Q8 -> 0.57317837 | T8: 14.589113
A9: Trending Top 10 | B9: ALL INDIA | C9: Amazon Prime Video | D9: Svod Originals Shows | E9: PAID | F9: Shows | G9: From S4 | H9: English,Hindi | I9: 46131 | J9: 3 | K9: Drama,Horrror | L9: =VLOOKUP($C9&$E9,'Updated SES'!A:N,14,0) -> 36.49824 | M9: =VLOOKUP($K9,'Genre Penetration'!A:B,2,0)*VLOOKUP($C9&$E9,'Updated SES'!A:I,9,0) -> #N/A | N9: =VLOOKUP(K:K,'Genre Penetration'!A:C,3,0)*VLOOKUP($C9&$E9,'Updated SES'!A:J,10,0) -> #N/A | O9: =VLOOKUP($B9,'Language Penetration'!$B$1:$BE$14,MATCH('Compile data Working'!$H107,'Language Penetration'!$B$1:$BE$1,0),0) -> 0.2 | P9: =IF(ISBLANK(J9),RANDBETWEEN(1,2)&"%",IF(J9=1,RANDBETWEEN(35,40)&"%",IF(J9=2,RANDBETWEEN(30,35)&"%",IF(J9=3,RANDBETWEEN(25,30)&"%",IF(J9=4,RANDBETWEEN(20,25)&"%",IF(J9=5,RANDBETWEEN(15,20)&"%",IF(J9=6,RANDBETWEEN(10,15)&"%",IF(J9=7,RANDBETWEEN(8,10)&"%",IF(J9=8,RANDBETWEEN(6,8)&"%",IF(J9=9,RANDBETWEEN(4,6)&"%",IF(J9=10,RANDBETWEEN(2,4)&"%",""))))))))))) -> 27% | Q9: =IFERROR(L9*(M9+N9)*O9*P9,RANDBETWEEN(1,2)%*L9*(M9+N9)*O9) -> #N/A | R9: =VLOOKUP(D:D,ranking!W:X,2,0) -> 0.6 | S9: =R9*Q9 -> #N/A | T9: 12.476475
A10: Trending Top 10 | B10: ALL INDIA | C10: Netflix | D10: Svod Originals Shows | E10: PAID | F10: Shows | G10: Berlin and the Lady with an Ermine | H10: Hindi,English,Tamil,Telugu | I10: 46157 | J10: 4 | K10: Crime,Drama,Thriller | L10: =VLOOKUP($C10&$E10,'Updated SES'!A:N,14,0) -> 55.4592 | M10: =VLOOKUP($K10,'Genre Penetration'!A:B,2,0)*VLOOKUP($C10&$E10,'Updated SES'!A:I,9,0) -> 0.3528 | N10: =VLOOKUP(K:K,'Genre Penetration'!A:C,3,0)*VLOOKUP($C10&$E10,'Updated SES'!A:J,10,0) -> 0.1428 | O10: =VLOOKUP($B10,'Language Penetration'!$B$1:$BE$14,MATCH('Compile data Working'!$H13,'Language Penetration'!$B$1:$BE$1,0),0) -> 0.6 | P10: =IF(ISBLANK(J10),RANDBETWEEN(1,2)&"%",IF(J10=1,RANDBETWEEN(35,40)&"%",IF(J10=2,RANDBETWEEN(30,35)&"%",IF(J10=3,RANDBETWEEN(25,30)&"%",IF(J10=4,RANDBETWEEN(20,25)&"%",IF(J10=5,RANDBETWEEN(15,20)&"%",IF(J10=6,RANDBETWEEN(10,15)&"%",IF(J10=7,RANDBETWEEN(8,10)&"%",IF(J10=8,RANDBETWEEN(6,8)&"%",IF(J10=9,RANDBETWEEN(4,6)&"%",IF(J10=10,RANDBETWEEN(2,4)&"%",""))))))))))) -> 20% | Q10: =IFERROR(L10*(M10+N10)*O10*P10,RANDBETWEEN(1,2)%*L10*(M10+N10)*O10) -> 3.2982695 | R10: =VLOOKUP(D:D,ranking!W:X,2,0) -> 0.6 | S10: =R10*Q10 -> 1.9789617 | T10: 10.281037
A11: WK-22'2026 | B11: ALL INDIA | C11: Sony Liv | D11: SVOD Originals Shows | E11: PAID | F11: Shows | G11: Gullak Season 5 | H11: Hindi | I11: 46178 | J11: 5 | K11: Comedy,Drama | L11: =VLOOKUP($C11&$E11,'Updated SES'!A:N,14,0) -> 21.68204 | M11: =VLOOKUP($K11,'Genre Penetration'!A:B,2,0)*VLOOKUP($C11&$E11,'Updated SES'!A:I,9,0) -> 0.3055 | N11: =VLOOKUP(K:K,'Genre Penetration'!A:C,3,0)*VLOOKUP($C11&$E11,'Updated SES'!A:J,10,0) -> 0.1855 | O11: =VLOOKUP($B11,'Language Penetration'!$B$1:$BE$14,MATCH('Compile data Working'!$H70,'Language Penetration'!$B$1:$BE$1,0),0) -> #N/A | P11: =IF(ISBLANK(J11),RANDBETWEEN(1,2)&"%",IF(J11=1,RANDBETWEEN(35,40)&"%",IF(J11=2,RANDBETWEEN(30,35)&"%",IF(J11=3,RANDBETWEEN(25,30)&"%",IF(J11=4,RANDBETWEEN(20,25)&"%",IF(J11=5,RANDBETWEEN(15,20)&"%",IF(J11=6,RANDBETWEEN(10,15)&"%",IF(J11=7,RANDBETWEEN(8,10)&"%",IF(J11=8,RANDBETWEEN(6,8)&"%",IF(J11=9,RANDBETWEEN(4,6)&"%",IF(J11=10,RANDBETWEEN(2,4)&"%",""))))))))))) -> 17% | Q11: =IFERROR(L11*(M11+N11)*O11*P11,RANDBETWEEN(1,2)%*L11*(M11+N11)*O11) -> #N/A | R11: =VLOOKUP(D:D,ranking!W:X,2,0) -> 0.6 | S11: =R11*Q11 -> #N/A | T11: 10.206505
A12: Trending Top 10 | B12: ALL INDIA | C12: Amazon Prime Video | D12: Svod Originals Shows | E12: PAID | F12: Shows | G12: Off Campus | H12: English,Hindi,Kannada,Malayalam,Tamil,Telugu | I12: 46155 | J12: 2 | K12: Drama,Romance | L12: =VLOOKUP($C12&$E12,'Updated SES'!A:N,14,0) -> 36.49824 | M12: =VLOOKUP($K12,'Genre Penetration'!A:B,2,0)*VLOOKUP($C12&$E12,'Updated SES'!A:I,9,0) -> 0.208 | N12: =VLOOKUP(K:K,'Genre Penetration'!A:C,3,0)*VLOOKUP($C12&$E12,'Updated SES'!A:J,10,0) -> 0.288 | O12: =VLOOKUP($B12,'Language Penetration'!$B$1:$BE$14,MATCH('Compile data Working'!$H209,'Language Penetration'!$B$1:$BE$1,0),0) -> 0.2 | P12: =IF(ISBLANK(J12),RANDBETWEEN(1,2)&"%",IF(J12=1,RANDBETWEEN(35,40)&"%",IF(J12=2,RANDBETWEEN(30,35)&"%",IF(J12=3,RANDBETWEEN(25,30)&"%",IF(J12=4,RANDBETWEEN(20,25)&"%",IF(J12=5,RANDBETWEEN(15,20)&"%",IF(J12=6,RANDBETWEEN(10,15)&"%",IF(J12=7,RANDBETWEEN(8,10)&"%",IF(J12=8,RANDBETWEEN(6,8)&"%",IF(J12=9,RANDBETWEEN(4,6)&"%",IF(J12=10,RANDBETWEEN(2,4)&"%",""))))))))))) -> 30% | Q12: =IFERROR(L12*(M12+N12)*O12*P12,RANDBETWEEN(1,2)%*L12*(M12+N12)*O12) -> 1.0861876 | R12: =VLOOKUP(D:D,ranking!W:X,2,0) -> 0.6 | S12: =R12*Q12 -> 0.65171257 | T12: 9.8921343
A13: Trending Top 10 | B13: ALL INDIA | C13: Amazon MX Player | D13: Avod Originals Shows | E13: FREE | F13: Shows | G13: Vimal Khanna | H13: Hindi | I13: 46157 | J13: 2 | K13: Crime,Thriller | L13: =VLOOKUP($C13&$E13,'Updated SES'!A:N,14,0) -> 78.93987 | M13: =VLOOKUP($K13,'Genre Penetration'!A:B,2,0)*VLOOKUP($C13&$E13,'Updated SES'!A:I,9,0) -> 0.496 | N13: =VLOOKUP(K:K,'Genre Penetration'!A:C,3,0)*VLOOKUP($C13&$E13,'Updated SES'!A:J,10,0) -> 0.076 | O13: =VLOOKUP($B13,'Language Penetration'!$B$1:$BE$14,MATCH('Compile data Working'!$H130,'Language Penetration'!$B$1:$BE$1,0),0) -> 0.1 | P13: =IF(ISBLANK(J13),RANDBETWEEN(1,2)&"%",IF(J13=1,RANDBETWEEN(35,40)&"%",IF(J13=2,RANDBETWEEN(30,35)&"%",IF(J13=3,RANDBETWEEN(25,30)&"%",IF(J13=4,RANDBETWEEN(20,25)&"%",IF(J13=5,RANDBETWEEN(15,20)&"%",IF(J13=6,RANDBETWEEN(10,15)&"%",IF(J13=7,RANDBETWEEN(8,10)&"%",IF(J13=8,RANDBETWEEN(6,8)&"%",IF(J13=9,RANDBETWEEN(4,6)&"%",IF(J13=10,RANDBETWEEN(2,4)&"%",""))))))))))) -> 35% | Q13: =IFERROR(L13*(M13+N13)*O13*P13,RANDBETWEEN(1,2)%*L13*(M13+N13)*O13) -> 1.5803762 | R13: =VLOOKUP(D:D,ranking!W:X,2,0) -> 0.6 | S13: =R13*Q13 -> 0.94822572 | T13: 9.1091012
A14: Trending Top 10 | B14: ALL INDIA | C14: Netflix | D14: Theatrical releases | E14: PAID | F14: Movies | G14: Kara | H14: Hindi,Tamil,Telugu,Malayalam,Kannada | I14: 46170 | J14: 3 | K14: Action,Crime,Thriller | L14: =VLOOKUP($C14&$E14,'Updated SES'!A:N,14,0) -> 55.4592 | M14: =VLOOKUP($K14,'Genre Penetration'!A:B,2,0)*VLOOKUP($C14&$E14,'Updated SES'!A:I,9,0) -> 0.3528 | N14: =VLOOKUP(K:K,'Genre Penetration'!A:C,3,0)*VLOOKUP($C14&$E14,'Updated SES'!A:J,10,0) -> 0.1428 | O14: =VLOOKUP($B14,'Language Penetration'!$B$1:$BE$14,MATCH('Compile data Working'!$H32,'Language Penetration'!$B$1:$BE$1,0),0) -> #N/A | P14: =IF(ISBLANK(J14),RANDBETWEEN(1,2)&"%",IF(J14=1,RANDBETWEEN(35,40)&"%",IF(J14=2,RANDBETWEEN(30,35)&"%",IF(J14=3,RANDBETWEEN(25,30)&"%",IF(J14=4,RANDBETWEEN(20,25)&"%",IF(J14=5,RANDBETWEEN(15,20)&"%",IF(J14=6,RANDBETWEEN(10,15)&"%",IF(J14=7,RANDBETWEEN(8,10)&"%",IF(J14=8,RANDBETWEEN(6,8)&"%",IF(J14=9,RANDBETWEEN(4,6)&"%",IF(J14=10,RANDBETWEEN(2,4)&"%",""))))))))))) -> 25% | Q14: =IFERROR(L14*(M14+N14)*O14*P14,RANDBETWEEN(1,2)%*L14*(M14+N14)*O14) -> #N/A | R14: =VLOOKUP(D:D,ranking!W:X,2,0) -> 0.7 | S14: =R14*Q14 -> #N/A | T14: 9.0712981
A15: Trending Top 10 | B15: ALL INDIA | C15: Amazon Prime Video | D15: Svod Originals Shows | E15: PAID | F15: Shows | G15: Spider-Noir | H15: English,Hindi,Kannada,Malayalam,Tamil,Telugu | I15: 46169 | J15: 4 | K15: Action,Adevnture,Drama | L15: =VLOOKUP($C15&$E15,'Updated SES'!A:N,14,0) -> 36.49824 | M15: =VLOOKUP($K15,'Genre Penetration'!A:B,2,0)*VLOOKUP($C15&$E15,'Updated SES'!A:I,9,0) -> #N/A | N15: =VLOOKUP(K:K,'Genre Penetration'!A:C,3,0)*VLOOKUP($C15&$E15,'Updated SES'!A:J,10,0) -> #N/A | O15: =VLOOKUP($B15,'Language Penetration'!$B$1:$BE$14,MATCH('Compile data Working'!$H239,'Language Penetration'!$B$1:$BE$1,0),0) -> #N/A | P15: =IF(ISBLANK(J15),RANDBETWEEN(1,2)&"%",IF(J15=1,RANDBETWEEN(35,40)&"%",IF(J15=2,RANDBETWEEN(30,35)&"%",IF(J15=3,RANDBETWEEN(25,30)&"%",IF(J15=4,RANDBETWEEN(20,25)&"%",IF(J15=5,RANDBETWEEN(15,20)&"%",IF(J15=6,RANDBETWEEN(10,15)&"%",IF(J15=7,RANDBETWEEN(8,10)&"%",IF(J15=8,RANDBETWEEN(6,8)&"%",IF(J15=9,RANDBETWEEN(4,6)&"%",IF(J15=10,RANDBETWEEN(2,4)&"%",""))))))))))) -> 21% | Q15: =IFERROR(L15*(M15+N15)*O15*P15,RANDBETWEEN(1,2)%*L15*(M15+N15)*O15) -> #N/A | R15: =VLOOKUP(D:D,ranking!W:X,2,0) -> 0.6 | S15: =R15*Q15 -> #N/A | T15: 8.2396161
A16: WK-22'2026 | B16: ALL INDIA | C16: Netflix | D16: SVOD Originals Shows | E16: PAID | F16: Shows | G16: Night Shift for Cuties | H16: English | I16: 46177 | K16: Comedy,Drama | L16: =VLOOKUP($C16&$E16,'Updated SES'!A:N,14,0) -> 55.4592 | M16: =VLOOKUP($K16,'Genre Penetration'!A:B,2,0)*VLOOKUP($C16&$E16,'Updated SES'!A:I,9,0) -> 0.2303 | N16: =VLOOKUP(K:K,'Genre Penetration'!A:C,3,0)*VLOOKUP($C16&$E16,'Updated SES'!A:J,10,0) -> 0.2703 | O16: =VLOOKUP($B16,'Language Penetration'!$B$1:$BE$14,MATCH('Compile data Working'!$H61,'Language Penetration'!$B$1:$BE$1,0),0) -> 0.2 | P16: =IF(ISBLANK(J16),RANDBETWEEN(1,2)&"%",IF(J16=1,RANDBETWEEN(35,40)&"%",IF(J16=2,RANDBETWEEN(30,35)&"%",IF(J16=3,RANDBETWEEN(25,30)&"%",IF(J16=4,RANDBETWEEN(20,25)&"%",IF(J16=5,RANDBETWEEN(15,20)&"%",IF(J16=6,RANDBETWEEN(10,15)&"%",IF(J16=7,RANDBETWEEN(8,10)&"%",IF(J16=8,RANDBETWEEN(6,8)&"%",IF(J16=9,RANDBETWEEN(4,6)&"%",IF(J16=10,RANDBETWEEN(2,4)&"%",""))))))))))) -> 1% | Q16: =IFERROR(L16*(M16+N16)*O16*P16,RANDBETWEEN(1,2)%*L16*(M16+N16)*O16) -> 0.055525751 | R16: =VLOOKUP(D:D,ranking!W:X,2,0) -> 0.6 | S16: =R16*Q16 -> 0.033315451 | T16: 8.0166772 | U16: 8.0166772
A17: WK-22'2026 | B17: ALL INDIA | C17: Netflix | D17: Theatrical releases | E17: PAID | F17: Movies | G17: Godzilla x Kong: The New Empire | H17: Hindi,English,Tamil,Telugu | I17: 46177 | J17: 6 | K17: Action,Adventure | L17: =VLOOKUP($C17&$E17,'Updated SES'!A:N,14,0) -> 55.4592 | M17: =VLOOKUP($K17,'Genre Penetration'!A:B,2,0)*VLOOKUP($C17&$E17,'Updated SES'!A:I,9,0) -> 0.2695 | N17: =VLOOKUP(K:K,'Genre Penetration'!A:C,3,0)*VLOOKUP($C17&$E17,'Updated SES'!A:J,10,0) -> 0.2295 | O17: =VLOOKUP($B17,'Language Penetration'!$B$1:$BE$14,MATCH('Compile data Working'!$H238,'Language Penetration'!$B$1:$BE$1,0),0) -> 0.6 | P17: =IF(ISBLANK(J17),RANDBETWEEN(1,2)&"%",IF(J17=1,RANDBETWEEN(35,40)&"%",IF(J17=2,RANDBETWEEN(30,35)&"%",IF(J17=3,RANDBETWEEN(25,30)&"%",IF(J17=4,RANDBETWEEN(20,25)&"%",IF(J17=5,RANDBETWEEN(15,20)&"%",IF(J17=6,RANDBETWEEN(10,15)&"%",IF(J17=7,RANDBETWEEN(8,10)&"%",IF(J17=8,RANDBETWEEN(6,8)&"%",IF(J17=9,RANDBETWEEN(4,6)&"%",IF(J17=10,RANDBETWEEN(2,4)&"%",""))))))))))) -> 11% | Q17: =IFERROR(L17*(M17+N17)*O17*P17,RANDBETWEEN(1,2)%*L17*(M17+N17)*O17) -> 1.8264933 | R17: =VLOOKUP(D:D,ranking!W:X,2,0) -> 0.7 | S17: =R17*Q17 -> 1.2785453 | T17: 7.8451881 | U17: 7.8451881
A18: WK-22'2026 | B18: ALL INDIA | C18: Netflix | D18: Theatrical releases | E18: PAID | F18: Movies | G18: Valentine’s Day | H18: English | I18: 46177 | K18: Comedy,Romance | L18: =VLOOKUP($C18&$E18,'Updated SES'!A:N,14,0) -> 55.4592 | M18: =VLOOKUP($K18,'Genre Penetration'!A:B,2,0)*VLOOKUP($C18&$E18,'Updated SES'!A:I,9,0) -> 0.147 | N18: =VLOOKUP(K:K,'Genre Penetration'!A:C,3,0)*VLOOKUP($C18&$E18,'Updated SES'!A:J,10,0) -> 0.357 | O18: =VLOOKUP($B18,'Language Penetration'!$B$1:$BE$14,MATCH('Compile data Working'!#REF!,'Language Penetration'!$B$1:$BE$1,0),0) -> #REF! | P18: =IF(ISBLANK(J18),RANDBETWEEN(1,2)&"%",IF(J18=1,RANDBETWEEN(35,40)&"%",IF(J18=2,RANDBETWEEN(30,35)&"%",IF(J18=3,RANDBETWEEN(25,30)&"%",IF(J18=4,RANDBETWEEN(20,25)&"%",IF(J18=5,RANDBETWEEN(15,20)&"%",IF(J18=6,RANDBETWEEN(10,15)&"%",IF(J18=7,RANDBETWEEN(8,10)&"%",IF(J18=8,RANDBETWEEN(6,8)&"%",IF(J18=9,RANDBETWEEN(4,6)&"%",IF(J18=10,RANDBETWEEN(2,4)&"%",""))))))))))) -> 1% | Q18: =IFERROR(L18*(M18+N18)*O18*P18,RANDBETWEEN(1,2)%*L18*(M18+N18)*O18) -> #REF! | R18: =VLOOKUP(D:D,ranking!W:X,2,0) -> 0.7 | S18: =R18*Q18 -> #REF! | T18: 7.8100538 | U18: 7.8100538
A19: WK-22'2026 | B19: ALL INDIA | C19: Netflix | D19: SVOD Originals Shows | E19: PAID | F19: Shows | G19: The Witness | H19: Hindi,English | I19: 46177 | J19: 5 | K19: Crime,Drama | L19: =VLOOKUP($C19&$E19,'Updated SES'!A:N,14,0) -> 55.4592 | M19: =VLOOKUP($K19,'Genre Penetration'!A:B,2,0)*VLOOKUP($C19&$E19,'Updated SES'!A:I,9,0) -> 0.2842 | N19: =VLOOKUP(K:K,'Genre Penetration'!A:C,3,0)*VLOOKUP($C19&$E19,'Updated SES'!A:J,10,0) -> 0.2142 | O19: =VLOOKUP($B19,'Language Penetration'!$B$1:$BE$14,MATCH('Compile data Working'!#REF!,'Language Penetration'!$B$1:$BE$1,0),0) -> #REF! | P19: =IF(ISBLANK(J19),RANDBETWEEN(1,2)&"%",IF(J19=1,RANDBETWEEN(35,40)&"%",IF(J19=2,RANDBETWEEN(30,35)&"%",IF(J19=3,RANDBETWEEN(25,30)&"%",IF(J19=4,RANDBETWEEN(20,25)&"%",IF(J19=5,RANDBETWEEN(15,20)&"%",IF(J19=6,RANDBETWEEN(10,15)&"%",IF(J19=7,RANDBETWEEN(8,10)&"%",IF(J19=8,RANDBETWEEN(6,8)&"%",IF(J19=9,RANDBETWEEN(4,6)&"%",IF(J19=10,RANDBETWEEN(2,4)&"%",""))))))))))) -> 15% | Q19: =IFERROR(L19*(M19+N19)*O19*P19,RANDBETWEEN(1,2)%*L19*(M19+N19)*O19) -> #REF! | R19: =VLOOKUP(D:D,ranking!W:X,2,0) -> 0.6 | S19: =R19*Q19 -> #REF! | T19: 7.5097594 | U19: 7.5097594
A20: WK-22'2026 | B20: ALL INDIA | C20: Netflix | D20: Theatrical releases | E20: PAID | F20: Movies | G20: Furiosa: A Mad Max Saga | H20: Hindi,English,Tamil,Telugu | I20: 46177 | J20: 8 | K20: Action,Adventure | L20: =VLOOKUP($C20&$E20,'Updated SES'!A:N,14,0) -> 55.4592 | M20: =VLOOKUP($K20,'Genre Penetration'!A:B,2,0)*VLOOKUP($C20&$E20,'Updated SES'!A:I,9,0) -> 0.2695 | N20: =VLOOKUP(K:K,'Genre Penetration'!A:C,3,0)*VLOOKUP($C20&$E20,'Updated SES'!A:J,10,0) -> 0.2295 | O20: =VLOOKUP($B20,'Language Penetration'!$B$1:$BE$14,MATCH('Compile data Working'!$H89,'Language Penetration'!$B$1:$BE$1,0),0) -> 0.2 | P20: =IF(ISBLANK(J20),RANDBETWEEN(1,2)&"%",IF(J20=1,RANDBETWEEN(35,40)&"%",IF(J20=2,RANDBETWEEN(30,35)&"%",IF(J20=3,RANDBETWEEN(25,30)&"%",IF(J20=4,RANDBETWEEN(20,25)&"%",IF(J20=5,RANDBETWEEN(15,20)&"%",IF(J20=6,RANDBETWEEN(10,15)&"%",IF(J20=7,RANDBETWEEN(8,10)&"%",IF(J20=8,RANDBETWEEN(6,8)&"%",IF(J20=9,RANDBETWEEN(4,6)&"%",IF(J20=10,RANDBETWEEN(2,4)&"%",""))))))))))) -> 7% | Q20: =IFERROR(L20*(M20+N20)*O20*P20,RANDBETWEEN(1,2)%*L20*(M20+N20)*O20) -> 0.38743797 | R20: =VLOOKUP(D:D,ranking!W:X,2,0) -> 0.7 | S20: =R20*Q20 -> 0.27120658 | T20: 7.3313933 | U20: 7.3313933
A21: Trending Top 10 | B21: ALL INDIA | C21: Zee5 | D21: Svod Originals Shows | E21: PAID | F21: Shows | G21: Satrangi: Badle ka Khel | H21: Hindi | I21: 46164 | J21: 3 | K21: Action,Crime | L21: =VLOOKUP($C21&$E21,'Updated SES'!A:N,14,0) -> 60.152 | M21: =VLOOKUP($K21,'Genre Penetration'!A:B,2,0)*VLOOKUP($C21&$E21,'Updated SES'!A:I,9,0) -> 0.416 | N21: =VLOOKUP(K:K,'Genre Penetration'!A:C,3,0)*VLOOKUP($C21&$E21,'Updated SES'!A:J,10,0) -> 0.126 | O21: =VLOOKUP($B21,'Language Penetration'!$B$1:$BE$14,MATCH('Compile data Working'!#REF!,'Language Penetration'!$B$1:$BE$1,0),0) -> #REF! | P21: =IF(ISBLANK(J21),RANDBETWEEN(1,2)&"%",IF(J21=1,RANDBETWEEN(35,40)&"%",IF(J21=2,RANDBETWEEN(30,35)&"%",IF(J21=3,RANDBETWEEN(25,30)&"%",IF(J21=4,RANDBETWEEN(20,25)&"%",IF(J21=5,RANDBETWEEN(15,20)&"%",IF(J21=6,RANDBETWEEN(10,15)&"%",IF(J21=7,RANDBETWEEN(8,10)&"%",IF(J21=8,RANDBETWEEN(6,8)&"%",IF(J21=9,RANDBETWEEN(4,6)&"%",IF(J21=10,RANDBETWEEN(2,4)&"%",""))))))))))) -> 29% | Q21: =IFERROR(L21*(M21+N21)*O21*P21,RANDBETWEEN(1,2)%*L21*(M21+N21)*O21) -> #REF! | R21: =VLOOKUP(D:D,ranking!W:X,2,0) -> 0.6 | S21: =R21*Q21 -> #REF! | T21: 6.902955
A22: Trending Top 10 | B22: ALL INDIA | C22: Netflix | D22: Svod Originals Shows | E22: PAID | F22: Shows | G22: A Good Girl’s Guide to Murder S2 | H22: Hindi,English | I22: 46169 | J22: 8 | K22: Crime,Drama,Thriller | L22: =VLOOKUP($C22&$E22,'Updated SES'!A:N,14,0) -> 55.4592 | M22: =VLOOKUP($K22,'Genre Penetration'!A:B,2,0)*VLOOKUP($C22&$E22,'Updated SES'!A:I,9,0) -> 0.3528 | N22: =VLOOKUP(K:K,'Genre Penetration'!A:C,3,0)*VLOOKUP($C22&$E22,'Updated SES'!A:J,10,0) -> 0.1428 | O22: =VLOOKUP($B22,'Language Penetration'!$B$1:$BE$14,MATCH('Compile data Working'!$H48,'Language Penetration'!$B$1:$BE$1,0),0) -> 0.2 | P22: =IF(ISBLANK(J22),RANDBETWEEN(1,2)&"%",IF(J22=1,RANDBETWEEN(35,40)&"%",IF(J22=2,RANDBETWEEN(30,35)&"%",IF(J22=3,RANDBETWEEN(25,30)&"%",IF(J22=4,RANDBETWEEN(20,25)&"%",IF(J22=5,RANDBETWEEN(15,20)&"%",IF(J22=6,RANDBETWEEN(10,15)&"%",IF(J22=7,RANDBETWEEN(8,10)&"%",IF(J22=8,RANDBETWEEN(6,8)&"%",IF(J22=9,RANDBETWEEN(4,6)&"%",IF(J22=10,RANDBETWEEN(2,4)&"%",""))))))))))) -> 7% | Q22: =IFERROR(L22*(M22+N22)*O22*P22,RANDBETWEEN(1,2)%*L22*(M22+N22)*O22) -> 0.38479811 | R22: =VLOOKUP(D:D,ranking!W:X,2,0) -> 0.6 | S22: =R22*Q22 -> 0.23087887 | T22: 6.8231422
A23: WK-22'2026 | B23: ALL INDIA | C23: Amazon Prime Video | D23: SVOD Originals Shows | E23: PAID | F23: Shows | G23: The Pyramid Scheme | H23: Hindi | I23: 46178 | J23: 1 | K23: Comedy,Drama | L23: =VLOOKUP($C23&$E23,'Updated SES'!A:N,14,0) -> 36.49824 | M23: =VLOOKUP($K23,'Genre Penetration'!A:B,2,0)*VLOOKUP($C23&$E23,'Updated SES'!A:I,9,0) -> 0.2444 | N23: =VLOOKUP(K:K,'Genre Penetration'!A:C,3,0)*VLOOKUP($C23&$E23,'Updated SES'!A:J,10,0) -> 0.2544 | O23: =VLOOKUP($B23,'Language Penetration'!$B$1:$BE$14,MATCH('Compile data Working'!$H35,'Language Penetration'!$B$1:$BE$1,0),0) -> 0.2 | P23: =IF(ISBLANK(J23),RANDBETWEEN(1,2)&"%",IF(J23=1,RANDBETWEEN(35,40)&"%",IF(J23=2,RANDBETWEEN(30,35)&"%",IF(J23=3,RANDBETWEEN(25,30)&"%",IF(J23=4,RANDBETWEEN(20,25)&"%",IF(J23=5,RANDBETWEEN(15,20)&"%",IF(J23=6,RANDBETWEEN(10,15)&"%",IF(J23=7,RANDBETWEEN(8,10)&"%",IF(J23=8,RANDBETWEEN(6,8)&"%",IF(J23=9,RANDBETWEEN(4,6)&"%",IF(J23=10,RANDBETWEEN(2,4)&"%",""))))))))))) -> 39% | Q23: =IFERROR(L23*(M23+N23)*O23*P23,RANDBETWEEN(1,2)%*L23*(M23+N23)*O23) -> 1.4200151 | R23: =VLOOKUP(D:D,ranking!W:X,2,0) -> 0.6 | S23: =R23*Q23 -> 0.85200907 | T23: 6.60295 | U23: 6.60295
A24: WK-22'2026 | B24: ALL INDIA | C24: Amazon Prime Video | D24: Theatrical releases | E24: PAID | F24: Movies | G24: Ugly Story | H24: Hindi,Tamil,Telugu | I24: 46178 | J24: 3 | K24: Drama,Thriller | L24: =VLOOKUP($C24&$E24,'Updated SES'!A:N,14,0) -> 36.49824 | M24: =VLOOKUP($K24,'Genre Penetration'!A:B,2,0)*VLOOKUP($C24&$E24,'Updated SES'!A:I,9,0) -> 0.286 | N24: =VLOOKUP(K:K,'Genre Penetration'!A:C,3,0)*VLOOKUP($C24&$E24,'Updated SES'!A:J,10,0) -> 0.216 | O24: =VLOOKUP($B24,'Language Penetration'!$B$1:$BE$14,MATCH('Compile data Working'!$H45,'Language Penetration'!$B$1:$BE$1,0),0) -> #N/A | P24: =IF(ISBLANK(J24),RANDBETWEEN(1,2)&"%",IF(J24=1,RANDBETWEEN(35,40)&"%",IF(J24=2,RANDBETWEEN(30,35)&"%",IF(J24=3,RANDBETWEEN(25,30)&"%",IF(J24=4,RANDBETWEEN(20,25)&"%",IF(J24=5,RANDBETWEEN(15,20)&"%",IF(J24=6,RANDBETWEEN(10,15)&"%",IF(J24=7,RANDBETWEEN(8,10)&"%",IF(J24=8,RANDBETWEEN(6,8)&"%",IF(J24=9,RANDBETWEEN(4,6)&"%",IF(J24=10,RANDBETWEEN(2,4)&"%",""))))))))))) -> 27% | Q24: =IFERROR(L24*(M24+N24)*O24*P24,RANDBETWEEN(1,2)%*L24*(M24+N24)*O24) -> #N/A | R24: =VLOOKUP(D:D,ranking!W:X,2,0) -> 0.7 | S24: =R24*Q24 -> #N/A | T24: 6.559757 | U24: 6.559757
A25: WK-22'2026 | B25: ALL INDIA | C25: Lionsgate Play | D25: SVOD Originals Shows | E25: PAID | F25: Shows | G25: Schitt’s Creek | H25: English | I25: 46178 | K25: Comedy | L25: =VLOOKUP($C25&$E25,'Updated SES'!A:N,14,0) -> 25.34 | M25: =VLOOKUP($K25,'Genre Penetration'!A:B,2,0)*VLOOKUP($C25&$E25,'Updated SES'!A:I,9,0) -> 0.369 | N25: =VLOOKUP(K:K,'Genre Penetration'!A:C,3,0)*VLOOKUP($C25&$E25,'Updated SES'!A:J,10,0) -> 0.099 | O25: =VLOOKUP($B25,'Language Penetration'!$B$1:$BE$14,MATCH('Compile data Working'!$H190,'Language Penetration'!$B$1:$BE$1,0),0) -> 0.12 | P25: =IF(ISBLANK(J25),RANDBETWEEN(1,2)&"%",IF(J25=1,RANDBETWEEN(35,40)&"%",IF(J25=2,RANDBETWEEN(30,35)&"%",IF(J25=3,RANDBETWEEN(25,30)&"%",IF(J25=4,RANDBETWEEN(20,25)&"%",IF(J25=5,RANDBETWEEN(15,20)&"%",IF(J25=6,RANDBETWEEN(10,15)&"%",IF(J25=7,RANDBETWEEN(8,10)&"%",IF(J25=8,RANDBETWEEN(6,8)&"%",IF(J25=9,RANDBETWEEN(4,6)&"%",IF(J25=10,RANDBETWEEN(2,4)&"%",""))))))))))) -> 1% | Q25: =IFERROR(L25*(M25+N25)*O25*P25,RANDBETWEEN(1,2)%*L25*(M25+N25)*O25) -> 0.014230944 | R25: =VLOOKUP(D:D,ranking!W:X,2,0) -> 0.6 | S25: =R25*Q25 -> 0.0085385664 | T25: 6.4431295 | U25: 6.4431295
A26: Trending Top 10 | B26: ALL INDIA | C26: Netflix | D26: Svod Originals Shows | E26: PAID | F26: Shows | G26: Desi Bling | H26: Hindi,English,Tamil,Telugu | I26: 46162 | J26: 6 | K26: Reality Tv | L26: =VLOOKUP($C26&$E26,'Updated SES'!A:N,14,0) -> 55.4592 | M26: =VLOOKUP($K26,'Genre Penetration'!A:B,2,0)*VLOOKUP($C26&$E26,'Updated SES'!A:I,9,0) -> 0.196 | N26: =VLOOKUP(K:K,'Genre Penetration'!A:C,3,0)*VLOOKUP($C26&$E26,'Updated SES'!A:J,10,0) -> 0.306 | O26: =VLOOKUP($B26,'Language Penetration'!$B$1:$BE$14,MATCH('Compile data Working'!$H229,'Language Penetration'!$B$1:$BE$1,0),0) -> 0.6 | P26: =IF(ISBLANK(J26),RANDBETWEEN(1,2)&"%",IF(J26=1,RANDBETWEEN(35,40)&"%",IF(J26=2,RANDBETWEEN(30,35)&"%",IF(J26=3,RANDBETWEEN(25,30)&"%",IF(J26=4,RANDBETWEEN(20,25)&"%",IF(J26=5,RANDBETWEEN(15,20)&"%",IF(J26=6,RANDBETWEEN(10,15)&"%",IF(J26=7,RANDBETWEEN(8,10)&"%",IF(J26=8,RANDBETWEEN(6,8)&"%",IF(J26=9,RANDBETWEEN(4,6)&"%",IF(J26=10,RANDBETWEEN(2,4)&"%",""))))))))))) -> 15% | Q26: =IFERROR(L26*(M26+N26)*O26*P26,RANDBETWEEN(1,2)%*L26*(M26+N26)*O26) -> 2.5056467 | R26: =VLOOKUP(D:D,ranking!W:X,2,0) -> 0.6 | S26: =R26*Q26 -> 1.503388 | T26: 6.3720916
A27: Cott Data Servey | B27: ALL INDIA | C27: Jio Hotstar | D27: Tv Catch-Up | E27: PAID | F27: Tv CatchUp | G27: Laughter Chefs S3 | H27: Hindi | I27: 45983 | K27: Reality, Comedy | L27: =VLOOKUP($C27&$E27,'Updated SES'!A:N,14,0) -> 127.11702 | M27: =VLOOKUP($K27,'Genre Penetration'!A:B,2,0)*VLOOKUP($C27&$E27,'Updated SES'!A:I,9,0) -> #N/A | N27: =VLOOKUP(K:K,'Genre Penetration'!A:C,3,0)*VLOOKUP($C27&$E27,'Updated SES'!A:J,10,0) -> #N/A | O27: =VLOOKUP($B27,'Language Penetration'!$B$1:$BE$14,MATCH('Compile data Working'!$H95,'Language Penetration'!$B$1:$BE$1,0),0) -> #N/A | P27: =IF(ISBLANK(J27),RANDBETWEEN(1,2)&"%",IF(J27=1,RANDBETWEEN(35,40)&"%",IF(J27=2,RANDBETWEEN(30,35)&"%",IF(J27=3,RANDBETWEEN(25,30)&"%",IF(J27=4,RANDBETWEEN(20,25)&"%",IF(J27=5,RANDBETWEEN(15,20)&"%",IF(J27=6,RANDBETWEEN(10,15)&"%",IF(J27=7,RANDBETWEEN(8,10)&"%",IF(J27=8,RANDBETWEEN(6,8)&"%",IF(J27=9,RANDBETWEEN(4,6)&"%",IF(J27=10,RANDBETWEEN(2,4)&"%",""))))))))))) -> 2% | Q27: =IFERROR(L27*(M27+N27)*O27*P27,RANDBETWEEN(1,2)%*L27*(M27+N27)*O27) -> #N/A | R27: =VLOOKUP(D:D,ranking!W:X,2,0) -> 0.3 | S27: =R27*Q27 -> #N/A | T27: 6.2489218
A28: WK-22'2026 | B28: ALL INDIA | C28: Netflix | D28: SVOD Originals Movies | E28: PAID | F28: Movies | G28: The Murder of Rachel Nickell | H28: Hindi,English,Tamil,Telugu | I28: 46177 | K28: Crime,Documentary | L28: =VLOOKUP($C28&$E28,'Updated SES'!A:N,14,0) -> 55.4592 | M28: =VLOOKUP($K28,'Genre Penetration'!A:B,2,0)*VLOOKUP($C28&$E28,'Updated SES'!A:I,9,0) -> 0.2695 | N28: =VLOOKUP(K:K,'Genre Penetration'!A:C,3,0)*VLOOKUP($C28&$E28,'Updated SES'!A:J,10,0) -> 0.2295 | O28: =VLOOKUP($B28,'Language Penetration'!$B$1:$BE$14,MATCH('Compile data Working'!$H23,'Language Penetration'!$B$1:$BE$1,0),0) -> 0.6 | P28: =IF(ISBLANK(J28),RANDBETWEEN(1,2)&"%",IF(J28=1,RANDBETWEEN(35,40)&"%",IF(J28=2,RANDBETWEEN(30,35)&"%",IF(J28=3,RANDBETWEEN(25,30)&"%",IF(J28=4,RANDBETWEEN(20,25)&"%",IF(J28=5,RANDBETWEEN(15,20)&"%",IF(J28=6,RANDBETWEEN(10,15)&"%",IF(J28=7,RANDBETWEEN(8,10)&"%",IF(J28=8,RANDBETWEEN(6,8)&"%",IF(J28=9,RANDBETWEEN(4,6)&"%",IF(J28=10,RANDBETWEEN(2,4)&"%",""))))))))))) -> 2% | Q28: =IFERROR(L28*(M28+N28)*O28*P28,RANDBETWEEN(1,2)%*L28*(M28+N28)*O28) -> 0.33208969 | R28: =VLOOKUP(D:D,ranking!W:X,2,0) -> 0.8 | S28: =R28*Q28 -> 0.26567175 | T28: 6.1769502 | U28: 6.1769502
A29: WK-22'2026 | B29: ALL INDIA | C29: Netflix | D29: SVOD Originals Movies | E29: PAID | F29: Movies | G29: Poldi | H29: Hindi,English | I29: 46177 | K29: Documentary | L29: =VLOOKUP($C29&$E29,'Updated SES'!A:N,14,0) -> 55.4592 | M29: =VLOOKUP($K29,'Genre Penetration'!A:B,2,0)*VLOOKUP($C29&$E29,'Updated SES'!A:I,9,0) -> 0.2205 | N29: =VLOOKUP(K:K,'Genre Penetration'!A:C,3,0)*VLOOKUP($C29&$E29,'Updated SES'!A:J,10,0) -> 0.2805 | O29: =VLOOKUP($B29,'Language Penetration'!$B$1:$BE$14,MATCH('Compile data Working'!$H27,'Language Penetration'!$B$1:$BE$1,0),0) -> 0.6 | P29: =IF(ISBLANK(J29),RANDBETWEEN(1,2)&"%",IF(J29=1,RANDBETWEEN(35,40)&"%",IF(J29=2,RANDBETWEEN(30,35)&"%",IF(J29=3,RANDBETWEEN(25,30)&"%",IF(J29=4,RANDBETWEEN(20,25)&"%",IF(J29=5,RANDBETWEEN(15,20)&"%",IF(J29=6,RANDBETWEEN(10,15)&"%",IF(J29=7,RANDBETWEEN(8,10)&"%",IF(J29=8,RANDBETWEEN(6,8)&"%",IF(J29=9,RANDBETWEEN(4,6)&"%",IF(J29=10,RANDBETWEEN(2,4)&"%",""))))))))))) -> 2% | Q29: =IFERROR(L29*(M29+N29)*O29*P29,RANDBETWEEN(1,2)%*L29*(M29+N29)*O29) -> 0.33342071 | R29: =VLOOKUP(D:D,ranking!W:X,2,0) -> 0.8 | S29: =R29*Q29 -> 0.26673657 | T29: 6.1649492 | U29: 6.1649492
A30: Trending Top 10 | B30: ALL INDIA | C30: Amazon Prime Video | D30: Svod Originals Shows | E30: PAID | F30: Shows | G30: The Boys S5 | H30: English,Hindi,Kannada,Malayalam,Tamil,Telugu | I30: 46120 | J30: 7 | K30: Action,Comedy,Drama | L30: =VLOOKUP($C30&$E30,'Updated SES'!A:N,14,0) -> 36.49824 | M30: =VLOOKUP($K30,'Genre Penetration'!A:B,2,0)*VLOOKUP($C30&$E30,'Updated SES'!A:I,9,0) -> 0.2496 | N30: =VLOOKUP(K:K,'Genre Penetration'!A:C,3,0)*VLOOKUP($C30&$E30,'Updated SES'!A:J,10,0) -> 0.2496 | O30: =VLOOKUP($B30,'Language Penetration'!$B$1:$BE$14,MATCH('Compile data Working'!$H198,'Language Penetration'!$B$1:$BE$1,0),0) -> 0.6 | P30: =IF(ISBLANK(J30),RANDBETWEEN(1,2)&"%",IF(J30=1,RANDBETWEEN(35,40)&"%",IF(J30=2,RANDBETWEEN(30,35)&"%",IF(J30=3,RANDBETWEEN(25,30)&"%",IF(J30=4,RANDBETWEEN(20,25)&"%",IF(J30=5,RANDBETWEEN(15,20)&"%",IF(J30=6,RANDBETWEEN(10,15)&"%",IF(J30=7,RANDBETWEEN(8,10)&"%",IF(J30=8,RANDBETWEEN(6,8)&"%",IF(J30=9,RANDBETWEEN(4,6)&"%",IF(J30=10,RANDBETWEEN(2,4)&"%",""))))))))))) -> 10% | Q30: =IFERROR(L30*(M30+N30)*O30*P30,RANDBETWEEN(1,2)%*L30*(M30+N30)*O30) -> 1.0931953 | R30: =VLOOKUP(D:D,ranking!W:X,2,0) -> 0.6 | S30: =R30*Q30 -> 0.65591717 | T30: 6.1108385
A31: WK-22'2026 | B31: ALL INDIA | C31: Zee5 | D31: SVOD Originals Shows | E31: PAID | F31: Shows | G31: Brown | H31: Hindi | I31: 46178 | J31: 2 | K31: Crime,Drama,Thriller | L31: =VLOOKUP($C31&$E31,'Updated SES'!A:N,14,0) -> 60.152 | M31: =VLOOKUP($K31,'Genre Penetration'!A:B,2,0)*VLOOKUP($C31&$E31,'Updated SES'!A:I,9,0) -> 0.468 | N31: =VLOOKUP(K:K,'Genre Penetration'!A:C,3,0)*VLOOKUP($C31&$E31,'Updated SES'!A:J,10,0) -> 0.098 | O31: =VLOOKUP($B31,'Language Penetration'!$B$1:$BE$14,MATCH('Compile data Working'!$H218,'Language Penetration'!$B$1:$BE$1,0),0) -> 0.6 | P31: =IF(ISBLANK(J31),RANDBETWEEN(1,2)&"%",IF(J31=1,RANDBETWEEN(35,40)&"%",IF(J31=2,RANDBETWEEN(30,35)&"%",IF(J31=3,RANDBETWEEN(25,30)&"%",IF(J31=4,RANDBETWEEN(20,25)&"%",IF(J31=5,RANDBETWEEN(15,20)&"%",IF(J31=6,RANDBETWEEN(10,15)&"%",IF(J31=7,RANDBETWEEN(8,10)&"%",IF(J31=8,RANDBETWEEN(6,8)&"%",IF(J31=9,RANDBETWEEN(4,6)&"%",IF(J31=10,RANDBETWEEN(2,4)&"%",""))))))))))) -> 34% | Q31: =IFERROR(L31*(M31+N31)*O31*P31,RANDBETWEEN(1,2)%*L31*(M31+N31)*O31) -> 6.9453905 | R31: =VLOOKUP(D:D,ranking!W:X,2,0) -> 0.6 | S31: =R31*Q31 -> 4.1672343 | T31: 5.9959235 | U31: 5.9959235
A32: WK-22'2026 | B32: ALL INDIA | C32: Jio Hotstar | D32: Theatrical releases | E32: PAID | F32: Movies | G32: Immaculate | H32: Hindi,English,Tamil,Telugu | I32: 46177 | K32: Horror,Thriller | L32: =VLOOKUP($C32&$E32,'Updated SES'!A:N,14,0) -> 127.11702 | M32: =VLOOKUP($K32,'Genre Penetration'!A:B,2,0)*VLOOKUP($C32&$E32,'Updated SES'!A:I,9,0) -> 0.469 | N32: =VLOOKUP(K:K,'Genre Penetration'!A:C,3,0)*VLOOKUP($C32&$E32,'Updated SES'!A:J,10,0) -> 0.099 | O32: =VLOOKUP($B32,'Language Penetration'!$B$1:$BE$14,MATCH('Compile data Working'!#REF!,'Language Penetration'!$B$1:$BE$1,0),0) -> #REF! | P32: =IF(ISBLANK(J32),RANDBETWEEN(1,2)&"%",IF(J32=1,RANDBETWEEN(35,40)&"%",IF(J32=2,RANDBETWEEN(30,35)&"%",IF(J32=3,RANDBETWEEN(25,30)&"%",IF(J32=4,RANDBETWEEN(20,25)&"%",IF(J32=5,RANDBETWEEN(15,20)&"%",IF(J32=6,RANDBETWEEN(10,15)&"%",IF(J32=7,RANDBETWEEN(8,10)&"%",IF(J32=8,RANDBETWEEN(6,8)&"%",IF(J32=9,RANDBETWEEN(4,6)&"%",IF(J32=10,RANDBETWEEN(2,4)&"%",""))))))))))) -> 1% | Q32: =IFERROR(L32*(M32+N32)*O32*P32,RANDBETWEEN(1,2)%*L32*(M32+N32)*O32) -> #REF! | R32: =VLOOKUP(D:D,ranking!W:X,2,0) -> 0.7 | S32: =R32*Q32 -> #REF! | T32: 5.9749394 | U32: 5.9749394
A33: WK-22'2026 | B33: ALL INDIA | C33: Netflix | D33: Theatrical releases | E33: PAID | F33: Movies | G33: Until She Remembers | H33: Hindi,English | I33: 46177 | K33: Drama,Romance | L33: =VLOOKUP($C33&$E33,'Updated SES'!A:N,14,0) -> 55.4592 | M33: =VLOOKUP($K33,'Genre Penetration'!A:B,2,0)*VLOOKUP($C33&$E33,'Updated SES'!A:I,9,0) -> 0.196 | N33: =VLOOKUP(K:K,'Genre Penetration'!A:C,3,0)*VLOOKUP($C33&$E33,'Updated SES'!A:J,10,0) -> 0.306 | O33: =VLOOKUP($B33,'Language Penetration'!$B$1:$BE$14,MATCH('Compile data Working'!$H200,'Language Penetration'!$B$1:$BE$1,0),0) -> 0.6 | P33: =IF(ISBLANK(J33),RANDBETWEEN(1,2)&"%",IF(J33=1,RANDBETWEEN(35,40)&"%",IF(J33=2,RANDBETWEEN(30,35)&"%",IF(J33=3,RANDBETWEEN(25,30)&"%",IF(J33=4,RANDBETWEEN(20,25)&"%",IF(J33=5,RANDBETWEEN(15,20)&"%",IF(J33=6,RANDBETWEEN(10,15)&"%",IF(J33=7,RANDBETWEEN(8,10)&"%",IF(J33=8,RANDBETWEEN(6,8)&"%",IF(J33=9,RANDBETWEEN(4,6)&"%",IF(J33=10,RANDBETWEEN(2,4)&"%",""))))))))))) -> 2% | Q33: =IFERROR(L33*(M33+N33)*O33*P33,RANDBETWEEN(1,2)%*L33*(M33+N33)*O33) -> 0.33408622 | R33: =VLOOKUP(D:D,ranking!W:X,2,0) -> 0.7 | S33: =R33*Q33 -> 0.23386035 | T33: 5.8878518 | U33: 5.8878518
A34: Trending Top 10 | B34: ALL INDIA | C34: Sony Liv | D34: Tv Catch-Up | E34: FREE | F34: Tv CatchUp | G34: Indian Idol S16 | H34: Hindi | I34: 45948 | J34: 4 | K34: Reality Tv | L34: =VLOOKUP($C34&$E34,'Updated SES'!A:N,14,0) -> 5.268 | M34: =VLOOKUP($K34,'Genre Penetration'!A:B,2,0)*VLOOKUP($C34&$E34,'Updated SES'!A:I,9,0) -> 0.264 | N34: =VLOOKUP(K:K,'Genre Penetration'!A:C,3,0)*VLOOKUP($C34&$E34,'Updated SES'!A:J,10,0) -> 0.204 | O34: =VLOOKUP($B34,'Language Penetration'!$B$1:$BE$14,MATCH('Compile data Working'!#REF!,'Language Penetration'!$B$1:$BE$1,0),0) -> #REF! | P34: =IF(ISBLANK(J34),RANDBETWEEN(1,2)&"%",IF(J34=1,RANDBETWEEN(35,40)&"%",IF(J34=2,RANDBETWEEN(30,35)&"%",IF(J34=3,RANDBETWEEN(25,30)&"%",IF(J34=4,RANDBETWEEN(20,25)&"%",IF(J34=5,RANDBETWEEN(15,20)&"%",IF(J34=6,RANDBETWEEN(10,15)&"%",IF(J34=7,RANDBETWEEN(8,10)&"%",IF(J34=8,RANDBETWEEN(6,8)&"%",IF(J34=9,RANDBETWEEN(4,6)&"%",IF(J34=10,RANDBETWEEN(2,4)&"%",""))))))))))) -> 25% | Q34: =IFERROR(L34*(M34+N34)*O34*P34,RANDBETWEEN(1,2)%*L34*(M34+N34)*O34) -> #REF! | R34: =VLOOKUP(D:D,ranking!W:X,2,0) -> 0.3 | S34: =R34*Q34 -> #REF! | T34: 5.7981512
A35: Trending Top 10 | B35: ALL INDIA | C35: Apple Tv | D35: Svod Originals Shows | E35: PAID | F35: Shows | G35: Maximum Pleasure Guaranteed | H35: English | I35: 46162 | J35: 7 | K35: Crime,Thriller | L35: =VLOOKUP($C35&$E35,'Updated SES'!A:N,14,0) -> 1.669 | M35: =VLOOKUP($K35,'Genre Penetration'!A:B,2,0)*VLOOKUP($C35&$E35,'Updated SES'!A:I,9,0) -> 0.372 | N35: =VLOOKUP(K:K,'Genre Penetration'!A:C,3,0)*VLOOKUP($C35&$E35,'Updated SES'!A:J,10,0) -> 0.152 | O35: =VLOOKUP($B35,'Language Penetration'!$B$1:$BE$14,MATCH('Compile data Working'!$H41,'Language Penetration'!$B$1:$BE$1,0),0) -> #N/A | P35: =IF(ISBLANK(J35),RANDBETWEEN(1,2)&"%",IF(J35=1,RANDBETWEEN(35,40)&"%",IF(J35=2,RANDBETWEEN(30,35)&"%",IF(J35=3,RANDBETWEEN(25,30)&"%",IF(J35=4,RANDBETWEEN(20,25)&"%",IF(J35=5,RANDBETWEEN(15,20)&"%",IF(J35=6,RANDBETWEEN(10,15)&"%",IF(J35=7,RANDBETWEEN(8,10)&"%",IF(J35=8,RANDBETWEEN(6,8)&"%",IF(J35=9,RANDBETWEEN(4,6)&"%",IF(J35=10,RANDBETWEEN(2,4)&"%",""))))))))))) -> 9% | Q35: =IFERROR(L35*(M35+N35)*O35*P35,RANDBETWEEN(1,2)%*L35*(M35+N35)*O35) -> #N/A | R35: =VLOOKUP(D:D,ranking!W:X,2,0) -> 0.6 | S35: =R35*Q35 -> #N/A | T35: 5.7234718
A36: WK-22'2026 | B36: ALL INDIA | C36: Amazon Mx Player | D36: Theatrical releases | E36: FREE | F36: Movies | G36: Sukhamano Sukhamanu | H36: Tamil | I36: 46178 | K36: Comedy,Drama,Fantasy | L36: =VLOOKUP($C36&$E36,'Updated SES'!A:N,14,0) -> 78.93987 | M36: =VLOOKUP($K36,'Genre Penetration'!A:B,2,0)*VLOOKUP($C36&$E36,'Updated SES'!A:I,9,0) -> 0.432 | N36: =VLOOKUP(K:K,'Genre Penetration'!A:C,3,0)*VLOOKUP($C36&$E36,'Updated SES'!A:J,10,0) -> 0.092 | O36: =VLOOKUP($B36,'Language Penetration'!$B$1:$BE$14,MATCH('Compile data Working'!$H55,'Language Penetration'!$B$1:$BE$1,0),0) -> 0.6 | P36: =IF(ISBLANK(J36),RANDBETWEEN(1,2)&"%",IF(J36=1,RANDBETWEEN(35,40)&"%",IF(J36=2,RANDBETWEEN(30,35)&"%",IF(J36=3,RANDBETWEEN(25,30)&"%",IF(J36=4,RANDBETWEEN(20,25)&"%",IF(J36=5,RANDBETWEEN(15,20)&"%",IF(J36=6,RANDBETWEEN(10,15)&"%",IF(J36=7,RANDBETWEEN(8,10)&"%",IF(J36=8,RANDBETWEEN(6,8)&"%",IF(J36=9,RANDBETWEEN(4,6)&"%",IF(J36=10,RANDBETWEEN(2,4)&"%",""))))))))))) -> 1% | Q36: =IFERROR(L36*(M36+N36)*O36*P36,RANDBETWEEN(1,2)%*L36*(M36+N36)*O36) -> 0.24818695 | R36: =VLOOKUP(D:D,ranking!W:X,2,0) -> 0.7 | S36: =R36*Q36 -> 0.17373087 | T36: 5.3398045 | U36: 5.3398045
A37: Trending Top 10 | B37: ALL INDIA | C37: Zee5 | D37: Avod Originals Shows | E37: FREE | F37: Shows | G37: Hathras 16 days | H37: Hindi | I37: 46157 | J37: 4 | K37: Crime,Documentary | L37: =VLOOKUP($C37&$E37,'Updated SES'!A:N,14,0) -> 24.4258 | M37: =VLOOKUP($K37,'Genre Penetration'!A:B,2,0)*VLOOKUP($C37&$E37,'Updated SES'!A:I,9,0) -> 0.374 | N37: =VLOOKUP(K:K,'Genre Penetration'!A:C,3,0)*VLOOKUP($C37&$E37,'Updated SES'!A:J,10,0) -> 0.144 | O37: =VLOOKUP($B37,'Language Penetration'!$B$1:$BE$14,MATCH('Compile data Working'!#REF!,'Language Penetration'!$B$1:$BE$1,0),0) -> #REF! | P37: =IF(ISBLANK(J37),RANDBETWEEN(1,2)&"%",IF(J37=1,RANDBETWEEN(35,40)&"%",IF(J37=2,RANDBETWEEN(30,35)&"%",IF(J37=3,RANDBETWEEN(25,30)&"%",IF(J37=4,RANDBETWEEN(20,25)&"%",IF(J37=5,RANDBETWEEN(15,20)&"%",IF(J37=6,RANDBETWEEN(10,15)&"%",IF(J37=7,RANDBETWEEN(8,10)&"%",IF(J37=8,RANDBETWEEN(6,8)&"%",IF(J37=9,RANDBETWEEN(4,6)&"%",IF(J37=10,RANDBETWEEN(2,4)&"%",""))))))))))) -> 24% | Q37: =IFERROR(L37*(M37+N37)*O37*P37,RANDBETWEEN(1,2)%*L37*(M37+N37)*O37) -> #REF! | R37: =VLOOKUP(D:D,ranking!W:X,2,0) -> 0.6 | S37: =R37*Q37 -> #REF! | T37: 5.1265625
A38: Trending Top 10 | B38: ALL INDIA | C38: Amazon Prime Video | D38: Svod Originals Movies | E38: PAID | F38: Movies | G38: System | H38: Hindi,Tamil,Telugu | I38: 46164 | J38: 2 | K38: Drama,Suspense | L38: =VLOOKUP($C38&$E38,'Updated SES'!A:N,14,0) -> 36.49824 | M38: =VLOOKUP($K38,'Genre Penetration'!A:B,2,0)*VLOOKUP($C38&$E38,'Updated SES'!A:I,9,0) -> 0.312 | N38: =VLOOKUP(K:K,'Genre Penetration'!A:C,3,0)*VLOOKUP($C38&$E38,'Updated SES'!A:J,10,0) -> 0.192 | O38: =VLOOKUP($B38,'Language Penetration'!$B$1:$BE$14,MATCH('Compile data Working'!$H103,'Language Penetration'!$B$1:$BE$1,0),0) -> 0.09 | P38: =IF(ISBLANK(J38),RANDBETWEEN(1,2)&"%",IF(J38=1,RANDBETWEEN(35,40)&"%",IF(J38=2,RANDBETWEEN(30,35)&"%",IF(J38=3,RANDBETWEEN(25,30)&"%",IF(J38=4,RANDBETWEEN(20,25)&"%",IF(J38=5,RANDBETWEEN(15,20)&"%",IF(J38=6,RANDBETWEEN(10,15)&"%",IF(J38=7,RANDBETWEEN(8,10)&"%",IF(J38=8,RANDBETWEEN(6,8)&"%",IF(J38=9,RANDBETWEEN(4,6)&"%",IF(J38=10,RANDBETWEEN(2,4)&"%",""))))))))))) -> 33% | Q38: =IFERROR(L38*(M38+N38)*O38*P38,RANDBETWEEN(1,2)%*L38*(M38+N38)*O38) -> 0.54633485 | R38: =VLOOKUP(D:D,ranking!W:X,2,0) -> 0.8 | S38: =R38*Q38 -> 0.43706788 | T38: 5.1048459
A39: WK-22'2026 | B39: ALL INDIA | C39: Jio Hotstar | D39: SVOD Originals Shows | E39: PAID | F39: Shows | G39: Magnum P.I. | H39: English | I39: 46173 | K39: Action,Adevnture,Crime | L39: =VLOOKUP($C39&$E39,'Updated SES'!A:N,14,0) -> 127.11702 | M39: =VLOOKUP($K39,'Genre Penetration'!A:B,2,0)*VLOOKUP($C39&$E39,'Updated SES'!A:I,9,0) -> #N/A | N39: =VLOOKUP(K:K,'Genre Penetration'!A:C,3,0)*VLOOKUP($C39&$E39,'Updated SES'!A:J,10,0) -> #N/A | O39: =VLOOKUP($B39,'Language Penetration'!$B$1:$BE$14,MATCH('Compile data Working'!$H226,'Language Penetration'!$B$1:$BE$1,0),0) -> 0.6 | P39: =IF(ISBLANK(J39),RANDBETWEEN(1,2)&"%",IF(J39=1,RANDBETWEEN(35,40)&"%",IF(J39=2,RANDBETWEEN(30,35)&"%",IF(J39=3,RANDBETWEEN(25,30)&"%",IF(J39=4,RANDBETWEEN(20,25)&"%",IF(J39=5,RANDBETWEEN(15,20)&"%",IF(J39=6,RANDBETWEEN(10,15)&"%",IF(J39=7,RANDBETWEEN(8,10)&"%",IF(J39=8,RANDBETWEEN(6,8)&"%",IF(J39=9,RANDBETWEEN(4,6)&"%",IF(J39=10,RANDBETWEEN(2,4)&"%",""))))))))))) -> 2% | Q39: =IFERROR(L39*(M39+N39)*O39*P39,RANDBETWEEN(1,2)%*L39*(M39+N39)*O39) -> #N/A | R39: =VLOOKUP(D:D,ranking!W:X,2,0) -> 0.6 | S39: =R39*Q39 -> #N/A | T39: 5.0588902
A40: WK-22'2026 | B40: ALL INDIA | C40: Jio Hotstar | D40: SVOD Originals Shows | E40: PAID | F40: Shows | G40: Saturday Night Live UK | H40: English | I40: 46174 | K40: Comedy | L40: =VLOOKUP($C40&$E40,'Updated SES'!A:N,14,0) -> 127.11702 | M40: =VLOOKUP($K40,'Genre Penetration'!A:B,2,0)*VLOOKUP($C40&$E40,'Updated SES'!A:I,9,0) -> 0.3015 | N40: =VLOOKUP(K:K,'Genre Penetration'!A:C,3,0)*VLOOKUP($C40&$E40,'Updated SES'!A:J,10,0) -> 0.1815 | O40: =VLOOKUP($B40,'Language Penetration'!$B$1:$BE$14,MATCH('Compile data Working'!$H235,'Language Penetration'!$B$1:$BE$1,0),0) -> 0.6 | P40: =IF(ISBLANK(J40),RANDBETWEEN(1,2)&"%",IF(J40=1,RANDBETWEEN(35,40)&"%",IF(J40=2,RANDBETWEEN(30,35)&"%",IF(J40=3,RANDBETWEEN(25,30)&"%",IF(J40=4,RANDBETWEEN(20,25)&"%",IF(J40=5,RANDBETWEEN(15,20)&"%",IF(J40=6,RANDBETWEEN(10,15)&"%",IF(J40=7,RANDBETWEEN(8,10)&"%",IF(J40=8,RANDBETWEEN(6,8)&"%",IF(J40=9,RANDBETWEEN(4,6)&"%",IF(J40=10,RANDBETWEEN(2,4)&"%",""))))))))))) -> 1% | Q40: =IFERROR(L40*(M40+N40)*O40*P40,RANDBETWEEN(1,2)%*L40*(M40+N40)*O40) -> 0.36838512 | R40: =VLOOKUP(D:D,ranking!W:X,2,0) -> 0.6 | S40: =R40*Q40 -> 0.22103107 | T40: 4.9604708
A41: WK-22'2026 | B41: ALL INDIA | C41: Jio Hotstar | D41: Theatrical releases | E41: PAID | F41: Movies | G41: Jaws 3-D | H41: Hindi,English | I41: 46174 | K41: Adventure,Horror,Thriller | L41: =VLOOKUP($C41&$E41,'Updated SES'!A:N,14,0) -> 127.11702 | M41: =VLOOKUP($K41,'Genre Penetration'!A:B,2,0)*VLOOKUP($C41&$E41,'Updated SES'!A:I,9,0) -> #N/A | N41: =VLOOKUP(K:K,'Genre Penetration'!A:C,3,0)*VLOOKUP($C41&$E41,'Updated SES'!A:J,10,0) -> #N/A | O41: 0.007 | P41: =IF(ISBLANK(J41),RANDBETWEEN(1,2)&"%",IF(J41=1,RANDBETWEEN(35,40)&"%",IF(J41=2,RANDBETWEEN(30,35)&"%",IF(J41=3,RANDBETWEEN(25,30)&"%",IF(J41=4,RANDBETWEEN(20,25)&"%",IF(J41=5,RANDBETWEEN(15,20)&"%",IF(J41=6,RANDBETWEEN(10,15)&"%",IF(J41=7,RANDBETWEEN(8,10)&"%",IF(J41=8,RANDBETWEEN(6,8)&"%",IF(J41=9,RANDBETWEEN(4,6)&"%",IF(J41=10,RANDBETWEEN(2,4)&"%",""))))))))))) -> 1% | Q41: =IFERROR(L41*(M41+N41)*O41*P41,RANDBETWEEN(1,2)%*L41*(M41+N41)*O41) -> #N/A | R41: =VLOOKUP(D:D,ranking!W:X,2,0) -> 0.7 | S41: =R41*Q41 -> #N/A | T41: 4.949917
...

Sheet Sheet2
A1: ss | B1: ss
A2: Punjabi,Haryanvi | B2: 0.095
A3: Hindi,Kannada,Tamil | B3: 0.26666667
A4: English,Hindi,Kannada,Tamil,Telugu | B4: 0.23
A5: Hindi,Tamil,Telugu,Turkish | B5: #N/A
A6: Bengali,Hindi,Malayalam,Marathi,Tamil,Telugu | B6: 0.19
A7: Haryanvi,Rajasthani | B7: 0.1
A8: Hindi,English,Malayalam,Tamil,Telugu | B8: 0.224
A9: Hindi,Telugu | B9: 0.375
A10: English,Hindi,Kannada,Malayala,Marathi,Tamil,Telugu | B10: 0.19142857

Sheet ranking
A1: =B1&D1 -> OTT PLATFORMTop 10 | B1: OTT PLATFORM | C1: Content format | D1: Top 10 | E1: PAID/FREE | F1: Show/Movies | G1: Genre | H1: Language | I1: Average of Rank | J1: Round | L1: Rank | M1: Watching Percentage | O1: Rank | P1: Watching Percentage | S1: Rank | T1: Watching Percentage | AB1: 1) Original Shows - 80%
A2: =B2&D2 -> Adda TimesAbhishapto | B2: Adda Times | C2: Svod Originals Shows | D2: Abhishapto | E2: PAID | F2: Show | G2: Drama | H2: Bengali | I2: 9 | J2: 9 | L2: 7 | M2: 40-35% | O2: 7 | P2: 40-35% | S2: 1 | T2: 0.9 | W2: Content format | X2: Watching % | AB2: 2) Original Movies - 100%
A3: =B3&D3 -> Adda TimesBasanta Ese Geche | B3: Adda Times | C3: Svod Originals Shows | D3: Basanta Ese Geche | E3: PAID | F3: Show | G3: Drama | H3: Bengali | I3: 2 | J3: 2 | L3: 6 | M3: 35-30% | O3: 6 | P3: 35-30% | S3: 2 | T3: 0.85 | W3: Avod Originals Movies | X3: 0.8 | AB3: 3) Theatrical releases - 75% (conditions pl discuss)
A4: =B4&D4 -> Adda TimesCabaret | B4: Adda Times | C4: Svod Originals Shows | D4: Cabaret | E4: PAID | F4: Show | G4: Drama | H4: Bengali | I4: 4 | J4: 4 | L4: 5 | M4: 30-25% | O4: 5 | P4: 30-25% | S4: 3 | T4: 0.8 | W4: Avod Originals Shows | X4: 0.6 | AB4: 4) Catch up TV Shows - 30% (For bigg boss its also live and have highlights so higher)
A5: =B5&D5 -> Adda TimesGhoshbabur-retirement-plan | B5: Adda Times | C5: Svod Originals Shows | D5: Ghoshbabur-retirement-plan | E5: PAID | F5: Show | G5: Drama | H5: Bengali | I5: 7 | J5: 7 | L5: 4 | M5: 25-20% | O5: 4 | P5: 25-20% | S5: 4 | T5: 0.7 | W5: Live Event | X5: 0.1 | AB5: 5) Live sports - depending upon sports 100% for Cricket, Kabbadi 40%, rest sport 10-15%
A6: =B6&D6 -> Adda TimesKothamrita | B6: Adda Times | C6: Svod Originals Shows | D6: Kothamrita | E6: PAID | F6: Show | G6: Drama,Family | H6: Bengali | I6: 10 | J6: 10 | L6: 3 | M6: 20-15% | O6: 3 | P6: 20-15% | S6: 5 | T6: 0.65 | W6: Svod Originals Movies | X6: 0.8 | AB6: 4) Highlights - 10% of Live sports
A7: =B7&D7 -> Adda TimesNandini | B7: Adda Times | C7: Svod Originals Shows | D7: Nandini | E7: PAID | F7: Show | G7: Drama | H7: Bengali | I7: 8 | J7: 8 | L7: 2 | M7: 15-10% | O7: 2 | P7: 15-10% | S7: 6 | T7: 0.6 | W7: Svod Originals Shows | X7: 0.6
A8: =B8&D8 -> Adda TimesPetni | B8: Adda Times | C8: Svod Originals Shows | D8: Petni | E8: PAID | F8: Show | G8: Drama | H8: Bengali | I8: 5 | J8: 5 | L8: 1 | M8: 10-8% | O8: 1 | P8: 10-8% | S8: 7 | T8: 0.55 | W8: Theatrical releases | X8: 0.7
A9: =B9&D9 -> Adda TimesPreme Pora Baron | B9: Adda Times | C9: Svod Originals Shows | D9: Preme Pora Baron | E9: PAID | F9: Show | G9: Drama | H9: Bengali | I9: 3 | J9: 3 | L9: 8 | M9: 8-6% | S9: 8 | T9: 0.5 | W9: Tv Catch-Up | X9: 0.3
A10: =B10&D10 -> Adda TimesSIN - Whispers Of Guilt | B10: Adda Times | C10: Svod Originals Shows | D10: SIN - Whispers Of Guilt | E10: PAID | F10: Show | G10: Comedy | H10: Bengali | I10: 6 | J10: 6 | L10: 9 | M10: 6-4% | S10: 9 | T10: 0.45 | W10: Theatrical Movies | X10: 0.7
A11: =B11&D11 -> Adda TimesThe First Rain | B11: Adda Times | C11: Svod Originals Shows | D11: The First Rain | E11: PAID | F11: Show | G11: Drama,Romance | H11: Bengali | I11: 1 | J11: 1 | L11: 10 | M11: 4-2% | S11: 10 | T11: 0.4
A12: =B12&D12 -> Aha Video11th Hour | B12: Aha Video | C12: Svod Originals Shows | D12: 11th Hour | E12: PAID | F12: Show | G12: Drama,Thriller | H12: Telugu | I12: 8 | J12: 8 | S12: 11 | T12: =T11*90% -> 0.36
A13: =B13&D13 -> Aha VideoAkash Vaani | B13: Aha Video | C13: Svod Originals Shows | D13: Akash Vaani | E13: PAID | F13: Show | G13: Comedy,Romane | H13: Tamil,Telugu | I13: 5 | J13: 5 | S13: 12 | T13: =T12*90% -> 0.324
A14: =B14&D14 -> Aha VideoAmmuchi 2 | B14: Aha Video | C14: Svod Originals Shows | D14: Ammuchi 2 | E14: PAID | F14: Show | G14: Comedy | H14: Tamil | I14: 6 | J14: 6 | S14: 13 | T14: =T13*90% -> 0.2916
A15: =B15&D15 -> Aha VideoAnya's Tutorial | B15: Aha Video | C15: Svod Originals Shows | D15: Anya's Tutorial | E15: PAID | F15: Show | G15: Drama | H15: Tamil | I15: 10 | J15: 10 | S15: 14 | T15: =T14*90% -> 0.26244
A16: =B16&D16 -> Aha VideoEmoji | B16: Aha Video | C16: Svod Originals Shows | D16: Emoji | E16: PAID | F16: Show | G16: Romance | H16: Tamil | I16: 3 | J16: 3 | S16: 15 | T16: =T15*90% -> 0.236196
A17: =B17&D17 -> Aha VideoEP7 Youtubers | B17: Aha Video | C17: Svod Originals Shows | D17: EP7 Youtubers | E17: PAID | F17: Show | G17: Game Show | H17: Telugu | I17: 4 | J17: 4 | S17: 16 | T17: =T16*90% -> 0.2125764
A18: =B18&D18 -> Aha VideoIrai | B18: Aha Video | C18: Svod Originals Shows | D18: Irai | E18: PAID | F18: Show | G18: Action,Crime,Drama | H18: Tamil | I18: 2 | J18: 2 | S18: 17 | T18: =T17*90% -> 0.19131876
A19: =B19&D19 -> Aha VideoKuthukku Pathu | B19: Aha Video | C19: Svod Originals Shows | D19: Kuthukku Pathu | E19: PAID | F19: Show | G19: Comedy | H19: Tamil | I19: 7 | J19: 7 | S19: 18 | T19: =T18*90% -> 0.17218688
A20: =B20&D20 -> Aha VideoMad Company | B20: Aha Video | C20: Svod Originals Shows | D20: Mad Company | E20: PAID | F20: Show | G20: Comedy,Drama | H20: Tamil | I20: 9 | J20: 9 | S20: 19 | T20: =T19*90% -> 0.1549682
A21: =B21&D21 -> Aha VideoPettaikaali | B21: Aha Video | C21: Svod Originals Shows | D21: Pettaikaali | E21: PAID | F21: Show | G21: Action | H21: Tamil | I21: 1 | J21: 1 | S21: 20 | T21: =T20*90% -> 0.13947138
A22: =B22&D22 -> Aha VideoAyngaran | B22: Aha Video | C22: Theatrical releases | D22: Ayngaran | E22: PAID | F22: Movie | G22: Action,Drama | H22: Tamil | I22: 4 | J22: 4 | S22: 21 | T22: =T21*90% -> 0.12552424
A23: =B23&D23 -> Aha VideoDiary | B23: Aha Video | C23: Theatrical releases | D23: Diary | E23: PAID | F23: Movie | G23: Horror,Thriller | H23: Tamil | I23: 3 | J23: 3 | S23: 22 | T23: =T22*90% -> 0.11297181
... A92: =B92&D92 -> Apple TvBefore | B92: Apple Tv | C92: Svod Originals Shows | D92: Before | E92: PAID | F92: Show | G92: Drama,Thriller | H92: English | I92: 9 | J92: 9 | S92: 100 | T92: =T91*90% -> 7.865082e-05
A93: =B93&D93 -> Apple TvDisclaimer | B93: Apple Tv | C93: Svod Originals Shows | D93: Disclaimer | E93: PAID | F93: Show | G93: Drama,Mystery,Thriller | H93: English | I93: 5 | J93: 5
A94: =B94&D94 -> Apple TvPresumed Innocent | B94: Apple Tv | C94: Svod Originals Shows | D94: Presumed Innocent | E94: PAID | F94: Show | G94: Crime,Drama,Mystery | H94: English | I94: 7 | J94: 7
A95: =B95&D95 -> Apple TvSee | B95: Apple Tv | C95: Svod Originals Shows | D95: See | E95: PAID | F95: Show | G95: Action,Drama,Sci-Fi | H95: English | I95: 8 | J95: 8
A96: =B96&D96 -> Apple TvSeverance | B96: Apple Tv | C96: Svod Originals Shows | D96: Severance | E96: PAID | F96: Show | G96: Drama,Mystery,Thriller | H96: English | I96: 10 | J96: 10
A97: =B97&D97 -> Apple TvShrinking | B97: Apple Tv | C97: Svod Originals Shows | D97: Shrinking | E97: PAID | F97: Show | G97: Comedy,Drama | H97: English | I97: 3 | J97: 3
A98: =B98&D98 -> Apple TvSilo | B98: Apple Tv | C98: Svod Originals Shows | D98: Silo | E98: PAID | F98: Show | G98: Drama,Mystery,Sci-Fi | H98: English | I98: 1 | J98: 1
A99: =B99&D99 -> Apple TvSlow Horses | B99: Apple Tv | C99: Svod Originals Shows | D99: Slow Horses | E99: PAID | F99: Show | G99: Drama,Thriller | H99: English | I99: 6 | J99: 6
A100: =B100&D100 -> Apple TvTed Lasso | B100: Apple Tv | C100: Svod Originals Shows | D100: Ted Lasso | E100: PAID | F100: Show | G100: Comedy,Drama,Sport | H100: English | I100: 4 | J100: 4
A101: =B101&D101 -> Apple TvKillers of the Flower Moon | B101: Apple Tv | C101: Theatrical releases | D101: Killers of the Flower Moon | E101: PAID | F101: Movie | G101: Crime,Drama,Mystery | H101: English | I101: 8 | J101: 8
A102: =B102&D102 -> Apple TvLuck | B102: Apple Tv | C102: Theatrical releases | D102: Luck | E102: PAID | F102: Movie | G102: Animation,Adventure,Comedy | H102: English | I102: 4 | J102: 4
A103: =B103&D103 -> Apple TvWolfs | B103: Apple Tv | C103: Theatrical releases | D103: Wolfs | E103: PAID | F103: Movie | G103: Crime,Thriller | H103: English | I103: 1 | J103: 1
A104: =B104&D104 -> Chaupal TvJatt & Jullit 3 | B104: Chaupal Tv | C104: Svod Originals Movies | D104: Jatt & Jullit 3 | E104: PAID | F104: Movie | G104: Comedy,Romance | H104: Punjabi | I104: 3 | J104: 3
... A393: =B393&D393 -> Zee5Yek Number | B393: Zee5 | C393: Svod Originals Movies | D393: Yek Number | E393: PAID | F393: Movie | G393: Drama | H393: Marathi | I393: 4.6666667 | J393: 5
A394: =B394&D394 -> Zee52012 | B394: Zee5 | C394: Theatrical releases | D394: 2012 | E394: RENT | F394: Movie | G394: Action,Sci-Fi | H394: Hindi,English,Tamil, | I394: 9 | J394: 9
A395: =B395&D395 -> Zee5Bhaiyya Ji | B395: Zee5 | C395: Theatrical releases | D395: Bhaiyya Ji | E395: PAID | F395: Movie | G395: Action,Drama | H395: Hindi | I395: 7.3333333 | J395: 7
A396: =B396&D396 -> Zee5Fifty Shades Freed | B396: Zee5 | C396: Theatrical releases | D396: Fifty Shades Freed | E396: RENT | F396: Movie | G396: Romance,Drama,Thriller | H396: Hindi,English | I396: 6 | J396: 6
...

Sheet Updated SES
A2: OTT PlatformsTYPE | B2: OTT Platforms | C2: Language | D2: Region | E2: TYPE | F2: Show Type | G2: Top 10 | H2: Actual Subscribers | I2: Male % | J2: Female % | K2: CTV | L2: Mobile | M2: CTV+Mobile | N2: Total Viewers | V2: Category | W2: 2-24 | X2: 25-34 | Y2: 35-44 | Z2: 45+
A3: =B3&E3 -> Adda TimesPAID | B3: Adda Times | C3: Bengali | D3: West Bengali | E3: PAID | F3: SVOD | G3: NA | H3: 1.6 | I3: 0.8 | J3: 0.2 | K3: 0.13 | L3: 0.87 | M3: 0.06 | N3: =H3*K3*3+H3*L3*1.1-H3*M3*3 -> 1.8672 | V3: ALL INDIA | W3: 0.3 | X3: 0.33 | Y3: 0.2 | Z3: 0.17
A4: =B4&E4 -> Aha VideoPAID | B4: Aha Video | C4: Telugu & Tamil | D4: Andhra Pradesh,Telangana,Tamilnadu | E4: PAID | F4: SVOD | G4: Yes | H4: 9.23 | I4: 0.76 | J4: 0.24 | K4: 0.22 | L4: 0.78 | M4: 0.05 | N4: =H4*K4*3+H4*L4*1.1-H4*M4*3 -> 12.62664
A5: =B5&E5 -> Aha VideoFREE | B5: Aha Video | C5: Telugu & Tamil | D5: Andhra Pradesh,Telangana,Tamilnadu | E5: FREE | F5: AVOD | G5: Yes | H5: 3.75 | I5: 0.76 | J5: 0.24 | K5: 0.22 | L5: 0.78 | M5: 0.05 | N5: =H5*K5*3+H5*L5*1.1-H5*M5*3 -> 5.13
A6: =B6&E6 -> AlttPAID | B6: Altt | C6: Hindi | D6: All India | E6: PAID | F6: SVOD | G6: Yes | H6: 12.16 | I6: 0.65 | J6: 0.35 | K6: 0.26 | L6: 0.74 | M6: 0.07 | N6: =H6*K6*3+H6*L6*1.1-H6*M6*3 -> 16.82944
A7: =B7&E7 -> Amazon Prime VideoPAID | B7: Amazon Prime Video | C7: Hindi,English,Tamil,Telugu,Malayalam,Kannada,Bengali | D7: All India | E7: PAID | F7: SVOD | G7: Yes | H7: 22.08 | I7: 0.52 | J7: 0.48 | K7: 0.37 | L7: 0.63 | M7: 0.05 | N7: =H7*K7*3+H7*L7*1.1-H7*M7*3 -> 36.49824
A8: =B8&E8 -> Amazon Prime VideoFREE | B8: Amazon Prime Video | C8: Hindi,English,Tamil,Telugu,Malayalam,Kannada,Bengali | D8: All India | E8: FREE | F8: SVOD | G8: Yes | H8: 5.09 | I8: 0.52 | J8: 0.48 | K8: 0.37 | L8: 0.63 | M8: 0.05 | N8: =H8*K8*3+H8*L8*1.1-H8*M8*3 -> 8.41377 | T8: Demographic Profile | U8: Jio Hotstar | V8: Amazon Prime Video | W8: Netflix | X8: Amazon MX Player | Y8: Zee5 | Z8: Sony Liv | AA8: Alt Balaji | AB8: Sun NXT | AC8: Hoichoi | AD8: Aha Video | AE8: Stage | AF8: Other OTT (Non Regional) | AG8: Other OTT (Regional) | AK8: Location | AL8: Jio Hotstar | AM8: Amazon Prime Video | AN8: Netflix | AO8: Amazon MX Player | AP8: Zee5 | AQ8: Sony Liv | AR8: Alt Balaji | AS8: Sun NXT | AT8: Hoichoi | AU8: Aha Video | AV8: Stage | AW8: Other OTT (Non Regional) | AX8: Other OTT (Regional)
A9: =B9&E9 -> Amazon Prime VideoRENT | B9: Amazon Prime Video | C9: Hindi,English,Tamil,Telugu,Malayalam,Kannada,Bengali | D9: All India | E9: RENT | F9: Rent | G9: NA | H9: 3 | I9: 0.68 | J9: 0.32 | K9: 0.37 | L9: 0.63 | M9: 0.08 | N9: =H9*K9*3+H9*L9*1.1-H9*M9*3 -> 4.689 | T9: M <18 | U9: 0.10790021 | V9: 0.034482029 | W9: 0.035616735 | X9: 0.081691769 | Y9: 0.014519981 | Z9: 0.04214677 | AA9: 0.033684735 | AB9: 0.03331181 | AC9: 0.1309339 | AD9: 0.023882568 | AE9: 0.031394817 | AF9: 0.10547326 | AG9: 0.048860553 | AK9: North - Metro & T1 | AL9: 0.16111013 | AM9: 0.22260068 | AN9: 0.23109857 | AO9: 0.3575414 | AP9: 0.19018048 | AQ9: 0.2027027 | AR9: 0.1888668 | AS9: 0.0010650257 | AT9: 0.0044869546 | AU9: 0.0020714194 | AV9: 0.51032078 | AW9: 0.19978664 | AX9: 0.096550337
