Workbook

Sheet Top 50 Shows & Movies
F1: WK-24, 2026 ( 13 Jun 2026 - 19 Jun 2026 )
A6: Week | B6: MARKET | C6: Platform | D6: Content format | E6: PAID/FREE | F6: Content Type | G6: Shows/Live Content | H6: Language | I6: Genre | J6: Release Date | K6: Rank | L6: Reach
A7: WK-24,2026 | B7: ALL INDIA | C7: JioHotstar | D7: Theatrical Movies | E7: PAID | F7: Movies | G7: Dhurandhar: The Revenge | H7: Hindi,Kannada,Malayalam,Tamil,Telugu | I7: Action,Crime,Thriller | J7: 46177 | K7: 1 | L7: 56.557616
A8: WK-24,2026 | B8: ALL INDIA | C8: JioHotstar | D8: Live Event | E8: PAID | F8: Sports | G8: AFGHANISTAN IN INDIA ODI SERIES 2026 | H8: Bengali,Bhojpuri,English,Haryanvi,Hindi,Kannada,Malayalam,Tamil,Telugu | I8: Sports | J8: 46186 | K8: =K7+1 -> 2 | L8: 46.138629
A9: WK-24,2026 | B9: ALL INDIA | C9: JioHotstar | D9: Live Event | E9: PAID | F9: Sports | G9: ICC Women's T20 World Cup 2026 | H9: Hindi | I9: Sport | J9: 46185 | K9: =K8+1 -> 3 | L9: 45.834995
A10: WK-24,2026 | B10: ALL INDIA | C10: Amazon Prime Video | D10: Theatrical Movies | E10: PAID | F10: Movies | G10: Karuppu | H10: Hindi,Kannada,Malayalam,Tamil | I10: Action,Comedy,Drama | J10: 46185 | K10: =K9+1 -> 4 | L10: 26.903316
A11: WK-24,2026 | B11: ALL INDIA | C11: Amazon Prime Video | D11: Svod Originals Shows | E11: PAID | F11: Shows | G11: Raakh | H11: Hindi,Tamil,Telugu | I11: Crime,Drama,Thriller | J11: 46185 | K11: =K10+1 -> 5 | L11: 26.705003
A12: WK-24,2026 | B12: ALL INDIA | C12: Netflix | D12: Theatrical Movies | E12: PAID | F12: Movies | G12: Bhooth Bangla | H12: Hindi | I12: Comedy,Horror | J12: 46185 | K12: =K11+1 -> 6 | L12: 19.527626
A13: WK-24,2026 | B13: ALL INDIA | C13: Amazon MX Player | D13: Avod Originals Shows | E13: FREE | F13: Shows | G13: Ab Hoga Hisaab | H13: Hindi | I13: Crime,Drama,Thriller | J13: 46191 | K13: =K12+1 -> 7 | L13: 24.870206
A14: WK-24,2026 | B14: ALL INDIA | C14: JioHotstar | D14: Tv Catch-Up | E14: PAID | F14: Tv catchup | G14: Laughter Chefs S3 | H14: Hindi | I14: Comedy,Reality-Tv | J14: 45983 | K14: =K13+1 -> 8 | L14: 21.996205
A15: WK-24,2026 | B15: ALL INDIA | C15: JioHotstar | D15: Svod Originals Shows | E15: PAID | F15: Shows | G15: Thukra Ke Mera Pyaar Season 2 | H15: Bengali,Bhojpuri,Hindi,Kannada,Malayalam,Marathi,Tamil,Telugu | I15: Romance | J15: 46192 | K15: =K14+1 -> 9 | L15: 21.448858
A16: WK-24,2026 | B16: ALL INDIA | C16: Amazon Prime Video | D16: SVOD Originals Movies | E16: PAID | F16: Movies | G16: Your Fault: London | H16: English,Hindi,Kannada,Malayalam,Tamil,Telugu | I16: Drama,Romance | J16: 46190 | K16: =K15+1 -> 10 | L16: 18.923245
A17: WK-24,2026 | B17: ALL INDIA | C17: JioHotstar | D17: Tv Catch-Up | E17: PAID | F17: Tv catchup | G17: Anupama | H17: Hindi | I17: Drama | J17: 44025 | K17: =K16+1 -> 11 | L17: 18.374668
A18: WK-24,2026 | B18: ALL INDIA | C18: Amazon Prime Video | D18: Svod Originals Shows | E18: PAID | F18: Shows | G18: From S4 | H18: English,Hindi | I18: Drama,Horror | J18: 46131 | K18: =K17+1 -> 12 | L18: 17.994455
A19: WK-24,2026 | B19: ALL INDIA | C19: Amazon Prime Video | D19: Svod Originals Shows | E19: PAID | F19: Shows | G19: The Pyramid Scheme | H19: Hindi | I19: Comedy,Drama | J19: 46178 | K19: =K18+1 -> 13 | L19: 17.507986
... A21: WK-24,2026 | B21: ALL INDIA | C21: Amazon Prime Video | D21: Theatrical Movies | E21: PAID | F21: Movies | G21: Mareechika | H21: Hindi | I21: Drama,Romance,Thriller | J21: 46192 | K21: =K20+1 -> 15 | L21: 16.624409
A22: WK-24,2026 | B22: ALL INDIA | C22: Netflix | D22: Theatrical Movies | E22: PAID | F22: Movies | G22: 29 | H22: Hindi,Kannada,Malayalam,Tamil,Telugu | I22: Comedy,Drama,Romance | J22: 46178 | K22: =K21+1 -> 16 | L22: 16.496989
A23: WK-24,2026 | B23: ALL INDIA | C23: Netflix | D23: SVOD Originals Shows | E23: PAID | F23: Shows | G23: My Love Story With Yamada-kun at Lv999 | H23: English | I23: Animation,Comedy,Romance | J23: 46188 | K23: =K22+1 -> 17 | L23: 16.496989
A24: WK-24,2026 | B24: ALL INDIA | C24: JioHotstar | D24: Theatrical Movies | E24: PAID | F24: Movies | G24: Kenatha Kanom | H24: Bengali,Hindi,Kannada,Malayalam,Marathi,Tamil,Telugu | I24: Comedy,Drama | J24: 46189 | K24: =K23+1 -> 18 | L24: 16.21064
A25: WK-24,2026 | B25: ALL INDIA | C25: Netflix | D25: Svod Originals Shows | E25: PAID | F25: Shows | G25: Teach You a Lesson | H25: English,Hindi,Tamil,Telugu | I25: Action,Drama | J25: 46178 | K25: =K24+1 -> 19 | L25: 16.16119
A26: WK-24,2026 | B26: ALL INDIA | C26: Netflix | D26: SVOD Originals Shows | E26: PAID | F26: Shows | G26: Horimiya Season 2 | H26: English | I26: Animation,Drama,Romance | J26: 46188 | K26: =K25+1 -> 20 | L26: 15.934591
A27: WK-24,2026 | B27: ALL INDIA | C27: Amazon Prime Video | D27: Theatrical Movies | E27: PAID | F27: Movies | G27: Dacoit | H27: Hindi | I27: Action,Drama,Thriller | J27: 46178 | K27: =K26+1 -> 21 | L27: 15.240957
A28: WK-24,2026 | B28: ALL INDIA | C28: JioHotstar | D28: SVOD Originals Shows | E28: PAID | F28: Shows | G28: Harry Potter: The Official Film Podcast | H28: English | I28: Talk Show | J28: 46190 | K28: =K27+1 -> 22 | L28: 14.736946
A29: WK-24,2026 | B29: ALL INDIA | C29: JioHotstar | D29: SVOD Originals Shows | E29: PAID | F29: Shows | G29: Save the Tigers Season 3 | H29: Bengali,Hindi,Kannada,Malayalam,Marathi,Tamil,Telugu | I29: Comedy,Drama,Thriller | J29: 46192 | K29: =K28+1 -> 23 | L29: 14.589576
A30: WK-24,2026 | B30: ALL INDIA | C30: JioHotstar | D30: Theatrical Movies | E30: PAID | F30: Movies | G30: Dridam | H30: Hindi,Kannada,Malayalam,Tamil,Telugu | I30: Crime,Drama,Thriller | J30: 46185 | K30: =K29+1 -> 24 | L30: 14.533046
A31: WK-24,2026 | B31: ALL INDIA | C31: Netflix | D31: Theatrical Movies | E31: PAID | F31: Movies | G31: Maa Behen | H31: English,Hindi,Tamil,Telugu | I31: Comedy,Crime,Drama | J31: 46177 | K31: =K30+1 -> 25 | L31: 14.305931
A32: WK-24,2026 | B32: ALL INDIA | C32: Sony Liv | D32: Svod Originals Shows | E32: PAID | F32: Shows | G32: Gullak Season 5 | H32: Hindi | I32: Comedy,Drama | J32: 46178 | K32: =K31+1 -> 26 | L32: 13.925057
A33: WK-24,2026 | B33: ALL INDIA | C33: Netflix | D33: SVOD Originals Shows | E33: PAID | F33: Shows | G33: Oasis | H33: English,Hindi,Tamil,Telugu | I33: Crime,Drama,Mystery | J33: 46192 | K33: =K32+1 -> 27 | L33: 13.809249
A34: WK-24,2026 | B34: ALL INDIA | C34: Amazon Prime Video | D34: Theatrical Movies | E34: PAID | F34: Movies | G34: A Snapshot of Forever | H34: English | I34: Comedy,Romance | J34: 46190 | K34: =K33+1 -> 28 | L34: 13.793016
... A56: WK-24,2026 | B56: ALL INDIA | C56: Lionsgate Play | D56: Theatrical Movies | E56: PAID | F56: Movies | G56: Motive For Murder (M4M) | H56: Hindi,Kannada,Malayalam,Tamil,Telugu | I56: Drama | J56: 46192 | K56: =K55+1 -> 50 | L56: 11.164489
C59: Gender
A60: PLATFORM | B60: Total Reach | C60: Male | D60: Female
A61: Amazon Prime Video | B61: 361.64643 | C61: =VLOOKUP(A:A,'Updated SES'!B:J,8,0) -> 0.52 | D61: =VLOOKUP(A:A,'Updated SES'!B:J,9,0) -> 0.48
A62: JioHotstar | B62: 329.92806 | C62: =VLOOKUP(A:A,'Updated SES'!B:J,8,0) -> 0.625 | D62: =VLOOKUP(A:A,'Updated SES'!B:J,9,0) -> 0.375
A63: Netflix | B63: 269.72524 | C63: =VLOOKUP(A:A,'Updated SES'!B:J,8,0) -> 0.49 | D63: =VLOOKUP(A:A,'Updated SES'!B:J,9,0) -> 0.51
A64: Sony Liv | B64: 90.716173 | C64: =VLOOKUP(A:A,'Updated SES'!B:J,8,0) -> 0.65 | D64: =VLOOKUP(A:A,'Updated SES'!B:J,9,0) -> 0.35
A65: Amazon MX Player | B65: 61.935932 | C65: =VLOOKUP(A:A,'Updated SES'!B:J,8,0) -> 0.8 | D65: =VLOOKUP(A:A,'Updated SES'!B:J,9,0) -> 0.2

Sheet Compile data Working
G1: WK-24, 2026 ( 13 Jun 2026 - 19 Jun 2026 )
M3: Genre Weightage%
A4: Week | B4: MARKET | C4: Platform | D4: Live Event | E4: PAID/FREE | F4: Show Type | G4: Shows/Live Content | H4: Language | I4: Release Date | J4: Ranking | K4: Genre | L4: Total Viewers In Mn | M4: Male | N4: Female | O4: Language Weightage % | P4: Ranking Penetration | Q4: Reach | R4: Content format % | S4: Final Reach | T4: WK-24 Reach
A5: Trending Top 10 | B5: ALL INDIA | C5: JioHotstar | D5: Theatrical Movies | E5: PAID | F5: Movies | G5: Dhurandhar: The Revenge | H5: Hindi,Kannada,Malayalam,Tamil,Telugu | I5: 46177 | J5: 3 | K5: Action,Crime,Thriller | L5: =VLOOKUP($C5&$E5,'Updated SES'!A:N,14,0) -> 127.11702 | M5: =VLOOKUP($K5,'Genre Penetration'!A:B,2,0)*VLOOKUP($C5&$E5,'Updated SES'!A:I,9,0) -> 0.4824 | N5: =VLOOKUP(K:K,'Genre Penetration'!A:C,3,0)*VLOOKUP($C5&$E5,'Updated SES'!A:J,10,0) -> 0.0924 | O5: =VLOOKUP($B5,'Language Penetration'!$B$1:$BE$14,MATCH('Compile data Working'!$H5,'Language Penetration'!$B$1:$BE$1,0),0) -> 0.204 | P5: =IF(ISBLANK(J5),RANDBETWEEN(1,2)&"%",IF(J5=1,RANDBETWEEN(35,40)&"%",IF(J5=2,RANDBETWEEN(30,35)&"%",IF(J5=3,RANDBETWEEN(25,30)&"%",IF(J5=4,RANDBETWEEN(20,25)&"%",IF(J5=5,RANDBETWEEN(15,20)&"%",IF(J5=6,RANDBETWEEN(10,15)&"%",IF(J5=7,RANDBETWEEN(8,10)&"%",IF(J5=8,RANDBETWEEN(6,8)&"%",IF(J5=9,RANDBETWEEN(4,6)&"%",IF(J5=10,RANDBETWEEN(2,4)&"%",""))))))))))) -> 27% | Q5: =IFERROR(L5*(M5+N5)*O5*P5,RANDBETWEEN(1,2)%*L5*(M5+N5)*O5) -> 4.0245228 | R5: =VLOOKUP(D:D,ranking!W:X,2,0) -> 0.7 | S5: =R5*Q5 -> 2.817166 | T5: 56.557616
A6: WK-24'2026 | B6: ALL INDIA | C6: JioHotstar | D6: Live Event | E6: PAID | F6: Sports | G6: AFGHANISTAN IN INDIA ODI SERIES 2026 | H6: Bengali,Bhojpuri,English,Haryanvi,Hindi,Kannada,Malayalam,Tamil,Telugu | I6: 46186 | K6: Sports | L6: =VLOOKUP($C6&$E6,'Updated SES'!A:N,14,0) -> 127.11702 | M6: =VLOOKUP($K6,'Genre Penetration'!A:B,2,0)*VLOOKUP($C6&$E6,'Updated SES'!A:I,9,0) -> 0.5025 | N6: =VLOOKUP(K:K,'Genre Penetration'!A:C,3,0)*VLOOKUP($C6&$E6,'Updated SES'!A:J,10,0) -> 0.0825 | O6: =VLOOKUP($B6,'Language Penetration'!$B$1:$BE$14,MATCH('Compile data Working'!$H6,'Language Penetration'!$B$1:$BE$1,0),0) -> #N/A | P6: =IF(ISBLANK(J6),RANDBETWEEN(1,2)&"%",IF(J6=1,RANDBETWEEN(35,40)&"%",IF(J6=2,RANDBETWEEN(30,35)&"%",IF(J6=3,RANDBETWEEN(25,30)&"%",IF(J6=4,RANDBETWEEN(20,25)&"%",IF(J6=5,RANDBETWEEN(15,20)&"%",IF(J6=6,RANDBETWEEN(10,15)&"%",IF(J6=7,RANDBETWEEN(8,10)&"%",IF(J6=8,RANDBETWEEN(6,8)&"%",IF(J6=9,RANDBETWEEN(4,6)&"%",IF(J6=10,RANDBETWEEN(2,4)&"%",""))))))))))) -> 2% | Q6: =IFERROR(L6*(M6+N6)*O6*P6,RANDBETWEEN(1,2)%*L6*(M6+N6)*O6) -> #N/A | R6: =VLOOKUP(D:D,ranking!W:X,2,0) -> 0.1 | S6: =R6*Q6 -> #N/A | T6: 46.138629
A7: Cott Data Servey | B7: ALL INDIA | C7: JioHotstar | D7: Live Event | E7: PAID | F7: Sports | G7: ICC Women's T20 World Cup 2026 | H7: Hindi | I7: 46185 | K7: Sport | L7: =VLOOKUP($C7&$E7,'Updated SES'!A:N,14,0) -> 127.11702 | M7: =VLOOKUP($K7,'Genre Penetration'!A:B,2,0)*VLOOKUP($C7&$E7,'Updated SES'!A:I,9,0) -> 0.5025 | N7: =VLOOKUP(K:K,'Genre Penetration'!A:C,3,0)*VLOOKUP($C7&$E7,'Updated SES'!A:J,10,0) -> 0.0825 | O7: =VLOOKUP($B7,'Language Penetration'!$B$1:$BE$14,MATCH('Compile data Working'!$H7,'Language Penetration'!$B$1:$BE$1,0),0) -> 0.6 | P7: =IF(ISBLANK(J7),RANDBETWEEN(1,2)&"%",IF(J7=1,RANDBETWEEN(35,40)&"%",IF(J7=2,RANDBETWEEN(30,35)&"%",IF(J7=3,RANDBETWEEN(25,30)&"%",IF(J7=4,RANDBETWEEN(20,25)&"%",IF(J7=5,RANDBETWEEN(15,20)&"%",IF(J7=6,RANDBETWEEN(10,15)&"%",IF(J7=7,RANDBETWEEN(8,10)&"%",IF(J7=8,RANDBETWEEN(6,8)&"%",IF(J7=9,RANDBETWEEN(4,6)&"%",IF(J7=10,RANDBETWEEN(2,4)&"%",""))))))))))) -> 1% | Q7: =IFERROR(L7*(M7+N7)*O7*P7,RANDBETWEEN(1,2)%*L7*(M7+N7)*O7) -> 0.44618074 | R7: =VLOOKUP(D:D,ranking!W:X,2,0) -> 0.1 | S7: =R7*Q7 -> 0.044618074 | T7: 45.834995
A8: Trending Top 10 | B8: ALL INDIA | C8: Amazon Prime Video | D8: Theatrical Movies | E8: PAID | F8: Movies | G8: Karuppu | H8: Hindi,Kannada,Malayalam,Tamil | I8: 46185 | J8: 3 | K8: Action,Comedy,Drama | L8: =VLOOKUP($C8&$E8,'Updated SES'!A:N,14,0) -> 36.49824 | M8: =VLOOKUP($K8,'Genre Penetration'!A:B,2,0)*VLOOKUP($C8&$E8,'Updated SES'!A:I,9,0) -> 0.2496 | N8: =VLOOKUP(K:K,'Genre Penetration'!A:C,3,0)*VLOOKUP($C8&$E8,'Updated SES'!A:J,10,0) -> 0.2496 | O8: =VLOOKUP($B8,'Language Penetration'!$B$1:$BE$14,MATCH('Compile data Working'!$H23,'Language Penetration'!$B$1:$BE$1,0),0) -> 0.17714286 | P8: =IF(ISBLANK(J8),RANDBETWEEN(1,2)&"%",IF(J8=1,RANDBETWEEN(35,40)&"%",IF(J8=2,RANDBETWEEN(30,35)&"%",IF(J8=3,RANDBETWEEN(25,30)&"%",IF(J8=4,RANDBETWEEN(20,25)&"%",IF(J8=5,RANDBETWEEN(15,20)&"%",IF(J8=6,RANDBETWEEN(10,15)&"%",IF(J8=7,RANDBETWEEN(8,10)&"%",IF(J8=8,RANDBETWEEN(6,8)&"%",IF(J8=9,RANDBETWEEN(4,6)&"%",IF(J8=10,RANDBETWEEN(2,4)&"%",""))))))))))) -> 30% | Q8: =IFERROR(L8*(M8+N8)*O8*P8,RANDBETWEEN(1,2)%*L8*(M8+N8)*O8) -> 0.96825868 | R8: =VLOOKUP(D:D,ranking!W:X,2,0) -> 0.7 | S8: =R8*Q8 -> 0.67778108 | T8: 26.903316
A9: Trending Top 10 | B9: ALL INDIA | C9: Amazon Prime Video | D9: Svod Originals Shows | E9: PAID | F9: Shows | G9: Raakh | H9: Hindi,Tamil,Telugu | I9: 46185 | J9: 1 | K9: Crime,Drama,Thriller | L9: =VLOOKUP($C9&$E9,'Updated SES'!A:N,14,0) -> 36.49824 | M9: =VLOOKUP($K9,'Genre Penetration'!A:B,2,0)*VLOOKUP($C9&$E9,'Updated SES'!A:I,9,0) -> 0.3744 | N9: =VLOOKUP(K:K,'Genre Penetration'!A:C,3,0)*VLOOKUP($C9&$E9,'Updated SES'!A:J,10,0) -> 0.1344 | O9: =VLOOKUP($B9,'Language Penetration'!$B$1:$BE$14,MATCH('Compile data Working'!$H13,'Language Penetration'!$B$1:$BE$1,0),0) -> 0.204 | P9: =IF(ISBLANK(J9),RANDBETWEEN(1,2)&"%",IF(J9=1,RANDBETWEEN(35,40)&"%",IF(J9=2,RANDBETWEEN(30,35)&"%",IF(J9=3,RANDBETWEEN(25,30)&"%",IF(J9=4,RANDBETWEEN(20,25)&"%",IF(J9=5,RANDBETWEEN(15,20)&"%",IF(J9=6,RANDBETWEEN(10,15)&"%",IF(J9=7,RANDBETWEEN(8,10)&"%",IF(J9=8,RANDBETWEEN(6,8)&"%",IF(J9=9,RANDBETWEEN(4,6)&"%",IF(J9=10,RANDBETWEEN(2,4)&"%",""))))))))))) -> 37% | Q9: =IFERROR(L9*(M9+N9)*O9*P9,RANDBETWEEN(1,2)%*L9*(M9+N9)*O9) -> 1.4016866 | R9: =VLOOKUP(D:D,ranking!W:X,2,0) -> 0.6 | S9: =R9*Q9 -> 0.84101195 | T9: 26.705003
A10: Trending Top 10 | B10: ALL INDIA | C10: Amazon MX Player | D10: Avod Originals Shows | E10: FREE | F10: Shows | G10: Ab Hoga Hisaab | H10: Hindi | I10: 46191 | J10: 1 | K10: Crime,Drama,Thriller | L10: =VLOOKUP($C10&$E10,'Updated SES'!A:N,14,0) -> 78.93987 | M10: =VLOOKUP($K10,'Genre Penetration'!A:B,2,0)*VLOOKUP($C10&$E10,'Updated SES'!A:I,9,0) -> 0.576 | N10: =VLOOKUP(K:K,'Genre Penetration'!A:C,3,0)*VLOOKUP($C10&$E10,'Updated SES'!A:J,10,0) -> 0.056 | O10: =VLOOKUP($B10,'Language Penetration'!$B$1:$BE$14,MATCH('Compile data Working'!$H9,'Language Penetration'!$B$1:$BE$1,0),0) -> 0.28333333 | P10: =IF(ISBLANK(J10),RANDBETWEEN(1,2)&"%",IF(J10=1,RANDBETWEEN(35,40)&"%",IF(J10=2,RANDBETWEEN(30,35)&"%",IF(J10=3,RANDBETWEEN(25,30)&"%",IF(J10=4,RANDBETWEEN(20,25)&"%",IF(J10=5,RANDBETWEEN(15,20)&"%",IF(J10=6,RANDBETWEEN(10,15)&"%",IF(J10=7,RANDBETWEEN(8,10)&"%",IF(J10=8,RANDBETWEEN(6,8)&"%",IF(J10=9,RANDBETWEEN(4,6)&"%",IF(J10=10,RANDBETWEEN(2,4)&"%",""))))))))))) -> 38% | Q10: =IFERROR(L10*(M10+N10)*O10*P10,RANDBETWEEN(1,2)%*L10*(M10+N10)*O10) -> 5.3714898 | R10: =VLOOKUP(D:D,ranking!W:X,2,0) -> 0.6 | S10: =R10*Q10 -> 3.2228939 | T10: 24.870206
A11: Cott Data Servey | B11: ALL INDIA | C11: JioHotstar | D11: Tv Catch-Up | E11: PAID | F11: Tv catchup | G11: Laughter Chefs S3 | H11: Hindi | I11: 45983 | J11: 2 | K11: Comedy,Reality-Tv | L11: =VLOOKUP($C11&$E11,'Updated SES'!A:N,14,0) -> 127.11702 | M11: =VLOOKUP($K11,'Genre Penetration'!A:B,2,0)*VLOOKUP($C11&$E11,'Updated SES'!A:I,9,0) -> 0.335 | N11: =VLOOKUP(K:K,'Genre Penetration'!A:C,3,0)*VLOOKUP($C11&$E11,'Updated SES'!A:J,10,0) -> 0.165 | O11: =VLOOKUP($B11,'Language Penetration'!$B$1:$BE$14,MATCH('Compile data Working'!$H10,'Language Penetration'!$B$1:$BE$1,0),0) -> 0.6 | P11: =IF(ISBLANK(J11),RANDBETWEEN(1,2)&"%",IF(J11=1,RANDBETWEEN(35,40)&"%",IF(J11=2,RANDBETWEEN(30,35)&"%",IF(J11=3,RANDBETWEEN(25,30)&"%",IF(J11=4,RANDBETWEEN(20,25)&"%",IF(J11=5,RANDBETWEEN(15,20)&"%",IF(J11=6,RANDBETWEEN(10,15)&"%",IF(J11=7,RANDBETWEEN(8,10)&"%",IF(J11=8,RANDBETWEEN(6,8)&"%",IF(J11=9,RANDBETWEEN(4,6)&"%",IF(J11=10,RANDBETWEEN(2,4)&"%",""))))))))))) -> 34% | Q11: =IFERROR(L11*(M11+N11)*O11*P11,RANDBETWEEN(1,2)%*L11*(M11+N11)*O11) -> 12.965936 | R11: =VLOOKUP(D:D,ranking!W:X,2,0) -> 0.3 | S11: =R11*Q11 -> 3.8897808 | T11: 21.996205
A12: Trending Top 10 | B12: ALL INDIA | C12: JioHotstar | D12: Svod Originals Shows | E12: PAID | F12: Shows | G12: Thukra Ke Mera Pyaar Season 2 | H12: Bengali,Bhojpuri,Hindi,Kannada,Malayalam,Marathi,Tamil,Telugu | I12: 46192 | J12: 1 | K12: Romance | L12: =VLOOKUP($C12&$E12,'Updated SES'!A:N,14,0) -> 127.11702 | M12: =VLOOKUP($K12,'Genre Penetration'!A:B,2,0)*VLOOKUP($C12&$E12,'Updated SES'!A:I,9,0) -> 0.3015 | N12: =VLOOKUP(K:K,'Genre Penetration'!A:C,3,0)*VLOOKUP($C12&$E12,'Updated SES'!A:J,10,0) -> 0.1815 | O12: =VLOOKUP($B12,'Language Penetration'!$B$1:$BE$14,MATCH('Compile data Working'!$H11,'Language Penetration'!$B$1:$BE$1,0),0) -> 0.6 | P12: =IF(ISBLANK(J12),RANDBETWEEN(1,2)&"%",IF(J12=1,RANDBETWEEN(35,40)&"%",IF(J12=2,RANDBETWEEN(30,35)&"%",IF(J12=3,RANDBETWEEN(25,30)&"%",IF(J12=4,RANDBETWEEN(20,25)&"%",IF(J12=5,RANDBETWEEN(15,20)&"%",IF(J12=6,RANDBETWEEN(10,15)&"%",IF(J12=7,RANDBETWEEN(8,10)&"%",IF(J12=8,RANDBETWEEN(6,8)&"%",IF(J12=9,RANDBETWEEN(4,6)&"%",IF(J12=10,RANDBETWEEN(2,4)&"%",""))))))))))) -> 37% | Q12: =IFERROR(L12*(M12+N12)*O12*P12,RANDBETWEEN(1,2)%*L12*(M12+N12)*O12) -> 13.63025 | R12: =VLOOKUP(D:D,ranking!W:X,2,0) -> 0.6 | S12: =R12*Q12 -> 8.1781498 | T12: 21.448858
A13: Trending Top 10 | B13: ALL INDIA | C13: Netflix | D13: Theatrical Movies | E13: PAID | F13: Movies | G13: Dhurandhar: The Revenge (Raw & Undekha) | H13: Hindi,Kannada,Malayalam,Tamil,Telugu | I13: 46192 | J13: 2 | K13: Action,Crime,Thriller | L13: =VLOOKUP($C13&$E13,'Updated SES'!A:N,14,0) -> 55.4592 | M13: =VLOOKUP($K13,'Genre Penetration'!A:B,2,0)*VLOOKUP($C13&$E13,'Updated SES'!A:I,9,0) -> 0.3528 | N13: =VLOOKUP(K:K,'Genre Penetration'!A:C,3,0)*VLOOKUP($C13&$E13,'Updated SES'!A:J,10,0) -> 0.1428 | O13: =VLOOKUP($B13,'Language Penetration'!$B$1:$BE$14,MATCH('Compile data Working'!$H12,'Language Penetration'!$B$1:$BE$1,0),0) -> #N/A | P13: =IF(ISBLANK(J13),RANDBETWEEN(1,2)&"%",IF(J13=1,RANDBETWEEN(35,40)&"%",IF(J13=2,RANDBETWEEN(30,35)&"%",IF(J13=3,RANDBETWEEN(25,30)&"%",IF(J13=4,RANDBETWEEN(20,25)&"%",IF(J13=5,RANDBETWEEN(15,20)&"%",IF(J13=6,RANDBETWEEN(10,15)&"%",IF(J13=7,RANDBETWEEN(8,10)&"%",IF(J13=8,RANDBETWEEN(6,8)&"%",IF(J13=9,RANDBETWEEN(4,6)&"%",IF(J13=10,RANDBETWEEN(2,4)&"%",""))))))))))) -> 35% | Q13: =IFERROR(L13*(M13+N13)*O13*P13,RANDBETWEEN(1,2)%*L13*(M13+N13)*O13) -> #N/A | R13: =VLOOKUP(D:D,ranking!W:X,2,0) -> 0.7 | S13: =R13*Q13 -> #N/A | T13: 21.295894
A14: Trending Top 10 | B14: ALL INDIA | C14: Netflix | D14: Theatrical Movies | E14: PAID | F14: Movies | G14: Bhooth Bangla | H14: Hindi | I14: 46185 | J14: 1 | K14: Comedy,Horror | L14: =VLOOKUP($C14&$E14,'Updated SES'!A:N,14,0) -> 55.4592 | M14: =VLOOKUP($K14,'Genre Penetration'!A:B,2,0)*VLOOKUP($C14&$E14,'Updated SES'!A:I,9,0) -> 0.2989 | N14: =VLOOKUP(K:K,'Genre Penetration'!A:C,3,0)*VLOOKUP($C14&$E14,'Updated SES'!A:J,10,0) -> 0.1989 | O14: =VLOOKUP($B14,'Language Penetration'!$B$1:$BE$14,MATCH('Compile data Working'!$H42,'Language Penetration'!$B$1:$BE$1,0),0) -> 0.2 | P14: =IF(ISBLANK(J14),RANDBETWEEN(1,2)&"%",IF(J14=1,RANDBETWEEN(35,40)&"%",IF(J14=2,RANDBETWEEN(30,35)&"%",IF(J14=3,RANDBETWEEN(25,30)&"%",IF(J14=4,RANDBETWEEN(20,25)&"%",IF(J14=5,RANDBETWEEN(15,20)&"%",IF(J14=6,RANDBETWEEN(10,15)&"%",IF(J14=7,RANDBETWEEN(8,10)&"%",IF(J14=8,RANDBETWEEN(6,8)&"%",IF(J14=9,RANDBETWEEN(4,6)&"%",IF(J14=10,RANDBETWEEN(2,4)&"%",""))))))))))) -> 37% | Q14: =IFERROR(L14*(M14+N14)*O14*P14,RANDBETWEEN(1,2)%*L14*(M14+N14)*O14) -> 2.0429616 | R14: =VLOOKUP(D:D,ranking!W:X,2,0) -> 0.7 | S14: =R14*Q14 -> 1.4300731 | T14: 19.527626
A15: Trending Top 10 | B15: ALL INDIA | C15: Amazon Prime Video | D15: SVOD Originals Movies | E15: PAID | F15: Movies | G15: Your Fault: London | H15: English,Hindi,Kannada,Malayalam,Tamil,Telugu | I15: 46190 | J15: 5 | K15: Drama,Romance | L15: =VLOOKUP($C15&$E15,'Updated SES'!A:N,14,0) -> 36.49824 | M15: =VLOOKUP($K15,'Genre Penetration'!A:B,2,0)*VLOOKUP($C15&$E15,'Updated SES'!A:I,9,0) -> 0.208 | N15: =VLOOKUP(K:K,'Genre Penetration'!A:C,3,0)*VLOOKUP($C15&$E15,'Updated SES'!A:J,10,0) -> 0.288 | O15: =VLOOKUP($B15,'Language Penetration'!$B$1:$BE$14,MATCH('Compile data Working'!$H8,'Language Penetration'!$B$1:$BE$1,0),0) -> #N/A | P15: =IF(ISBLANK(J15),RANDBETWEEN(1,2)&"%",IF(J15=1,RANDBETWEEN(35,40)&"%",IF(J15=2,RANDBETWEEN(30,35)&"%",IF(J15=3,RANDBETWEEN(25,30)&"%",IF(J15=4,RANDBETWEEN(20,25)&"%",IF(J15=5,RANDBETWEEN(15,20)&"%",IF(J15=6,RANDBETWEEN(10,15)&"%",IF(J15=7,RANDBETWEEN(8,10)&"%",IF(J15=8,RANDBETWEEN(6,8)&"%",IF(J15=9,RANDBETWEEN(4,6)&"%",IF(J15=10,RANDBETWEEN(2,4)&"%",""))))))))))) -> 19% | Q15: =IFERROR(L15*(M15+N15)*O15*P15,RANDBETWEEN(1,2)%*L15*(M15+N15)*O15) -> #N/A | R15: =VLOOKUP(D:D,ranking!W:X,2,0) -> 0.8 | S15: =R15*Q15 -> #N/A | T15: 18.923245
A16: Cott Data Servey | B16: ALL INDIA | C16: JioHotstar | D16: Tv Catch-Up | E16: PAID | F16: Tv catchup | G16: Anupama | H16: Hindi | I16: 44025 | K16: Drama | L16: =VLOOKUP($C16&$E16,'Updated SES'!A:N,14,0) -> 127.11702 | M16: =VLOOKUP($K16,'Genre Penetration'!A:B,2,0)*VLOOKUP($C16&$E16,'Updated SES'!A:I,9,0) -> 0.335 | N16: =VLOOKUP(K:K,'Genre Penetration'!A:C,3,0)*VLOOKUP($C16&$E16,'Updated SES'!A:J,10,0) -> 0.165 | O16: =VLOOKUP($B16,'Language Penetration'!$B$1:$BE$14,MATCH('Compile data Working'!$H17,'Language Penetration'!$B$1:$BE$1,0),0) -> 0.4 | P16: =IF(ISBLANK(J16),RANDBETWEEN(1,2)&"%",IF(J16=1,RANDBETWEEN(35,40)&"%",IF(J16=2,RANDBETWEEN(30,35)&"%",IF(J16=3,RANDBETWEEN(25,30)&"%",IF(J16=4,RANDBETWEEN(20,25)&"%",IF(J16=5,RANDBETWEEN(15,20)&"%",IF(J16=6,RANDBETWEEN(10,15)&"%",IF(J16=7,RANDBETWEEN(8,10)&"%",IF(J16=8,RANDBETWEEN(6,8)&"%",IF(J16=9,RANDBETWEEN(4,6)&"%",IF(J16=10,RANDBETWEEN(2,4)&"%",""))))))))))) -> 1% | Q16: =IFERROR(L16*(M16+N16)*O16*P16,RANDBETWEEN(1,2)%*L16*(M16+N16)*O16) -> 0.25423404 | R16: =VLOOKUP(D:D,ranking!W:X,2,0) -> 0.3 | S16: =R16*Q16 -> 0.076270212 | T16: 18.374668
A17: Trending Top 10 | B17: ALL INDIA | C17: Amazon Prime Video | D17: Svod Originals Shows | E17: PAID | F17: Shows | G17: From S4 | H17: English,Hindi | I17: 46131 | J17: 9 | K17: Drama,Horror | L17: =VLOOKUP($C17&$E17,'Updated SES'!A:N,14,0) -> 36.49824 | M17: =VLOOKUP($K17,'Genre Penetration'!A:B,2,0)*VLOOKUP($C17&$E17,'Updated SES'!A:I,9,0) -> 0.286 | N17: =VLOOKUP(K:K,'Genre Penetration'!A:C,3,0)*VLOOKUP($C17&$E17,'Updated SES'!A:J,10,0) -> 0.216 | O17: =VLOOKUP($B17,'Language Penetration'!$B$1:$BE$14,MATCH('Compile data Working'!$H18,'Language Penetration'!$B$1:$BE$1,0),0) -> 0.6 | P17: =IF(ISBLANK(J17),RANDBETWEEN(1,2)&"%",IF(J17=1,RANDBETWEEN(35,40)&"%",IF(J17=2,RANDBETWEEN(30,35)&"%",IF(J17=3,RANDBETWEEN(25,30)&"%",IF(J17=4,RANDBETWEEN(20,25)&"%",IF(J17=5,RANDBETWEEN(15,20)&"%",IF(J17=6,RANDBETWEEN(10,15)&"%",IF(J17=7,RANDBETWEEN(8,10)&"%",IF(J17=8,RANDBETWEEN(6,8)&"%",IF(J17=9,RANDBETWEEN(4,6)&"%",IF(J17=10,RANDBETWEEN(2,4)&"%",""))))))))))) -> 4% | Q17: =IFERROR(L17*(M17+N17)*O17*P17,RANDBETWEEN(1,2)%*L17*(M17+N17)*O17) -> 0.4397308 | R17: =VLOOKUP(D:D,ranking!W:X,2,0) -> 0.6 | S17: =R17*Q17 -> 0.26383848 | T17: 17.994455
A18: Trending Top 10 | B18: ALL INDIA | C18: Amazon Prime Video | D18: Svod Originals Shows | E18: PAID | F18: Shows | G18: The Pyramid Scheme | H18: Hindi | I18: 46178 | J18: 6 | K18: Comedy,Drama | L18: =VLOOKUP($C18&$E18,'Updated SES'!A:N,14,0) -> 36.49824 | M18: =VLOOKUP($K18,'Genre Penetration'!A:B,2,0)*VLOOKUP($C18&$E18,'Updated SES'!A:I,9,0) -> 0.2444 | N18: =VLOOKUP(K:K,'Genre Penetration'!A:C,3,0)*VLOOKUP($C18&$E18,'Updated SES'!A:J,10,0) -> 0.2544 | O18: =VLOOKUP($B18,'Language Penetration'!$B$1:$BE$14,MATCH('Compile data Working'!$H20,'Language Penetration'!$B$1:$BE$1,0),0) -> 0.6 | P18: =IF(ISBLANK(J18),RANDBETWEEN(1,2)&"%",IF(J18=1,RANDBETWEEN(35,40)&"%",IF(J18=2,RANDBETWEEN(30,35)&"%",IF(J18=3,RANDBETWEEN(25,30)&"%",IF(J18=4,RANDBETWEEN(20,25)&"%",IF(J18=5,RANDBETWEEN(15,20)&"%",IF(J18=6,RANDBETWEEN(10,15)&"%",IF(J18=7,RANDBETWEEN(8,10)&"%",IF(J18=8,RANDBETWEEN(6,8)&"%",IF(J18=9,RANDBETWEEN(4,6)&"%",IF(J18=10,RANDBETWEEN(2,4)&"%",""))))))))))) -> 10% | Q18: =IFERROR(L18*(M18+N18)*O18*P18,RANDBETWEEN(1,2)%*L18*(M18+N18)*O18) -> 1.0923193 | R18: =VLOOKUP(D:D,ranking!W:X,2,0) -> 0.6 | S18: =R18*Q18 -> 0.6553916 | T18: 17.507986
A19: Trending Top 10 | B19: ALL INDIA | C19: Amazon Prime Video | D19: Theatrical Movies | E19: PAID | F19: Movies | G19: Drishyam 3 | H19: Kannada,Malayalam,Tamil,Telugu | I19: 46191 | J19: 2 | K19: Crime,Drama,Thriller | L19: =VLOOKUP($C19&$E19,'Updated SES'!A:N,14,0) -> 36.49824 | M19: =VLOOKUP($K19,'Genre Penetration'!A:B,2,0)*VLOOKUP($C19&$E19,'Updated SES'!A:I,9,0) -> 0.3744 | N19: =VLOOKUP(K:K,'Genre Penetration'!A:C,3,0)*VLOOKUP($C19&$E19,'Updated SES'!A:J,10,0) -> 0.1344 | O19: =VLOOKUP($B19,'Language Penetration'!$B$1:$BE$14,MATCH('Compile data Working'!$H25,'Language Penetration'!$B$1:$BE$1,0),0) -> 0.2 | P19: =IF(ISBLANK(J19),RANDBETWEEN(1,2)&"%",IF(J19=1,RANDBETWEEN(35,40)&"%",IF(J19=2,RANDBETWEEN(30,35)&"%",IF(J19=3,RANDBETWEEN(25,30)&"%",IF(J19=4,RANDBETWEEN(20,25)&"%",IF(J19=5,RANDBETWEEN(15,20)&"%",IF(J19=6,RANDBETWEEN(10,15)&"%",IF(J19=7,RANDBETWEEN(8,10)&"%",IF(J19=8,RANDBETWEEN(6,8)&"%",IF(J19=9,RANDBETWEEN(4,6)&"%",IF(J19=10,RANDBETWEEN(2,4)&"%",""))))))))))) -> 35% | Q19: =IFERROR(L19*(M19+N19)*O19*P19,RANDBETWEEN(1,2)%*L19*(M19+N19)*O19) -> 1.2999213 | R19: =VLOOKUP(D:D,ranking!W:X,2,0) -> 0.7 | S19: =R19*Q19 -> 0.90994492 | T19: 16.858131
A20: Trending Top 10 | B20: ALL INDIA | C20: Amazon Prime Video | D20: Theatrical Movies | E20: PAID | F20: Movies | G20: Mareechika | H20: Hindi | I20: 46192 | J20: 7 | K20: Drama,Romance,Thriller | L20: =VLOOKUP($C20&$E20,'Updated SES'!A:N,14,0) -> 36.49824 | M20: =VLOOKUP($K20,'Genre Penetration'!A:B,2,0)*VLOOKUP($C20&$E20,'Updated SES'!A:I,9,0) -> 0.208 | N20: =VLOOKUP(K:K,'Genre Penetration'!A:C,3,0)*VLOOKUP($C20&$E20,'Updated SES'!A:J,10,0) -> 0.288 | O20: =VLOOKUP($B20,'Language Penetration'!$B$1:$BE$14,MATCH('Compile data Working'!$H26,'Language Penetration'!$B$1:$BE$1,0),0) -> 0.6 | P20: =IF(ISBLANK(J20),RANDBETWEEN(1,2)&"%",IF(J20=1,RANDBETWEEN(35,40)&"%",IF(J20=2,RANDBETWEEN(30,35)&"%",IF(J20=3,RANDBETWEEN(25,30)&"%",IF(J20=4,RANDBETWEEN(20,25)&"%",IF(J20=5,RANDBETWEEN(15,20)&"%",IF(J20=6,RANDBETWEEN(10,15)&"%",IF(J20=7,RANDBETWEEN(8,10)&"%",IF(J20=8,RANDBETWEEN(6,8)&"%",IF(J20=9,RANDBETWEEN(4,6)&"%",IF(J20=10,RANDBETWEEN(2,4)&"%",""))))))))))) -> 10% | Q20: =IFERROR(L20*(M20+N20)*O20*P20,RANDBETWEEN(1,2)%*L20*(M20+N20)*O20) -> 1.0861876 | R20: =VLOOKUP(D:D,ranking!W:X,2,0) -> 0.7 | S20: =R20*Q20 -> 0.76033134 | T20: 16.624409
A21: Trending Top 10 | B21: ALL INDIA | C21: Netflix | D21: Theatrical Movies | E21: PAID | F21: Movies | G21: 29 | H21: Hindi,Kannada,Malayalam,Tamil,Telugu | I21: 46178 | J21: 5 | K21: Comedy,Drama,Romance | L21: =VLOOKUP($C21&$E21,'Updated SES'!A:N,14,0) -> 55.4592 | M21: =VLOOKUP($K21,'Genre Penetration'!A:B,2,0)*VLOOKUP($C21&$E21,'Updated SES'!A:I,9,0) -> 0.1813 | N21: =VLOOKUP(K:K,'Genre Penetration'!A:C,3,0)*VLOOKUP($C21&$E21,'Updated SES'!A:J,10,0) -> 0.3213 | O21: =VLOOKUP($B21,'Language Penetration'!$B$1:$BE$14,MATCH('Compile data Working'!$H27,'Language Penetration'!$B$1:$BE$1,0),0) -> 0.2 | P21: =IF(ISBLANK(J21),RANDBETWEEN(1,2)&"%",IF(J21=1,RANDBETWEEN(35,40)&"%",IF(J21=2,RANDBETWEEN(30,35)&"%",IF(J21=3,RANDBETWEEN(25,30)&"%",IF(J21=4,RANDBETWEEN(20,25)&"%",IF(J21=5,RANDBETWEEN(15,20)&"%",IF(J21=6,RANDBETWEEN(10,15)&"%",IF(J21=7,RANDBETWEEN(8,10)&"%",IF(J21=8,RANDBETWEEN(6,8)&"%",IF(J21=9,RANDBETWEEN(4,6)&"%",IF(J21=10,RANDBETWEEN(2,4)&"%",""))))))))))) -> 15% | Q21: =IFERROR(L21*(M21+N21)*O21*P21,RANDBETWEEN(1,2)%*L21*(M21+N21)*O21) -> 0.83621382 | R21: =VLOOKUP(D:D,ranking!W:X,2,0) -> 0.7 | S21: =R21*Q21 -> 0.58534967 | T21: 16.496989
A22: WK-24'2026 | B22: ALL INDIA | C22: Netflix | D22: SVOD Originals Shows | E22: PAID | F22: Shows | G22: My Love Story With Yamada-kun at Lv999 | H22: English | I22: 46188 | K22: Animation,Comedy,Romance | L22: =VLOOKUP($C22&$E22,'Updated SES'!A:N,14,0) -> 55.4592 | M22: =VLOOKUP($K22,'Genre Penetration'!A:B,2,0)*VLOOKUP($C22&$E22,'Updated SES'!A:I,9,0) -> 0.2695 | N22: =VLOOKUP(K:K,'Genre Penetration'!A:C,3,0)*VLOOKUP($C22&$E22,'Updated SES'!A:J,10,0) -> 0.2295 | O22: =VLOOKUP($B22,'Language Penetration'!$B$1:$BE$14,MATCH('Compile data Working'!$H28,'Language Penetration'!$B$1:$BE$1,0),0) -> 0.17714286 | P22: =IF(ISBLANK(J22),RANDBETWEEN(1,2)&"%",IF(J22=1,RANDBETWEEN(35,40)&"%",IF(J22=2,RANDBETWEEN(30,35)&"%",IF(J22=3,RANDBETWEEN(25,30)&"%",IF(J22=4,RANDBETWEEN(20,25)&"%",IF(J22=5,RANDBETWEEN(15,20)&"%",IF(J22=6,RANDBETWEEN(10,15)&"%",IF(J22=7,RANDBETWEEN(8,10)&"%",IF(J22=8,RANDBETWEEN(6,8)&"%",IF(J22=9,RANDBETWEEN(4,6)&"%",IF(J22=10,RANDBETWEEN(2,4)&"%",""))))))))))) -> 2% | Q22: =IFERROR(L22*(M22+N22)*O22*P22,RANDBETWEEN(1,2)%*L22*(M22+N22)*O22) -> 0.098045527 | R22: =VLOOKUP(D:D,ranking!W:X,2,0) -> 0.6 | S22: =R22*Q22 -> 0.058827316 | T22: 16.496989
A23: WK-24'2026 | B23: ALL INDIA | C23: JioHotstar | D23: Theatrical Movies | E23: PAID | F23: Movies | G23: Kenatha Kanom | H23: Bengali,Hindi,Kannada,Malayalam,Marathi,Tamil,Telugu | I23: 46189 | K23: Comedy,Drama | L23: =VLOOKUP($C23&$E23,'Updated SES'!A:N,14,0) -> 127.11702 | M23: =VLOOKUP($K23,'Genre Penetration'!A:B,2,0)*VLOOKUP($C23&$E23,'Updated SES'!A:I,9,0) -> 0.3149 | N23: =VLOOKUP(K:K,'Genre Penetration'!A:C,3,0)*VLOOKUP($C23&$E23,'Updated SES'!A:J,10,0) -> 0.1749 | O23: =VLOOKUP($B23,'Language Penetration'!$B$1:$BE$14,MATCH('Compile data Working'!$H29,'Language Penetration'!$B$1:$BE$1,0),0) -> 0.204 | P23: =IF(ISBLANK(J23),RANDBETWEEN(1,2)&"%",IF(J23=1,RANDBETWEEN(35,40)&"%",IF(J23=2,RANDBETWEEN(30,35)&"%",IF(J23=3,RANDBETWEEN(25,30)&"%",IF(J23=4,RANDBETWEEN(20,25)&"%",IF(J23=5,RANDBETWEEN(15,20)&"%",IF(J23=6,RANDBETWEEN(10,15)&"%",IF(J23=7,RANDBETWEEN(8,10)&"%",IF(J23=8,RANDBETWEEN(6,8)&"%",IF(J23=9,RANDBETWEEN(4,6)&"%",IF(J23=10,RANDBETWEEN(2,4)&"%",""))))))))))) -> 1% | Q23: =IFERROR(L23*(M23+N23)*O23*P23,RANDBETWEEN(1,2)%*L23*(M23+N23)*O23) -> 0.12701431 | R23: =VLOOKUP(D:D,ranking!W:X,2,0) -> 0.7 | S23: =R23*Q23 -> 0.088910017 | T23: 16.21064
A24: Trending Top 10 | B24: ALL INDIA | C24: Netflix | D24: Svod Originals Shows | E24: PAID | F24: Shows | G24: Teach You a Lesson | H24: English,Hindi,Tamil,Telugu | I24: 46178 | J24: 1 | K24: Action,Drama | L24: =VLOOKUP($C24&$E24,'Updated SES'!A:N,14,0) -> 55.4592 | M24: =VLOOKUP($K24,'Genre Penetration'!A:B,2,0)*VLOOKUP($C24&$E24,'Updated SES'!A:I,9,0) -> 0.2597 | N24: =VLOOKUP(K:K,'Genre Penetration'!A:C,3,0)*VLOOKUP($C24&$E24,'Updated SES'!A:J,10,0) -> 0.2397 | O24: =VLOOKUP($B24,'Language Penetration'!$B$1:$BE$14,MATCH('Compile data Working'!$H30,'Language Penetration'!$B$1:$BE$1,0),0) -> 0.2625 | P24: =IF(ISBLANK(J24),RANDBETWEEN(1,2)&"%",IF(J24=1,RANDBETWEEN(35,40)&"%",IF(J24=2,RANDBETWEEN(30,35)&"%",IF(J24=3,RANDBETWEEN(25,30)&"%",IF(J24=4,RANDBETWEEN(20,25)&"%",IF(J24=5,RANDBETWEEN(15,20)&"%",IF(J24=6,RANDBETWEEN(10,15)&"%",IF(J24=7,RANDBETWEEN(8,10)&"%",IF(J24=8,RANDBETWEEN(6,8)&"%",IF(J24=9,RANDBETWEEN(4,6)&"%",IF(J24=10,RANDBETWEEN(2,4)&"%",""))))))))))) -> 36% | Q24: =IFERROR(L24*(M24+N24)*O24*P24,RANDBETWEEN(1,2)%*L24*(M24+N24)*O24) -> 2.6173027 | R24: =VLOOKUP(D:D,ranking!W:X,2,0) -> 0.6 | S24: =R24*Q24 -> 1.5703816 | T24: 16.16119
A25: WK-24'2026 | B25: ALL INDIA | C25: Netflix | D25: SVOD Originals Shows | E25: PAID | F25: Shows | G25: Horimiya Season 2 | H25: English | I25: 46188 | K25: Animation,Drama,Romance | L25: =VLOOKUP($C25&$E25,'Updated SES'!A:N,14,0) -> 55.4592 | M25: =VLOOKUP($K25,'Genre Penetration'!A:B,2,0)*VLOOKUP($C25&$E25,'Updated SES'!A:I,9,0) -> 0.2695 | N25: =VLOOKUP(K:K,'Genre Penetration'!A:C,3,0)*VLOOKUP($C25&$E25,'Updated SES'!A:J,10,0) -> 0.2295 | O25: =VLOOKUP($B25,'Language Penetration'!$B$1:$BE$14,MATCH('Compile data Working'!$H31,'Language Penetration'!$B$1:$BE$1,0),0) -> 0.6 | P25: =IF(ISBLANK(J25),RANDBETWEEN(1,2)&"%",IF(J25=1,RANDBETWEEN(35,40)&"%",IF(J25=2,RANDBETWEEN(30,35)&"%",IF(J25=3,RANDBETWEEN(25,30)&"%",IF(J25=4,RANDBETWEEN(20,25)&"%",IF(J25=5,RANDBETWEEN(15,20)&"%",IF(J25=6,RANDBETWEEN(10,15)&"%",IF(J25=7,RANDBETWEEN(8,10)&"%",IF(J25=8,RANDBETWEEN(6,8)&"%",IF(J25=9,RANDBETWEEN(4,6)&"%",IF(J25=10,RANDBETWEEN(2,4)&"%",""))))))))))) -> 1% | Q25: =IFERROR(L25*(M25+N25)*O25*P25,RANDBETWEEN(1,2)%*L25*(M25+N25)*O25) -> 0.16604484 | R25: =VLOOKUP(D:D,ranking!W:X,2,0) -> 0.6 | S25: =R25*Q25 -> 0.099626907 | T25: 15.934591
A26: Trending Top 10 | B26: ALL INDIA | C26: Amazon Prime Video | D26: Theatrical Movies | E26: PAID | F26: Movies | G26: Dacoit | H26: Hindi | I26: 46178 | J26: 10 | K26: Action,Drama,Thriller | L26: =VLOOKUP($C26&$E26,'Updated SES'!A:N,14,0) -> 36.49824 | M26: =VLOOKUP($K26,'Genre Penetration'!A:B,2,0)*VLOOKUP($C26&$E26,'Updated SES'!A:I,9,0) -> 0.3536 | N26: =VLOOKUP(K:K,'Genre Penetration'!A:C,3,0)*VLOOKUP($C26&$E26,'Updated SES'!A:J,10,0) -> 0.1536 | O26: =VLOOKUP($B26,'Language Penetration'!$B$1:$BE$14,MATCH('Compile data Working'!$H33,'Language Penetration'!$B$1:$BE$1,0),0) -> 0.2 | P26: =IF(ISBLANK(J26),RANDBETWEEN(1,2)&"%",IF(J26=1,RANDBETWEEN(35,40)&"%",IF(J26=2,RANDBETWEEN(30,35)&"%",IF(J26=3,RANDBETWEEN(25,30)&"%",IF(J26=4,RANDBETWEEN(20,25)&"%",IF(J26=5,RANDBETWEEN(15,20)&"%",IF(J26=6,RANDBETWEEN(10,15)&"%",IF(J26=7,RANDBETWEEN(8,10)&"%",IF(J26=8,RANDBETWEEN(6,8)&"%",IF(J26=9,RANDBETWEEN(4,6)&"%",IF(J26=10,RANDBETWEEN(2,4)&"%",""))))))))))) -> 3% | Q26: =IFERROR(L26*(M26+N26)*O26*P26,RANDBETWEEN(1,2)%*L26*(M26+N26)*O26) -> 0.11107144 | R26: =VLOOKUP(D:D,ranking!W:X,2,0) -> 0.7 | S26: =R26*Q26 -> 0.077750011 | T26: 15.240957
A27: WK-24'2026 | B27: ALL INDIA | C27: JioHotstar | D27: SVOD Originals Shows | E27: PAID | F27: Shows | G27: Harry Potter: The Official Film Podcast | H27: English | I27: 46190 | K27: Talk Show | L27: =VLOOKUP($C27&$E27,'Updated SES'!A:N,14,0) -> 127.11702 | M27: =VLOOKUP($K27,'Genre Penetration'!A:B,2,0)*VLOOKUP($C27&$E27,'Updated SES'!A:I,9,0) -> 0.335 | N27: =VLOOKUP(K:K,'Genre Penetration'!A:C,3,0)*VLOOKUP($C27&$E27,'Updated SES'!A:J,10,0) -> 0.165 | O27: =VLOOKUP($B27,'Language Penetration'!$B$1:$BE$14,MATCH('Compile data Working'!$H34,'Language Penetration'!$B$1:$BE$1,0),0) -> 0.2 | P27: =IF(ISBLANK(J27),RANDBETWEEN(1,2)&"%",IF(J27=1,RANDBETWEEN(35,40)&"%",IF(J27=2,RANDBETWEEN(30,35)&"%",IF(J27=3,RANDBETWEEN(25,30)&"%",IF(J27=4,RANDBETWEEN(20,25)&"%",IF(J27=5,RANDBETWEEN(15,20)&"%",IF(J27=6,RANDBETWEEN(10,15)&"%",IF(J27=7,RANDBETWEEN(8,10)&"%",IF(J27=8,RANDBETWEEN(6,8)&"%",IF(J27=9,RANDBETWEEN(4,6)&"%",IF(J27=10,RANDBETWEEN(2,4)&"%",""))))))))))) -> 2% | Q27: =IFERROR(L27*(M27+N27)*O27*P27,RANDBETWEEN(1,2)%*L27*(M27+N27)*O27) -> 0.25423404 | R27: =VLOOKUP(D:D,ranking!W:X,2,0) -> 0.6 | S27: =R27*Q27 -> 0.15254042 | T27: 14.736946
A28: WK-24'2026 | B28: ALL INDIA | C28: JioHotstar | D28: SVOD Originals Shows | E28: PAID | F28: Shows | G28: Save the Tigers Season 3 | H28: Bengali,Hindi,Kannada,Malayalam,Marathi,Tamil,Telugu | I28: 46192 | K28: Comedy,Drama,Thriller | L28: =VLOOKUP($C28&$E28,'Updated SES'!A:N,14,0) -> 127.11702 | M28: =VLOOKUP($K28,'Genre Penetration'!A:B,2,0)*VLOOKUP($C28&$E28,'Updated SES'!A:I,9,0) -> 0.3886 | N28: =VLOOKUP(K:K,'Genre Penetration'!A:C,3,0)*VLOOKUP($C28&$E28,'Updated SES'!A:J,10,0) -> 0.1386 | O28: =VLOOKUP($B28,'Language Penetration'!$B$1:$BE$14,MATCH('Compile data Working'!$H35,'Language Penetration'!$B$1:$BE$1,0),0) -> 0.2625 | P28: =IF(ISBLANK(J28),RANDBETWEEN(1,2)&"%",IF(J28=1,RANDBETWEEN(35,40)&"%",IF(J28=2,RANDBETWEEN(30,35)&"%",IF(J28=3,RANDBETWEEN(25,30)&"%",IF(J28=4,RANDBETWEEN(20,25)&"%",IF(J28=5,RANDBETWEEN(15,20)&"%",IF(J28=6,RANDBETWEEN(10,15)&"%",IF(J28=7,RANDBETWEEN(8,10)&"%",IF(J28=8,RANDBETWEEN(6,8)&"%",IF(J28=9,RANDBETWEEN(4,6)&"%",IF(J28=10,RANDBETWEEN(2,4)&"%",""))))))))))) -> 1% | Q28: =IFERROR(L28*(M28+N28)*O28*P28,RANDBETWEEN(1,2)%*L28*(M28+N28)*O28) -> 0.17591724 | R28: =VLOOKUP(D:D,ranking!W:X,2,0) -> 0.6 | S28: =R28*Q28 -> 0.10555035 | T28: 14.589576
A29: Trending Top 10 | B29: ALL INDIA | C29: JioHotstar | D29: Theatrical Movies | E29: PAID | F29: Movies | G29: Dridam | H29: Hindi,Kannada,Malayalam,Tamil,Telugu | I29: 46185 | J29: 5 | K29: Crime,Drama,Thriller | L29: =VLOOKUP($C29&$E29,'Updated SES'!A:N,14,0) -> 127.11702 | M29: =VLOOKUP($K29,'Genre Penetration'!A:B,2,0)*VLOOKUP($C29&$E29,'Updated SES'!A:I,9,0) -> 0.4824 | N29: =VLOOKUP(K:K,'Genre Penetration'!A:C,3,0)*VLOOKUP($C29&$E29,'Updated SES'!A:J,10,0) -> 0.0924 | O29: =VLOOKUP($B29,'Language Penetration'!$B$1:$BE$14,MATCH('Compile data Working'!$H36,'Language Penetration'!$B$1:$BE$1,0),0) -> 0.28333333 | P29: =IF(ISBLANK(J29),RANDBETWEEN(1,2)&"%",IF(J29=1,RANDBETWEEN(35,40)&"%",IF(J29=2,RANDBETWEEN(30,35)&"%",IF(J29=3,RANDBETWEEN(25,30)&"%",IF(J29=4,RANDBETWEEN(20,25)&"%",IF(J29=5,RANDBETWEEN(15,20)&"%",IF(J29=6,RANDBETWEEN(10,15)&"%",IF(J29=7,RANDBETWEEN(8,10)&"%",IF(J29=8,RANDBETWEEN(6,8)&"%",IF(J29=9,RANDBETWEEN(4,6)&"%",IF(J29=10,RANDBETWEEN(2,4)&"%",""))))))))))) -> 19% | Q29: =IFERROR(L29*(M29+N29)*O29*P29,RANDBETWEEN(1,2)%*L29*(M29+N29)*O29) -> 3.9334328 | R29: =VLOOKUP(D:D,ranking!W:X,2,0) -> 0.7 | S29: =R29*Q29 -> 2.753403 | T29: 14.533046
A30: Trending Top 10 | B30: ALL INDIA | C30: Netflix | D30: Theatrical Movies | E30: PAID | F30: Movies | G30: Maa Behen | H30: English,Hindi,Tamil,Telugu | I30: 46177 | J30: 3 | K30: Comedy,Crime,Drama | L30: =VLOOKUP($C30&$E30,'Updated SES'!A:N,14,0) -> 55.4592 | M30: =VLOOKUP($K30,'Genre Penetration'!A:B,2,0)*VLOOKUP($C30&$E30,'Updated SES'!A:I,9,0) -> 0.2744 | N30: =VLOOKUP(K:K,'Genre Penetration'!A:C,3,0)*VLOOKUP($C30&$E30,'Updated SES'!A:J,10,0) -> 0.2244 | O30: =VLOOKUP($B30,'Language Penetration'!$B$1:$BE$14,MATCH('Compile data Working'!$H37,'Language Penetration'!$B$1:$BE$1,0),0) -> 0.6 | P30: =IF(ISBLANK(J30),RANDBETWEEN(1,2)&"%",IF(J30=1,RANDBETWEEN(35,40)&"%",IF(J30=2,RANDBETWEEN(30,35)&"%",IF(J30=3,RANDBETWEEN(25,30)&"%",IF(J30=4,RANDBETWEEN(20,25)&"%",IF(J30=5,RANDBETWEEN(15,20)&"%",IF(J30=6,RANDBETWEEN(10,15)&"%",IF(J30=7,RANDBETWEEN(8,10)&"%",IF(J30=8,RANDBETWEEN(6,8)&"%",IF(J30=9,RANDBETWEEN(4,6)&"%",IF(J30=10,RANDBETWEEN(2,4)&"%",""))))))))))) -> 29% | Q30: =IFERROR(L30*(M30+N30)*O30*P30,RANDBETWEEN(1,2)%*L30*(M30+N30)*O30) -> 4.8133705 | R30: =VLOOKUP(D:D,ranking!W:X,2,0) -> 0.7 | S30: =R30*Q30 -> 3.3693594 | T30: 14.305931
A31: Trending Top 10 | B31: ALL INDIA | C31: Sony Liv | D31: Svod Originals Shows | E31: PAID | F31: Shows | G31: Gullak Season 5 | H31: Hindi | I31: 46178 | J31: 6 | K31: Comedy,Drama | L31: =VLOOKUP($C31&$E31,'Updated SES'!A:N,14,0) -> 21.68204 | M31: =VLOOKUP($K31,'Genre Penetration'!A:B,2,0)*VLOOKUP($C31&$E31,'Updated SES'!A:I,9,0) -> 0.3055 | N31: =VLOOKUP(K:K,'Genre Penetration'!A:C,3,0)*VLOOKUP($C31&$E31,'Updated SES'!A:J,10,0) -> 0.1855 | O31: =VLOOKUP($B31,'Language Penetration'!$B$1:$BE$14,MATCH('Compile data Working'!$H39,'Language Penetration'!$B$1:$BE$1,0),0) -> 0.2625 | P31: =IF(ISBLANK(J31),RANDBETWEEN(1,2)&"%",IF(J31=1,RANDBETWEEN(35,40)&"%",IF(J31=2,RANDBETWEEN(30,35)&"%",IF(J31=3,RANDBETWEEN(25,30)&"%",IF(J31=4,RANDBETWEEN(20,25)&"%",IF(J31=5,RANDBETWEEN(15,20)&"%",IF(J31=6,RANDBETWEEN(10,15)&"%",IF(J31=7,RANDBETWEEN(8,10)&"%",IF(J31=8,RANDBETWEEN(6,8)&"%",IF(J31=9,RANDBETWEEN(4,6)&"%",IF(J31=10,RANDBETWEEN(2,4)&"%",""))))))))))) -> 13% | Q31: =IFERROR(L31*(M31+N31)*O31*P31,RANDBETWEEN(1,2)%*L31*(M31+N31)*O31) -> 0.36329071 | R31: =VLOOKUP(D:D,ranking!W:X,2,0) -> 0.6 | S31: =R31*Q31 -> 0.21797443 | T31: 13.925057
A32: WK-24'2026 | B32: ALL INDIA | C32: Netflix | D32: SVOD Originals Shows | E32: PAID | F32: Shows | G32: Oasis | H32: English,Hindi,Tamil,Telugu | I32: 46192 | K32: Crime,Drama,Mystery | L32: =VLOOKUP($C32&$E32,'Updated SES'!A:N,14,0) -> 55.4592 | M32: =VLOOKUP($K32,'Genre Penetration'!A:B,2,0)*VLOOKUP($C32&$E32,'Updated SES'!A:I,9,0) -> 0.294 | N32: =VLOOKUP(K:K,'Genre Penetration'!A:C,3,0)*VLOOKUP($C32&$E32,'Updated SES'!A:J,10,0) -> 0.204 | O32: =VLOOKUP($B32,'Language Penetration'!$B$1:$BE$14,MATCH('Compile data Working'!$H19,'Language Penetration'!$B$1:$BE$1,0),0) -> 0.105 | P32: =IF(ISBLANK(J32),RANDBETWEEN(1,2)&"%",IF(J32=1,RANDBETWEEN(35,40)&"%",IF(J32=2,RANDBETWEEN(30,35)&"%",IF(J32=3,RANDBETWEEN(25,30)&"%",IF(J32=4,RANDBETWEEN(20,25)&"%",IF(J32=5,RANDBETWEEN(15,20)&"%",IF(J32=6,RANDBETWEEN(10,15)&"%",IF(J32=7,RANDBETWEEN(8,10)&"%",IF(J32=8,RANDBETWEEN(6,8)&"%",IF(J32=9,RANDBETWEEN(4,6)&"%",IF(J32=10,RANDBETWEEN(2,4)&"%",""))))))))))) -> 1% | Q32: =IFERROR(L32*(M32+N32)*O32*P32,RANDBETWEEN(1,2)%*L32*(M32+N32)*O32) -> 0.028999616 | R32: =VLOOKUP(D:D,ranking!W:X,2,0) -> 0.6 | S32: =R32*Q32 -> 0.017399769 | T32: 13.809249
A33: WK-24'2026 | B33: ALL INDIA | C33: Amazon Prime Video | D33: Theatrical Movies | E33: PAID | F33: Movies | G33: A Snapshot of Forever | H33: English | I33: 46190 | K33: Comedy,Romance | L33: =VLOOKUP($C33&$E33,'Updated SES'!A:N,14,0) -> 36.49824 | M33: =VLOOKUP($K33,'Genre Penetration'!A:B,2,0)*VLOOKUP($C33&$E33,'Updated SES'!A:I,9,0) -> 0.156 | N33: =VLOOKUP(K:K,'Genre Penetration'!A:C,3,0)*VLOOKUP($C33&$E33,'Updated SES'!A:J,10,0) -> 0.336 | O33: =VLOOKUP($B33,'Language Penetration'!$B$1:$BE$14,MATCH('Compile data Working'!$H40,'Language Penetration'!$B$1:$BE$1,0),0) -> 0.204 | P33: =IF(ISBLANK(J33),RANDBETWEEN(1,2)&"%",IF(J33=1,RANDBETWEEN(35,40)&"%",IF(J33=2,RANDBETWEEN(30,35)&"%",IF(J33=3,RANDBETWEEN(25,30)&"%",IF(J33=4,RANDBETWEEN(20,25)&"%",IF(J33=5,RANDBETWEEN(15,20)&"%",IF(J33=6,RANDBETWEEN(10,15)&"%",IF(J33=7,RANDBETWEEN(8,10)&"%",IF(J33=8,RANDBETWEEN(6,8)&"%",IF(J33=9,RANDBETWEEN(4,6)&"%",IF(J33=10,RANDBETWEEN(2,4)&"%",""))))))))))) -> 1% | Q33: =IFERROR(L33*(M33+N33)*O33*P33,RANDBETWEEN(1,2)%*L33*(M33+N33)*O33) -> 0.036632554 | R33: =VLOOKUP(D:D,ranking!W:X,2,0) -> 0.7 | S33: =R33*Q33 -> 0.025642787 | T33: 13.793016
A34: WK-24'2026 | B34: ALL INDIA | C34: JioHotstar | D34: SVOD Originals Movies | E34: PAID | F34: Movies | G34: Never Change! | H34: English | I34: 46190 | K34: Comedy | L34: =VLOOKUP($C34&$E34,'Updated SES'!A:N,14,0) -> 127.11702 | M34: =VLOOKUP($K34,'Genre Penetration'!A:B,2,0)*VLOOKUP($C34&$E34,'Updated SES'!A:I,9,0) -> 0.3015 | N34: =VLOOKUP(K:K,'Genre Penetration'!A:C,3,0)*VLOOKUP($C34&$E34,'Updated SES'!A:J,10,0) -> 0.1815 | O34: =VLOOKUP($B34,'Language Penetration'!$B$1:$BE$14,MATCH('Compile data Working'!$H41,'Language Penetration'!$B$1:$BE$1,0),0) -> 0.2 | P34: =IF(ISBLANK(J34),RANDBETWEEN(1,2)&"%",IF(J34=1,RANDBETWEEN(35,40)&"%",IF(J34=2,RANDBETWEEN(30,35)&"%",IF(J34=3,RANDBETWEEN(25,30)&"%",IF(J34=4,RANDBETWEEN(20,25)&"%",IF(J34=5,RANDBETWEEN(15,20)&"%",IF(J34=6,RANDBETWEEN(10,15)&"%",IF(J34=7,RANDBETWEEN(8,10)&"%",IF(J34=8,RANDBETWEEN(6,8)&"%",IF(J34=9,RANDBETWEEN(4,6)&"%",IF(J34=10,RANDBETWEEN(2,4)&"%",""))))))))))) -> 2% | Q34: =IFERROR(L34*(M34+N34)*O34*P34,RANDBETWEEN(1,2)%*L34*(M34+N34)*O34) -> 0.24559008 | R34: =VLOOKUP(D:D,ranking!W:X,2,0) -> 0.8 | S34: =R34*Q34 -> 0.19647207 | T34: 13.736946
A35: Trending Top 10 | B35: ALL INDIA | C35: Netflix | D35: SVOD Originals Movies | E35: PAID | F35: Movies | G35: Voicemails for Isabelle | H35: English,Hindi,Tamil,Telugu | I35: 46192 | J35: 6 | K35: Comedy,Drama,Romance | L35: =VLOOKUP($C35&$E35,'Updated SES'!A:N,14,0) -> 55.4592 | M35: =VLOOKUP($K35,'Genre Penetration'!A:B,2,0)*VLOOKUP($C35&$E35,'Updated SES'!A:I,9,0) -> 0.1813 | N35: =VLOOKUP(K:K,'Genre Penetration'!A:C,3,0)*VLOOKUP($C35&$E35,'Updated SES'!A:J,10,0) -> 0.3213 | O35: =VLOOKUP($B35,'Language Penetration'!$B$1:$BE$14,MATCH('Compile data Working'!$H32,'Language Penetration'!$B$1:$BE$1,0),0) -> 0.2625 | P35: =IF(ISBLANK(J35),RANDBETWEEN(1,2)&"%",IF(J35=1,RANDBETWEEN(35,40)&"%",IF(J35=2,RANDBETWEEN(30,35)&"%",IF(J35=3,RANDBETWEEN(25,30)&"%",IF(J35=4,RANDBETWEEN(20,25)&"%",IF(J35=5,RANDBETWEEN(15,20)&"%",IF(J35=6,RANDBETWEEN(10,15)&"%",IF(J35=7,RANDBETWEEN(8,10)&"%",IF(J35=8,RANDBETWEEN(6,8)&"%",IF(J35=9,RANDBETWEEN(4,6)&"%",IF(J35=10,RANDBETWEEN(2,4)&"%",""))))))))))) -> 13% | Q35: =IFERROR(L35*(M35+N35)*O35*P35,RANDBETWEEN(1,2)%*L35*(M35+N35)*O35) -> 0.95119322 | R35: =VLOOKUP(D:D,ranking!W:X,2,0) -> 0.8 | S35: =R35*Q35 -> 0.76095457 | T35: 13.721784
A36: WK-24'2026 | B36: ALL INDIA | C36: Amazon Prime Video | D36: Theatrical Movies | E36: PAID | F36: Movies | G36: Arco | H36: Hindi,Tamil,Telugu | I36: 46190 | K36: Adventure,Animation | L36: =VLOOKUP($C36&$E36,'Updated SES'!A:N,14,0) -> 36.49824 | M36: =VLOOKUP($K36,'Genre Penetration'!A:B,2,0)*VLOOKUP($C36&$E36,'Updated SES'!A:I,9,0) -> 0.286 | N36: =VLOOKUP(K:K,'Genre Penetration'!A:C,3,0)*VLOOKUP($C36&$E36,'Updated SES'!A:J,10,0) -> 0.216 | O36: =VLOOKUP($B36,'Language Penetration'!$B$1:$BE$14,MATCH('Compile data Working'!$H16,'Language Penetration'!$B$1:$BE$1,0),0) -> 0.6 | P36: =IF(ISBLANK(J36),RANDBETWEEN(1,2)&"%",IF(J36=1,RANDBETWEEN(35,40)&"%",IF(J36=2,RANDBETWEEN(30,35)&"%",IF(J36=3,RANDBETWEEN(25,30)&"%",IF(J36=4,RANDBETWEEN(20,25)&"%",IF(J36=5,RANDBETWEEN(15,20)&"%",IF(J36=6,RANDBETWEEN(10,15)&"%",IF(J36=7,RANDBETWEEN(8,10)&"%",IF(J36=8,RANDBETWEEN(6,8)&"%",IF(J36=9,RANDBETWEEN(4,6)&"%",IF(J36=10,RANDBETWEEN(2,4)&"%",""))))))))))) -> 2% | Q36: =IFERROR(L36*(M36+N36)*O36*P36,RANDBETWEEN(1,2)%*L36*(M36+N36)*O36) -> 0.2198654 | R36: =VLOOKUP(D:D,ranking!W:X,2,0) -> 0.7 | S36: =R36*Q36 -> 0.15390578 | T36: 13.390688
A37: Trending Top 10 | B37: ALL INDIA | C37: Sony Liv | D37: Tv Catch-Up | E37: FREE | F37: Shows | G37: Hastinapur Ke Veer | H37: Hindi | I37: 46175 | J37: 2 | K37: Mythology | L37: =VLOOKUP($C37&$E37,'Updated SES'!A:N,14,0) -> 5.268 | M37: =VLOOKUP($K37,'Genre Penetration'!A:B,2,0)*VLOOKUP($C37&$E37,'Updated SES'!A:I,9,0) -> 0.3828 | N37: =VLOOKUP(K:K,'Genre Penetration'!A:C,3,0)*VLOOKUP($C37&$E37,'Updated SES'!A:J,10,0) -> 0.1428 | O37: =VLOOKUP($B37,'Language Penetration'!$B$1:$BE$14,MATCH('Compile data Working'!$H43,'Language Penetration'!$B$1:$BE$1,0),0) -> 0.15 | P37: =IF(ISBLANK(J37),RANDBETWEEN(1,2)&"%",IF(J37=1,RANDBETWEEN(35,40)&"%",IF(J37=2,RANDBETWEEN(30,35)&"%",IF(J37=3,RANDBETWEEN(25,30)&"%",IF(J37=4,RANDBETWEEN(20,25)&"%",IF(J37=5,RANDBETWEEN(15,20)&"%",IF(J37=6,RANDBETWEEN(10,15)&"%",IF(J37=7,RANDBETWEEN(8,10)&"%",IF(J37=8,RANDBETWEEN(6,8)&"%",IF(J37=9,RANDBETWEEN(4,6)&"%",IF(J37=10,RANDBETWEEN(2,4)&"%",""))))))))))) -> 30% | Q37: =IFERROR(L37*(M37+N37)*O37*P37,RANDBETWEEN(1,2)%*L37*(M37+N37)*O37) -> 0.12459874 | R37: =VLOOKUP(D:D,ranking!W:X,2,0) -> 0.3 | S37: =R37*Q37 -> 0.037379621 | T37: 13.291294
A38: Trending Top 10 | B38: ALL INDIA | C38: Sony Liv | D38: Tv Catch-Up | E38: FREE | F38: Shows | G38: India's Best Dancer | H38: Hindi | I38: 46179 | J38: 5 | K38: Reality Tv | L38: =VLOOKUP($C38&$E38,'Updated SES'!A:N,14,0) -> 5.268 | M38: =VLOOKUP($K38,'Genre Penetration'!A:B,2,0)*VLOOKUP($C38&$E38,'Updated SES'!A:I,9,0) -> 0.264 | N38: =VLOOKUP(K:K,'Genre Penetration'!A:C,3,0)*VLOOKUP($C38&$E38,'Updated SES'!A:J,10,0) -> 0.204 | O38: =VLOOKUP($B38,'Language Penetration'!$B$1:$BE$14,MATCH('Compile data Working'!$H44,'Language Penetration'!$B$1:$BE$1,0),0) -> 0.2 | P38: =IF(ISBLANK(J38),RANDBETWEEN(1,2)&"%",IF(J38=1,RANDBETWEEN(35,40)&"%",IF(J38=2,RANDBETWEEN(30,35)&"%",IF(J38=3,RANDBETWEEN(25,30)&"%",IF(J38=4,RANDBETWEEN(20,25)&"%",IF(J38=5,RANDBETWEEN(15,20)&"%",IF(J38=6,RANDBETWEEN(10,15)&"%",IF(J38=7,RANDBETWEEN(8,10)&"%",IF(J38=8,RANDBETWEEN(6,8)&"%",IF(J38=9,RANDBETWEEN(4,6)&"%",IF(J38=10,RANDBETWEEN(2,4)&"%",""))))))))))) -> 19% | Q38: =IFERROR(L38*(M38+N38)*O38*P38,RANDBETWEEN(1,2)%*L38*(M38+N38)*O38) -> 0.093686112 | R38: =VLOOKUP(D:D,ranking!W:X,2,0) -> 0.3 | S38: =R38*Q38 -> 0.028105834 | T38: 13.131151
A39: Trending Top 10 | B39: ALL INDIA | C39: Netflix | D39: Svod Originals Shows | E39: PAID | F39: Shows | G39: I Will Find You | H39: English,Hindi,Tamil,Telugu | I39: 46191 | J39: 2 | K39: Crime,Drama,Thriller | L39: =VLOOKUP($C39&$E39,'Updated SES'!A:N,14,0) -> 55.4592 | M39: =VLOOKUP($K39,'Genre Penetration'!A:B,2,0)*VLOOKUP($C39&$E39,'Updated SES'!A:I,9,0) -> 0.3528 | N39: =VLOOKUP(K:K,'Genre Penetration'!A:C,3,0)*VLOOKUP($C39&$E39,'Updated SES'!A:J,10,0) -> 0.1428 | O39: =VLOOKUP($B39,'Language Penetration'!$B$1:$BE$14,MATCH('Compile data Working'!$H21,'Language Penetration'!$B$1:$BE$1,0),0) -> 0.204 | P39: =IF(ISBLANK(J39),RANDBETWEEN(1,2)&"%",IF(J39=1,RANDBETWEEN(35,40)&"%",IF(J39=2,RANDBETWEEN(30,35)&"%",IF(J39=3,RANDBETWEEN(25,30)&"%",IF(J39=4,RANDBETWEEN(20,25)&"%",IF(J39=5,RANDBETWEEN(15,20)&"%",IF(J39=6,RANDBETWEEN(10,15)&"%",IF(J39=7,RANDBETWEEN(8,10)&"%",IF(J39=8,RANDBETWEEN(6,8)&"%",IF(J39=9,RANDBETWEEN(4,6)&"%",IF(J39=10,RANDBETWEEN(2,4)&"%",""))))))))))) -> 35% | Q39: =IFERROR(L39*(M39+N39)*O39*P39,RANDBETWEEN(1,2)%*L39*(M39+N39)*O39) -> 1.9624704 | R39: =VLOOKUP(D:D,ranking!W:X,2,0) -> 0.6 | S39: =R39*Q39 -> 1.1774822 | T39: 13.120962
A40: Trending Top 10 | B40: ALL INDIA | C40: Sony Liv | D40: Theatrical Movies | E40: PAID | F40: Movies | G40: Athiradi | H40: Hindi,Kannada,Malayalam,Tamil,Telugu | I40: 46192 | J40: 1 | K40: Action,Comedy,Drama | L40: =VLOOKUP($C40&$E40,'Updated SES'!A:N,14,0) -> 21.68204 | M40: =VLOOKUP($K40,'Genre Penetration'!A:B,2,0)*VLOOKUP($C40&$E40,'Updated SES'!A:I,9,0) -> 0.312 | N40: =VLOOKUP(K:K,'Genre Penetration'!A:C,3,0)*VLOOKUP($C40&$E40,'Updated SES'!A:J,10,0) -> 0.182 | O40: =VLOOKUP($B40,'Language Penetration'!$B$1:$BE$14,MATCH('Compile data Working'!$H45,'Language Penetration'!$B$1:$BE$1,0),0) -> 0.2 | P40: =IF(ISBLANK(J40),RANDBETWEEN(1,2)&"%",IF(J40=1,RANDBETWEEN(35,40)&"%",IF(J40=2,RANDBETWEEN(30,35)&"%",IF(J40=3,RANDBETWEEN(25,30)&"%",IF(J40=4,RANDBETWEEN(20,25)&"%",IF(J40=5,RANDBETWEEN(15,20)&"%",IF(J40=6,RANDBETWEEN(10,15)&"%",IF(J40=7,RANDBETWEEN(8,10)&"%",IF(J40=8,RANDBETWEEN(6,8)&"%",IF(J40=9,RANDBETWEEN(4,6)&"%",IF(J40=10,RANDBETWEEN(2,4)&"%",""))))))))))) -> 35% | Q40: =IFERROR(L40*(M40+N40)*O40*P40,RANDBETWEEN(1,2)%*L40*(M40+N40)*O40) -> 0.74976494 | R40: =VLOOKUP(D:D,ranking!W:X,2,0) -> 0.7 | S40: =R40*Q40 -> 0.52483546 | T40: 12.946578
A41: WK-24'2026 | B41: ALL INDIA | C41: Netflix | D41: Theatrical Movies | E41: PAID | F41: Movies | G41: Color Book | H41: English | I41: 46192 | K41: Drama | L41: =VLOOKUP($C41&$E41,'Updated SES'!A:N,14,0) -> 55.4592 | M41: =VLOOKUP($K41,'Genre Penetration'!A:B,2,0)*VLOOKUP($C41&$E41,'Updated SES'!A:I,9,0) -> 0.245 | N41: =VLOOKUP(K:K,'Genre Penetration'!A:C,3,0)*VLOOKUP($C41&$E41,'Updated SES'!A:J,10,0) -> 0.255 | O41: =VLOOKUP($B41,'Language Penetration'!$B$1:$BE$14,MATCH('Compile data Working'!$H24,'Language Penetration'!$B$1:$BE$1,0),0) -> 0.2625 | P41: =IF(ISBLANK(J41),RANDBETWEEN(1,2)&"%",IF(J41=1,RANDBETWEEN(35,40)&"%",IF(J41=2,RANDBETWEEN(30,35)&"%",IF(J41=3,RANDBETWEEN(25,30)&"%",IF(J41=4,RANDBETWEEN(20,25)&"%",IF(J41=5,RANDBETWEEN(15,20)&"%",IF(J41=6,RANDBETWEEN(10,15)&"%",IF(J41=7,RANDBETWEEN(8,10)&"%",IF(J41=8,RANDBETWEEN(6,8)&"%",IF(J41=9,RANDBETWEEN(4,6)&"%",IF(J41=10,RANDBETWEEN(2,4)&"%",""))))))))))) -> 1% | Q41: =IFERROR(L41*(M41+N41)*O41*P41,RANDBETWEEN(1,2)%*L41*(M41+N41)*O41) -> 0.0727902 | R41: =VLOOKUP(D:D,ranking!W:X,2,0) -> 0.7 | S41: =R41*Q41 -> 0.05095314 | T41: 12.87192
...

Sheet Sheet2
A1: ss | B1: ss
A2: Punjabi,Haryanvi | B2: 0.095
A3: Hindi,Kannada,Tamil | B3: 0.26666667
A4: English,Hindi,Kannada,Tamil,Telugu | B4: 0.23
A5: Hindi,Tamil,Telugu,Turkish | B5: #N/A
A6: Bengali,Hindi,Malayalam,Marathi,Tamil,Telugu | B6: 0.19
A7: Haryanvi,Rajasthani | B7: 0.1
A8: Hindi,English,Malayalam,Tamil,Telugu | B8: 0.224
A9: Hindi,Telugu | B9: 0.375
A10: English,Hindi,Kannada,Malayala,Marathi,Tamil,Telugu | B10: 0.19142857

Sheet ranking
A1: =B1&D1 -> OTT PLATFORMTop 10 | B1: OTT PLATFORM | C1: Content format | D1: Top 10 | E1: PAID/FREE | F1: Show/Movies | G1: Genre | H1: Language | I1: Average of Rank | J1: Round | L1: Rank | M1: Watching Percentage | O1: Rank | P1: Watching Percentage | S1: Rank | T1: Watching Percentage | AB1: 1) Original Shows - 80%
A2: =B2&D2 -> Adda TimesAbhishapto | B2: Adda Times | C2: Svod Originals Shows | D2: Abhishapto | E2: PAID | F2: Show | G2: Drama | H2: Bengali | I2: 9 | J2: 9 | L2: 7 | M2: 40-35% | O2: 7 | P2: 40-35% | S2: 1 | T2: 0.9 | W2: Content format | X2: Watching % | AB2: 2) Original Movies - 100%
A3: =B3&D3 -> Adda TimesBasanta Ese Geche | B3: Adda Times | C3: Svod Originals Shows | D3: Basanta Ese Geche | E3: PAID | F3: Show | G3: Drama | H3: Bengali | I3: 2 | J3: 2 | L3: 6 | M3: 35-30% | O3: 6 | P3: 35-30% | S3: 2 | T3: 0.85 | W3: Avod Originals Movies | X3: 0.8 | AB3: 3) Theatrical releases - 75% (conditions pl discuss)
A4: =B4&D4 -> Adda TimesCabaret | B4: Adda Times | C4: Svod Originals Shows | D4: Cabaret | E4: PAID | F4: Show | G4: Drama | H4: Bengali | I4: 4 | J4: 4 | L4: 5 | M4: 30-25% | O4: 5 | P4: 30-25% | S4: 3 | T4: 0.8 | W4: Avod Originals Shows | X4: 0.6 | AB4: 4) Catch up TV Shows - 30% (For bigg boss its also live and have highlights so higher)
A5: =B5&D5 -> Adda TimesGhoshbabur-retirement-plan | B5: Adda Times | C5: Svod Originals Shows | D5: Ghoshbabur-retirement-plan | E5: PAID | F5: Show | G5: Drama | H5: Bengali | I5: 7 | J5: 7 | L5: 4 | M5: 25-20% | O5: 4 | P5: 25-20% | S5: 4 | T5: 0.7 | W5: Live Event | X5: 0.1 | AB5: 5) Live sports - depending upon sports 100% for Cricket, Kabbadi 40%, rest sport 10-15%
A6: =B6&D6 -> Adda TimesKothamrita | B6: Adda Times | C6: Svod Originals Shows | D6: Kothamrita | E6: PAID | F6: Show | G6: Drama,Family | H6: Bengali | I6: 10 | J6: 10 | L6: 3 | M6: 20-15% | O6: 3 | P6: 20-15% | S6: 5 | T6: 0.65 | W6: Svod Originals Movies | X6: 0.8 | AB6: 4) Highlights - 10% of Live sports
A7: =B7&D7 -> Adda TimesNandini | B7: Adda Times | C7: Svod Originals Shows | D7: Nandini | E7: PAID | F7: Show | G7: Drama | H7: Bengali | I7: 8 | J7: 8 | L7: 2 | M7: 15-10% | O7: 2 | P7: 15-10% | S7: 6 | T7: 0.6 | W7: Svod Originals Shows | X7: 0.6
A8: =B8&D8 -> Adda TimesPetni | B8: Adda Times | C8: Svod Originals Shows | D8: Petni | E8: PAID | F8: Show | G8: Drama | H8: Bengali | I8: 5 | J8: 5 | L8: 1 | M8: 10-8% | O8: 1 | P8: 10-8% | S8: 7 | T8: 0.55 | W8: Theatrical releases | X8: 0.7
A9: =B9&D9 -> Adda TimesPreme Pora Baron | B9: Adda Times | C9: Svod Originals Shows | D9: Preme Pora Baron | E9: PAID | F9: Show | G9: Drama | H9: Bengali | I9: 3 | J9: 3 | L9: 8 | M9: 8-6% | S9: 8 | T9: 0.5 | W9: Tv Catch-Up | X9: 0.3
A10: =B10&D10 -> Adda TimesSIN - Whispers Of Guilt | B10: Adda Times | C10: Svod Originals Shows | D10: SIN - Whispers Of Guilt | E10: PAID | F10: Show | G10: Comedy | H10: Bengali | I10: 6 | J10: 6 | L10: 9 | M10: 6-4% | S10: 9 | T10: 0.45 | W10: Theatrical Movies | X10: 0.7
A11: =B11&D11 -> Adda TimesThe First Rain | B11: Adda Times | C11: Svod Originals Shows | D11: The First Rain | E11: PAID | F11: Show | G11: Drama,Romance | H11: Bengali | I11: 1 | J11: 1 | L11: 10 | M11: 4-2% | S11: 10 | T11: 0.4
A12: =B12&D12 -> Aha Video11th Hour | B12: Aha Video | C12: Svod Originals Shows | D12: 11th Hour | E12: PAID | F12: Show | G12: Drama,Thriller | H12: Telugu | I12: 8 | J12: 8 | S12: 11 | T12: =T11*90% -> 0.36
A13: =B13&D13 -> Aha VideoAkash Vaani | B13: Aha Video | C13: Svod Originals Shows | D13: Akash Vaani | E13: PAID | F13: Show | G13: Comedy,Romane | H13: Tamil,Telugu | I13: 5 | J13: 5 | S13: 12 | T13: =T12*90% -> 0.324
A14: =B14&D14 -> Aha VideoAmmuchi 2 | B14: Aha Video | C14: Svod Originals Shows | D14: Ammuchi 2 | E14: PAID | F14: Show | G14: Comedy | H14: Tamil | I14: 6 | J14: 6 | S14: 13 | T14: =T13*90% -> 0.2916
A15: =B15&D15 -> Aha VideoAnya's Tutorial | B15: Aha Video | C15: Svod Originals Shows | D15: Anya's Tutorial | E15: PAID | F15: Show | G15: Drama | H15: Tamil | I15: 10 | J15: 10 | S15: 14 | T15: =T14*90% -> 0.26244
A16: =B16&D16 -> Aha VideoEmoji | B16: Aha Video | C16: Svod Originals Shows | D16: Emoji | E16: PAID | F16: Show | G16: Romance | H16: Tamil | I16: 3 | J16: 3 | S16: 15 | T16: =T15*90% -> 0.236196
A17: =B17&D17 -> Aha VideoEP7 Youtubers | B17: Aha Video | C17: Svod Originals Shows | D17: EP7 Youtubers | E17: PAID | F17: Show | G17: Game Show | H17: Telugu | I17: 4 | J17: 4 | S17: 16 | T17: =T16*90% -> 0.2125764
A18: =B18&D18 -> Aha VideoIrai | B18: Aha Video | C18: Svod Originals Shows | D18: Irai | E18: PAID | F18: Show | G18: Action,Crime,Drama | H18: Tamil | I18: 2 | J18: 2 | S18: 17 | T18: =T17*90% -> 0.19131876
A19: =B19&D19 -> Aha VideoKuthukku Pathu | B19: Aha Video | C19: Svod Originals Shows | D19: Kuthukku Pathu | E19: PAID | F19: Show | G19: Comedy | H19: Tamil | I19: 7 | J19: 7 | S19: 18 | T19: =T18*90% -> 0.17218688
A20: =B20&D20 -> Aha VideoMad Company | B20: Aha Video | C20: Svod Originals Shows | D20: Mad Company | E20: PAID | F20: Show | G20: Comedy,Drama | H20: Tamil | I20: 9 | J20: 9 | S20: 19 | T20: =T19*90% -> 0.1549682
A21: =B21&D21 -> Aha VideoPettaikaali | B21: Aha Video | C21: Svod Originals Shows | D21: Pettaikaali | E21: PAID | F21: Show | G21: Action | H21: Tamil | I21: 1 | J21: 1 | S21: 20 | T21: =T20*90% -> 0.13947138
A22: =B22&D22 -> Aha VideoAyngaran | B22: Aha Video | C22: Theatrical releases | D22: Ayngaran | E22: PAID | F22: Movie | G22: Action,Drama | H22: Tamil | I22: 4 | J22: 4 | S22: 21 | T22: =T21*90% -> 0.12552424
A23: =B23&D23 -> Aha VideoDiary | B23: Aha Video | C23: Theatrical releases | D23: Diary | E23: PAID | F23: Movie | G23: Horror,Thriller | H23: Tamil | I23: 3 | J23: 3 | S23: 22 | T23: =T22*90% -> 0.11297181
... A92: =B92&D92 -> Apple TvBefore | B92: Apple Tv | C92: Svod Originals Shows | D92: Before | E92: PAID | F92: Show | G92: Drama,Thriller | H92: English | I92: 9 | J92: 9 | S92: 100 | T92: =T91*90% -> 7.865082e-05
A93: =B93&D93 -> Apple TvDisclaimer | B93: Apple Tv | C93: Svod Originals Shows | D93: Disclaimer | E93: PAID | F93: Show | G93: Drama,Mystery,Thriller | H93: English | I93: 5 | J93: 5
A94: =B94&D94 -> Apple TvPresumed Innocent | B94: Apple Tv | C94: Svod Originals Shows | D94: Presumed Innocent | E94: PAID | F94: Show | G94: Crime,Drama,Mystery | H94: English | I94: 7 | J94: 7
A95: =B95&D95 -> Apple TvSee | B95: Apple Tv | C95: Svod Originals Shows | D95: See | E95: PAID | F95: Show | G95: Action,Drama,Sci-Fi | H95: English | I95: 8 | J95: 8
A96: =B96&D96 -> Apple TvSeverance | B96: Apple Tv | C96: Svod Originals Shows | D96: Severance | E96: PAID | F96: Show | G96: Drama,Mystery,Thriller | H96: English | I96: 10 | J96: 10
A97: =B97&D97 -> Apple TvShrinking | B97: Apple Tv | C97: Svod Originals Shows | D97: Shrinking | E97: PAID | F97: Show | G97: Comedy,Drama | H97: English | I97: 3 | J97: 3
A98: =B98&D98 -> Apple TvSilo | B98: Apple Tv | C98: Svod Originals Shows | D98: Silo | E98: PAID | F98: Show | G98: Drama,Mystery,Sci-Fi | H98: English | I98: 1 | J98: 1
A99: =B99&D99 -> Apple TvSlow Horses | B99: Apple Tv | C99: Svod Originals Shows | D99: Slow Horses | E99: PAID | F99: Show | G99: Drama,Thriller | H99: English | I99: 6 | J99: 6
A100: =B100&D100 -> Apple TvTed Lasso | B100: Apple Tv | C100: Svod Originals Shows | D100: Ted Lasso | E100: PAID | F100: Show | G100: Comedy,Drama,Sport | H100: English | I100: 4 | J100: 4
A101: =B101&D101 -> Apple TvKillers of the Flower Moon | B101: Apple Tv | C101: Theatrical releases | D101: Killers of the Flower Moon | E101: PAID | F101: Movie | G101: Crime,Drama,Mystery | H101: English | I101: 8 | J101: 8
A102: =B102&D102 -> Apple TvLuck | B102: Apple Tv | C102: Theatrical releases | D102: Luck | E102: PAID | F102: Movie | G102: Animation,Adventure,Comedy | H102: English | I102: 4 | J102: 4
A103: =B103&D103 -> Apple TvWolfs | B103: Apple Tv | C103: Theatrical releases | D103: Wolfs | E103: PAID | F103: Movie | G103: Crime,Thriller | H103: English | I103: 1 | J103: 1
A104: =B104&D104 -> Chaupal TvJatt & Jullit 3 | B104: Chaupal Tv | C104: Svod Originals Movies | D104: Jatt & Jullit 3 | E104: PAID | F104: Movie | G104: Comedy,Romance | H104: Punjabi | I104: 3 | J104: 3
... A393: =B393&D393 -> Zee5Yek Number | B393: Zee5 | C393: Svod Originals Movies | D393: Yek Number | E393: PAID | F393: Movie | G393: Drama | H393: Marathi | I393: 4.6666667 | J393: 5
A394: =B394&D394 -> Zee52012 | B394: Zee5 | C394: Theatrical releases | D394: 2012 | E394: RENT | F394: Movie | G394: Action,Sci-Fi | H394: Hindi,English,Tamil, | I394: 9 | J394: 9
A395: =B395&D395 -> Zee5Bhaiyya Ji | B395: Zee5 | C395: Theatrical releases | D395: Bhaiyya Ji | E395: PAID | F395: Movie | G395: Action,Drama | H395: Hindi | I395: 7.3333333 | J395: 7
